File: Data/Test_1.csv
Data : Criteria 1,,"True"
Data : Data capture scheme,,"Default settings"
Data : Interval 1,(ms),"20.00"
Data : Measurement 1,,"Time"
End of test : Criteria 1,,"Measurement level"
End of test : Measurement 1,,"Displacement"
End of test : Value 1,(mm),"30.00"
Compressive strain (Displacement) : Primary source,,"Displacement"

Results Table 1
,Area under curve,Maximum Force,Displacement at Maximum Force,Modulus (Automatic Young's),Break location,Compressive displacement at Maximum Force,Compressive strain (Displacement) at Maximum Force,Compressive stress at Maximum Force,Energy at Maximum Force,Energy to X-intercept at Modulus (Automatic Young's)
,(J),(kgf),(mm),(kgf/mm^2),,(mm),(%),(kgf/mm^2),(J),(J)
"1","0.3438","2.68","27.74","1.32","-----","27.74","27.74","0.27","0.29","0.00"
"2","0.4626","3.56","29.97","1.24","-----","29.97","29.97","0.36","0.46","0.00"
"3","0.4207","2.31","24.06","1.41","-----","24.06","24.06","0.23","0.31","0.01"
"4","0.4107","2.29","26.91","2.22","-----","26.91","26.91","0.23","0.35","0.01"
"5","0.2761","1.85","23.87","1.17","-----","23.87","23.87","0.19","0.17","0.00"
"6","0.2984","1.91","22.16","1.34","-----","22.16","22.16","0.19","0.17","0.00"
"7","0.8574","3.79","29.73","3.90","-----","29.73","29.73","0.38","0.85","0.00"
"8","0.8317","3.79","22.24","4.02","-----","22.24","22.24","0.38","0.56","0.00"
"9","0.8310","3.63","19.31","3.80","-----","19.31","19.31","0.36","0.48","-----"
"10","0.8155","3.68","19.13","3.76","-----","19.13","19.13","0.37","0.46","0.00"
"11","0.4425","2.52","21.01","1.74","-----","21.01","21.01","0.25","0.26","0.00"
"12","0.4391","2.34","17.24","1.26","-----","17.24","17.24","0.23","0.18","-----"
"13","0.3901","2.77","26.09","1.50","-----","26.09","26.09","0.28","0.29","0.00"
"14","0.3504","2.70","29.36","1.26","-----","29.36","29.36","0.27","0.33","0.00"
"15","0.3557","2.17","27.51","2.88","-----","27.51","27.51","0.22","0.32","0.02"
"16","0.3784","2.27","22.21","1.29","-----","22.21","22.21","0.23","0.22","0.00"
"17","0.3844","2.45","27.86","1.55","-----","27.86","27.86","0.24","0.34","0.00"
"18","0.3045","2.57","29.98","1.48","-----","29.98","29.98","0.26","0.30","0.00"
"19","0.2886","1.71","22.23","0.93","-----","22.23","22.23","0.17","0.17","0.00"
"20","0.3260","1.96","20.66","1.10","-----","20.66","20.66","0.20","0.18","0.00"
"21","0.2144","1.77","24.19","1.29","-----","24.19","24.19","0.18","0.12","0.00"
"22","0.2657","2.24","30.00","0.89","-----","30.00","30.00","0.22","0.27","0.00"
"23","0.3440","2.55","28.47","1.22","-----","28.47","28.47","0.25","0.31","0.00"
"24","0.3709","2.97","26.84","1.29","-----","26.84","26.84","0.30","0.28","0.00"
"25","0.4358","2.40","24.06","1.63","-----","24.06","24.06","0.24","0.30","0.00"
"26","0.3075","1.94","20.47","1.15","-----","20.47","20.47","0.19","0.19","0.00"
"27","0.2479","2.20","29.99","1.40","-----","29.99","29.99","0.22","0.25","0.00"
"28","0.2505","1.93","26.69","1.13","-----","26.69","26.69","0.19","0.19","0.00"
"29","0.2958","1.92","15.96","1.07","-----","15.96","15.96","0.19","0.13","-----"

Results Table 2


1,Time,Displacement,Force
,(s),(mm),(kgf)
"","0.0000","0.0000","0.0003"
"","0.0400","0.0031","0.0016"
"","0.0800","0.0222","0.0093"
"","0.1200","0.0617","0.0017"
"","0.1600","0.0928","0.0050"
"","0.2000","0.1247","-0.0005"
"","0.2400","0.1573","0.0031"
"","0.2800","0.1886","0.0023"
"","0.3200","0.2229","0.0030"
"","0.3600","0.2568","0.0025"
"","0.4000","0.2887","0.0057"
"","0.4400","0.3230","0.0070"
"","0.4800","0.3547","0.0089"
"","0.5200","0.3879","0.0124"
"","0.5600","0.4233","0.0150"
"","0.6000","0.4547","0.0172"
"","0.6400","0.4875","0.0212"
"","0.6800","0.5229","0.0243"
"","0.7200","0.5550","0.0302"
"","0.7600","0.5891","0.0321"
"","0.8000","0.6232","0.0354"
"","0.8400","0.6540","0.0392"
"","0.8800","0.6885","0.0447"
"","0.9200","0.7229","0.0485"
"","0.9600","0.7543","0.0508"
"","1.0000","0.7888","0.0590"
"","1.0400","0.8217","0.0632"
"","1.0800","0.8541","0.0629"
"","1.1200","0.8895","0.0719"
"","1.1600","0.9221","0.0752"
"","1.2000","0.9549","0.0759"
"","1.2400","0.9884","0.0855"
"","1.2800","1.0218","0.0894"
"","1.3200","1.0552","0.0925"
"","1.3600","1.0887","0.0985"
"","1.4000","1.1214","0.1011"
"","1.4400","1.1549","0.1059"
"","1.4800","1.1891","0.1123"
"","1.5200","1.2219","0.1146"
"","1.5600","1.2555","0.1191"
"","1.6000","1.2877","0.1244"
"","1.6400","1.3207","0.1275"
"","1.6800","1.3561","0.1312"
"","1.7200","1.3884","0.1383"
"","1.7600","1.4215","0.1408"
"","1.8000","1.4549","0.1456"
"","1.8400","1.4885","0.1496"
"","1.8800","1.5227","0.1548"
"","1.9200","1.5554","0.1594"
"","1.9600","1.5879","0.1626"
"","2.0000","1.6220","0.1659"
"","2.0400","1.6551","0.1730"
"","2.0800","1.6878","0.1737"
"","2.1200","1.7224","0.1805"
"","2.1600","1.7539","0.1834"
"","2.2000","1.7888","0.1865"
"","2.2400","1.8234","0.1915"
"","2.2800","1.8545","0.1944"
"","2.3200","1.8882","0.1954"
"","2.3600","1.9219","0.2002"
"","2.4000","1.9544","0.2020"
"","2.4400","1.9893","0.2052"
"","2.4800","2.0221","0.2059"
"","2.5200","2.0543","0.2068"
"","2.5600","2.0890","0.2130"
"","2.6000","2.1227","0.2167"
"","2.6400","2.1543","0.2173"
"","2.6800","2.1890","0.2224"
"","2.7200","2.2213","0.2261"
"","2.7600","2.2540","0.2291"
"","2.8000","2.2892","0.2345"
"","2.8400","2.3219","0.2371"
"","2.8800","2.3550","0.2387"
"","2.9200","2.3887","0.2452"
"","2.9600","2.4216","0.2467"
"","3.0000","2.4559","0.2497"
"","3.0400","2.4889","0.2518"
"","3.0800","2.5210","0.2527"
"","3.1200","2.5550","0.2570"
"","3.1600","2.5880","0.2621"
"","3.2000","2.6223","0.2628"
"","3.2400","2.6559","0.2667"
"","3.2800","2.6867","0.2691"
"","3.3200","2.7216","0.2723"
"","3.3600","2.7555","0.2780"
"","3.4000","2.7887","0.2809"
"","3.4400","2.8227","0.2843"
"","3.4800","2.8541","0.2890"
"","3.5200","2.8880","0.2925"
"","3.5600","2.9228","0.2982"
"","3.6000","2.9550","0.3011"
"","3.6400","2.9873","0.3041"
"","3.6800","3.0224","0.3101"
"","3.7200","3.0552","0.3118"
"","3.7600","3.0887","0.3162"
"","3.8000","3.1231","0.3213"
"","3.8400","3.1540","0.3227"
"","3.8800","3.1882","0.3284"
"","3.9200","3.2227","0.3328"
"","3.9600","3.2545","0.3341"
"","4.0000","3.2892","0.3370"
"","4.0400","3.3213","0.3397"
"","4.0800","3.3543","0.3432"
"","4.1200","3.3898","0.3479"
"","4.1600","3.4220","0.3533"
"","4.2000","3.4550","0.3562"
"","4.2400","3.4889","0.3584"
"","4.2800","3.5213","0.3623"
"","4.3200","3.5551","0.3661"
"","4.3600","3.5887","0.3692"
"","4.4000","3.6213","0.3733"
"","4.4400","3.6549","0.3757"
"","4.4800","3.6889","0.3809"
"","4.5200","3.7222","0.3853"
"","4.5600","3.7554","0.3897"
"","4.6000","3.7878","0.3934"
"","4.6400","3.8208","0.3979"
"","4.6800","3.8561","0.4036"
"","4.7200","3.8882","0.4053"
"","4.7600","3.9213","0.4119"
"","4.8000","3.9549","0.4158"
"","4.8400","3.9887","0.4193"
"","4.8800","4.0229","0.4227"
"","4.9200","4.0552","0.4278"
"","4.9600","4.0876","0.4307"
"","5.0000","4.1223","0.4329"
"","5.0400","4.1547","0.4387"
"","5.0800","4.1882","0.4409"
"","5.1200","4.2226","0.4439"
"","5.1600","4.2538","0.4468"
"","5.2000","4.2883","0.4514"
"","5.2400","4.3233","0.4558"
"","5.2800","4.3544","0.4559"
"","5.3200","4.3882","0.4576"
"","5.3600","4.4216","0.4640"
"","5.4000","4.4539","0.4659"
"","5.4400","4.4894","0.4696"
"","5.4800","4.5226","0.4721"
"","5.5200","4.5541","0.4715"
"","5.5600","4.5888","0.4779"
"","5.6000","4.6223","0.4820"
"","5.6400","4.6548","0.4848"
"","5.6800","4.6896","0.4890"
"","5.7200","4.7220","0.4903"
"","5.7600","4.7541","0.4911"
"","5.8000","4.7892","0.4986"
"","5.8400","4.8224","0.4989"
"","5.8800","4.8548","0.5021"
"","5.9200","4.8885","0.5057"
"","5.9600","4.9216","0.5076"
"","6.0000","4.9563","0.5109"
"","6.0400","4.9886","0.5143"
"","6.0800","5.0210","0.5151"
"","6.1200","5.0548","0.5188"
"","6.1600","5.0880","0.5226"
"","6.2000","5.1223","0.5251"
"","6.2400","5.1556","0.5293"
"","6.2800","5.1875","0.5305"
"","6.3200","5.2218","0.5300"
"","6.3600","5.2559","0.5319"
"","6.4000","5.2879","0.5324"
"","6.4400","5.3230","0.5342"
"","6.4800","5.3543","0.5355"
"","6.5200","5.3880","0.5385"
"","6.5600","5.4226","0.5411"
"","6.6000","5.4552","0.5411"
"","6.6400","5.4872","0.5239"
"","6.6800","5.5225","0.5015"
"","6.7200","5.5546","0.5011"
"","6.7600","5.5888","0.5035"
"","6.8000","5.6231","0.5039"
"","6.8400","5.6538","0.5070"
"","6.8800","5.6883","0.5105"
"","6.9200","5.7229","0.5139"
"","6.9600","5.7545","0.5133"
"","7.0000","5.7891","0.5139"
"","7.0400","5.8211","0.5175"
"","7.0800","5.8543","0.5193"
"","7.1200","5.8895","0.5236"
"","7.1600","5.9218","0.5244"
"","7.2000","5.9547","0.5268"
"","7.2400","5.9891","0.5315"
"","7.2800","6.0215","0.5321"
"","7.3200","6.0548","0.5302"
"","7.3600","6.0891","0.5104"
"","7.4000","6.1207","0.4977"
"","7.4400","6.1555","0.5067"
"","7.4800","6.1892","0.5145"
"","7.5200","6.2216","0.5149"
"","7.5600","6.2551","0.5226"
"","7.6000","6.2884","0.5252"
"","7.6400","6.3210","0.5298"
"","7.6800","6.3557","0.5367"
"","7.7200","6.3887","0.5393"
"","7.7600","6.4210","0.5421"
"","7.8000","6.4555","0.5469"
"","7.8400","6.4885","0.5475"
"","7.8800","6.5226","0.5500"
"","7.9200","6.5561","0.5544"
"","7.9600","6.5868","0.5541"
"","8.0000","6.6224","0.5585"
"","8.0400","6.6542","0.5620"
"","8.0800","6.6884","0.5645"
"","8.1200","6.7224","0.5689"
"","8.1600","6.7539","0.5701"
"","8.2000","6.7885","0.5750"
"","8.2400","6.8235","0.5797"
"","8.2800","6.8552","0.5789"
"","8.3200","6.8878","0.5829"
"","8.3600","6.9219","0.5845"
"","8.4000","6.9538","0.5887"
"","8.4400","6.9896","0.5905"
"","8.4800","7.0224","0.5902"
"","8.5200","7.0540","0.5887"
"","8.5600","7.0885","0.5916"
"","8.6000","7.1223","0.5926"
"","8.6400","7.1549","0.5916"
"","8.6800","7.1893","0.5925"
"","8.7200","7.2213","0.5914"
"","8.7600","7.2538","0.5913"
"","8.8000","7.2894","0.5962"
"","8.8400","7.3221","0.5937"
"","8.8800","7.3546","0.5938"
"","8.9200","7.3891","0.5953"
"","8.9600","7.4213","0.5916"
"","9.0000","7.4566","0.5941"
"","9.0400","7.4884","0.5946"
"","9.0800","7.5211","0.5952"
"","9.1200","7.5549","0.5957"
"","9.1600","7.5880","0.5943"
"","9.2000","7.6226","0.5906"
"","9.2400","7.6556","0.5901"
"","9.2800","7.6881","0.5889"
"","9.3200","7.7213","0.5849"
"","9.3600","7.7554","0.5829"
"","9.4000","7.7887","0.5800"
"","9.4400","7.8223","0.5760"
"","9.4800","7.8547","0.5679"
"","9.5200","7.8877","0.5588"
"","9.5600","7.9228","0.5563"
"","9.6000","7.9548","0.5507"
"","9.6400","7.9877","0.5414"
"","9.6800","8.0227","0.5384"
"","9.7200","8.0551","0.5323"
"","9.7600","8.0887","0.5311"
"","9.8000","8.1227","0.5283"
"","9.8400","8.1540","0.5224"
"","9.8800","8.1876","0.5188"
"","9.9200","8.2232","0.5189"
"","9.9600","8.2542","0.5113"
"","10.0000","8.2890","0.5073"
"","10.0400","8.3222","0.4992"
"","10.0800","8.3536","0.4908"
"","10.1200","8.3897","0.4897"
"","10.1600","8.4220","0.4815"
"","10.2000","8.4547","0.4726"
"","10.2400","8.4893","0.4713"
"","10.2800","8.5217","0.4665"
"","10.3200","8.5548","0.4653"
"","10.3600","8.5888","0.4623"
"","10.4000","8.6214","0.4456"
"","10.4400","8.6550","0.4317"
"","10.4800","8.6897","0.4204"
"","10.5200","8.7219","0.4089"
"","10.5600","8.7553","0.4027"
"","10.6000","8.7879","0.3543"
"","10.6400","8.8210","0.3074"
"","10.6800","8.8560","0.3066"
"","10.7200","8.8884","0.3084"
"","10.7600","8.9216","0.3123"
"","10.8000","8.9550","0.3172"
"","10.8400","8.9885","0.3192"
"","10.8800","9.0229","0.3188"
"","10.9200","9.0559","0.3215"
"","10.9600","9.0872","0.3234"
"","11.0000","9.1222","0.3286"
"","11.0400","9.1548","0.3297"
"","11.0800","9.1880","0.3297"
"","11.1200","9.2224","0.3326"
"","11.1600","9.2541","0.3349"
"","11.2000","9.2884","0.3384"
"","11.2400","9.3235","0.3416"
"","11.2800","9.3555","0.3415"
"","11.3200","9.3875","0.3397"
"","11.3600","9.4217","0.3436"
"","11.4000","9.4540","0.3430"
"","11.4400","9.4891","0.3486"
"","11.4800","9.5229","0.3504"
"","11.5200","9.5535","0.3494"
"","11.5600","9.5889","0.3573"
"","11.6000","9.6225","0.3590"
"","11.6400","9.6543","0.3578"
"","11.6800","9.6896","0.3635"
"","11.7200","9.7217","0.3665"
"","11.7600","9.7542","0.3684"
"","11.8000","9.7892","0.3736"
"","11.8400","9.8220","0.3761"
"","11.8800","9.8550","0.3788"
"","11.9200","9.8884","0.3801"
"","11.9600","9.9221","0.3810"
"","12.0000","9.9561","0.3855"
"","12.0400","9.9887","0.3894"
"","12.0800","10.0211","0.3930"
"","12.1200","10.0546","0.3976"
"","12.1600","10.0883","0.4010"
"","12.2000","10.1219","0.4029"
"","12.2400","10.1553","0.4085"
"","12.2800","10.1882","0.4108"
"","12.3200","10.2215","0.4145"
"","12.3600","10.2553","0.4197"
"","12.4000","10.2886","0.4206"
"","12.4400","10.3229","0.4230"
"","12.4800","10.3543","0.4276"
"","12.5200","10.3878","0.4264"
"","12.5600","10.4228","0.4303"
"","12.6000","10.4550","0.4292"
"","12.6400","10.4879","0.4291"
"","12.6800","10.5225","0.4340"
"","12.7200","10.5547","0.4322"
"","12.7600","10.5890","0.4314"
"","12.8000","10.6228","0.4335"
"","12.8400","10.6537","0.4321"
"","12.8800","10.6883","0.4341"
"","12.9200","10.7226","0.4317"
"","12.9600","10.7548","0.4211"
"","13.0000","10.7889","0.4136"
"","13.0400","10.8215","0.4015"
"","13.0800","10.8542","0.3761"
"","13.1200","10.8893","0.3345"
"","13.1600","10.9221","0.3018"
"","13.2000","10.9545","0.2773"
"","13.2400","10.9891","0.2765"
"","13.2800","11.0215","0.2792"
"","13.3200","11.0547","0.2797"
"","13.3600","11.0883","0.2857"
"","13.4000","11.1213","0.2884"
"","13.4400","11.1558","0.2890"
"","13.4800","11.1888","0.2923"
"","13.5200","11.2220","0.2889"
"","13.5600","11.2550","0.2867"
"","13.6000","11.2876","0.2854"
"","13.6400","11.3211","0.2495"
"","13.6800","11.3559","0.2194"
"","13.7200","11.3881","0.2212"
"","13.7600","11.4217","0.2216"
"","13.8000","11.4554","0.2249"
"","13.8400","11.4882","0.2252"
"","13.8800","11.5231","0.2236"
"","13.9200","11.5557","0.2239"
"","13.9600","11.5870","0.2231"
"","14.0000","11.6225","0.2261"
"","14.0400","11.6547","0.2217"
"","14.0800","11.6883","0.2128"
"","14.1200","11.7225","0.2167"
"","14.1600","11.7538","0.2190"
"","14.2000","11.7884","0.2252"
"","14.2400","11.8232","0.2282"
"","14.2800","11.8553","0.2272"
"","14.3200","11.8877","0.2299"
"","14.3600","11.9216","0.2343"
"","14.4000","11.9535","0.2355"
"","14.4400","11.9897","0.2367"
"","14.4800","12.0218","0.2325"
"","14.5200","12.0535","0.2273"
"","14.5600","12.0887","0.2354"
"","14.6000","12.1219","0.2366"
"","14.6400","12.1555","0.2368"
"","14.6800","12.1893","0.2411"
"","14.7200","12.2217","0.2417"
"","14.7600","12.2542","0.2392"
"","14.8000","12.2891","0.2430"
"","14.8400","12.3217","0.2430"
"","14.8800","12.3546","0.2404"
"","14.9200","12.3886","0.2413"
"","14.9600","12.4215","0.2353"
"","15.0000","12.4560","0.2375"
"","15.0400","12.4885","0.2374"
"","15.0800","12.5213","0.2366"
"","15.1200","12.5547","0.2362"
"","15.1600","12.5878","0.2373"
"","15.2000","12.6222","0.2347"
"","15.2400","12.6556","0.2398"
"","15.2800","12.6884","0.2390"
"","15.3200","12.7214","0.2395"
"","15.3600","12.7547","0.2432"
"","15.4000","12.7886","0.2442"
"","15.4400","12.8225","0.2426"
"","15.4800","12.8545","0.2456"
"","15.5200","12.8878","0.2455"
"","15.5600","12.9230","0.2467"
"","15.6000","12.9552","0.2466"
"","15.6400","12.9879","0.2475"
"","15.6800","13.0222","0.2496"
"","15.7200","13.0549","0.2499"
"","15.7600","13.0889","0.2479"
"","15.8000","13.1234","0.2500"
"","15.8400","13.1540","0.2490"
"","15.8800","13.1886","0.2523"
"","15.9200","13.2228","0.2540"
"","15.9600","13.2548","0.2501"
"","16.0000","13.2885","0.2526"
"","16.0400","13.3223","0.2549"
"","16.0800","13.3542","0.2542"
"","16.1200","13.3894","0.2570"
"","16.1600","13.4220","0.2566"
"","16.2000","13.4543","0.2585"
"","16.2400","13.4890","0.2635"
"","16.2800","13.5216","0.2605"
"","16.3200","13.5552","0.2597"
"","16.3600","13.5881","0.2623"
"","16.4000","13.6212","0.2664"
"","16.4400","13.6551","0.2742"
"","16.4800","13.6895","0.2858"
"","16.5200","13.7220","0.2918"
"","16.5600","13.7552","0.3022"
"","16.6000","13.7879","0.3150"
"","16.6400","13.8212","0.3254"
"","16.6800","13.8562","0.3411"
"","16.7200","13.8885","0.3504"
"","16.7600","13.9219","0.3630"
"","16.8000","13.9555","0.3762"
"","16.8400","13.9882","0.3858"
"","16.8800","14.0231","0.3963"
"","16.9200","14.0559","0.4053"
"","16.9600","14.0877","0.4174"
"","17.0000","14.1221","0.4290"
"","17.0400","14.1553","0.4391"
"","17.0800","14.1880","0.4480"
"","17.1200","14.2223","0.4590"
"","17.1600","14.2543","0.4676"
"","17.2000","14.2881","0.4784"
"","17.2400","14.3235","0.4916"
"","17.2800","14.3553","0.4968"
"","17.3200","14.3884","0.5058"
"","17.3600","14.4216","0.5181"
"","17.4000","14.4536","0.5274"
"","17.4400","14.4895","0.5389"
"","17.4800","14.5225","0.5469"
"","17.5200","14.5535","0.5572"
"","17.5600","14.5891","0.5702"
"","17.6000","14.6225","0.5797"
"","17.6400","14.6549","0.5863"
"","17.6800","14.6899","0.5987"
"","17.7200","14.7212","0.6052"
"","17.7600","14.7544","0.6130"
"","17.8000","14.7893","0.6238"
"","17.8400","14.8217","0.6322"
"","17.8800","14.8547","0.6402"
"","17.9200","14.8890","0.6499"
"","17.9600","14.9217","0.6586"
"","18.0000","14.9553","0.6673"
"","18.0400","14.9895","0.6770"
"","18.0800","15.0207","0.6831"
"","18.1200","15.0549","0.6937"
"","18.1600","15.0882","0.7025"
"","18.2000","15.1219","0.7084"
"","18.2400","15.1557","0.7185"
"","18.2800","15.1881","0.7251"
"","18.3200","15.2221","0.7328"
"","18.3600","15.2547","0.7428"
"","18.4000","15.2885","0.7505"
"","18.4400","15.3226","0.7583"
"","18.4800","15.3545","0.7667"
"","18.5200","15.3874","0.7733"
"","18.5600","15.4230","0.7845"
"","18.6000","15.4544","0.7877"
"","18.6400","15.4879","0.7977"
"","18.6800","15.5225","0.8068"
"","18.7200","15.5549","0.8151"
"","18.7600","15.5890","0.8220"
"","18.8000","15.6230","0.8301"
"","18.8400","15.6535","0.8355"
"","18.8800","15.6882","0.8445"
"","18.9200","15.7228","0.8535"
"","18.9600","15.7544","0.8597"
"","19.0000","15.7888","0.8675"
"","19.0400","15.8224","0.8792"
"","19.0800","15.8539","0.8840"
"","19.1200","15.8893","0.8950"
"","19.1600","15.9223","0.9041"
"","19.2000","15.9541","0.9091"
"","19.2400","15.9889","0.9189"
"","19.2800","16.0218","0.9282"
"","19.3200","16.0556","0.9361"
"","19.3600","16.0882","0.9408"
"","19.4000","16.1213","0.9500"
"","19.4400","16.1551","0.9575"
"","19.4800","16.1889","0.9675"
"","19.5200","16.2218","0.9757"
"","19.5600","16.2553","0.9835"
"","19.6000","16.2874","0.9903"
"","19.6400","16.3208","0.9985"
"","19.6800","16.3559","1.0093"
"","19.7200","16.3882","1.0150"
"","19.7600","16.4215","1.0238"
"","19.8000","16.4552","1.0334"
"","19.8400","16.4879","1.0395"
"","19.8800","16.5233","1.0493"
"","19.9200","16.5554","1.0568"
"","19.9600","16.5877","1.0611"
"","20.0000","16.6213","1.0709"
"","20.0400","16.6550","1.0795"
"","20.0800","16.6883","1.0884"
"","20.1200","16.7219","1.0962"
"","20.1600","16.7542","1.1017"
"","20.2000","16.7880","1.1124"
"","20.2400","16.8235","1.1223"
"","20.2800","16.8550","1.1257"
"","20.3200","16.8891","1.1343"
"","20.3600","16.9212","1.1416"
"","20.4000","16.9542","1.1496"
"","20.4400","16.9897","1.1620"
"","20.4800","17.0222","1.1678"
"","20.5200","17.0539","1.1742"
"","20.5600","17.0888","1.1829"
"","20.6000","17.1221","1.1922"
"","20.6400","17.1552","1.2018"
"","20.6800","17.1893","1.2095"
"","20.7200","17.2208","1.2157"
"","20.7600","17.2542","1.2266"
"","20.8000","17.2893","1.2377"
"","20.8400","17.3216","1.2471"
"","20.8800","17.3546","1.2518"
"","20.9200","17.3884","1.2622"
"","20.9600","17.4218","1.2726"
"","21.0000","17.4554","1.2812"
"","21.0400","17.4891","1.2894"
"","21.0800","17.5213","1.2977"
"","21.1200","17.5546","1.3046"
"","21.1600","17.5880","1.3128"
"","21.2000","17.6217","1.3231"
"","21.2400","17.6561","1.3324"
"","21.2800","17.6879","1.3374"
"","21.3200","17.7226","1.3462"
"","21.3600","17.7548","1.3534"
"","21.4000","17.7885","1.3634"
"","21.4400","17.8226","1.3724"
"","21.4800","17.8542","1.3786"
"","21.5200","17.8877","1.3879"
"","21.5600","17.9232","1.3985"
"","21.6000","17.9550","1.4048"
"","21.6400","17.9880","1.4121"
"","21.6800","18.0224","1.4210"
"","21.7200","18.0549","1.4305"
"","21.7600","18.0895","1.4425"
"","21.8000","18.1232","1.4504"
"","21.8400","18.1537","1.4545"
"","21.8800","18.1884","1.4652"
"","21.9200","18.2229","1.4770"
"","21.9600","18.2550","1.4840"
"","22.0000","18.2885","1.4906"
"","22.0400","18.3221","1.4999"
"","22.0800","18.3544","1.5089"
"","22.1200","18.3897","1.5185"
"","22.1600","18.4225","1.5262"
"","22.2000","18.4541","1.5337"
"","22.2400","18.4888","1.5425"
"","22.2800","18.5216","1.5528"
"","22.3200","18.5558","1.5611"
"","22.3600","18.5886","1.5674"
"","22.4000","18.6207","1.5748"
"","22.4400","18.6559","1.5867"
"","22.4800","18.6887","1.5942"
"","22.5200","18.7220","1.6046"
"","22.5600","18.7559","1.6141"
"","22.6000","18.7874","1.6166"
"","22.6400","18.8215","1.6277"
"","22.6800","18.8560","1.6372"
"","22.7200","18.8880","1.6424"
"","22.7600","18.9222","1.6536"
"","22.8000","18.9553","1.6621"
"","22.8400","18.9879","1.6674"
"","22.8800","19.0227","1.6770"
"","22.9200","19.0554","1.6845"
"","22.9600","19.0878","1.6902"
"","23.0000","19.1215","1.7007"
"","23.0400","19.1546","1.7072"
"","23.0800","19.1882","1.7194"
"","23.1200","19.2220","1.7254"
"","23.1600","19.2534","1.7284"
"","23.2000","19.2879","1.7404"
"","23.2400","19.3233","1.7498"
"","23.2800","19.3553","1.7551"
"","23.3200","19.3889","1.7614"
"","23.3600","19.4215","1.7670"
"","23.4000","19.4535","1.7728"
"","23.4400","19.4897","1.7860"
"","23.4800","19.5225","1.7907"
"","23.5200","19.5535","1.7936"
"","23.5600","19.5893","1.8043"
"","23.6000","19.6222","1.8114"
"","23.6400","19.6551","1.8201"
"","23.6800","19.6897","1.8248"
"","23.7200","19.7212","1.8298"
"","23.7600","19.7543","1.8387"
"","23.8000","19.7897","1.8483"
"","23.8400","19.8218","1.8523"
"","23.8800","19.8550","1.8590"
"","23.9200","19.8890","1.8669"
"","23.9600","19.9216","1.8729"
"","24.0000","19.9556","1.8789"
"","24.0400","19.9893","1.8857"
"","24.0800","20.0206","1.8891"
"","24.1200","20.0549","1.8943"
"","24.1600","20.0876","1.9019"
"","24.2000","20.1217","1.9088"
"","24.2400","20.1559","1.9133"
"","24.2800","20.1878","1.9160"
"","24.3200","20.2224","1.9263"
"","24.3600","20.2553","1.9284"
"","24.4000","20.2880","1.9336"
"","24.4400","20.3227","1.9418"
"","24.4800","20.3549","1.9438"
"","24.5200","20.3869","1.9464"
"","24.5600","20.4237","1.9563"
"","24.6000","20.4547","1.9548"
"","24.6400","20.4874","1.9593"
"","24.6800","20.5226","1.9691"
"","24.7200","20.5545","1.9684"
"","24.7600","20.5890","1.9764"
"","24.8000","20.6230","1.9793"
"","24.8400","20.6539","1.9799"
"","24.8800","20.6882","1.9885"
"","24.9200","20.7225","1.9954"
"","24.9600","20.7544","1.9934"
"","25.0000","20.7890","1.9986"
"","25.0400","20.8221","2.0027"
"","25.0800","20.8540","2.0031"
"","25.1200","20.8895","2.0086"
"","25.1600","20.9225","2.0150"
"","25.2000","20.9536","2.0116"
"","25.2400","20.9885","2.0167"
"","25.2800","21.0218","2.0214"
"","25.3200","21.0557","2.0246"
"","25.3600","21.0888","2.0243"
"","25.4000","21.1206","2.0222"
"","25.4400","21.1554","2.0337"
"","25.4800","21.1893","2.0333"
"","25.5200","21.2217","2.0317"
"","25.5600","21.2558","2.0402"
"","25.6000","21.2873","2.0371"
"","25.6400","21.3212","2.0454"
"","25.6800","21.3559","2.0351"
"","25.7200","21.3879","2.0332"
"","25.7600","21.4214","2.0475"
"","25.8000","21.4552","2.0455"
"","25.8400","21.4882","2.0540"
"","25.8800","21.5227","2.0585"
"","25.9200","21.5552","2.0386"
"","25.9600","21.5875","2.0455"
"","26.0000","21.6218","2.0539"
"","26.0400","21.6547","2.0587"
"","26.0800","21.6882","2.0565"
"","26.1200","21.7224","2.0466"
"","26.1600","21.7538","2.0534"
"","26.2000","21.7880","2.0645"
"","26.2400","21.8237","2.0746"
"","26.2800","21.8551","2.0745"
"","26.3200","21.8890","2.0807"
"","26.3600","21.9216","2.0833"
"","26.4000","21.9532","2.0865"
"","26.4400","21.9895","2.0693"
"","26.4800","22.0229","2.0764"
"","26.5200","22.0537","2.0827"
"","26.5600","22.0890","2.0930"
"","26.6000","22.1220","2.0847"
"","26.6400","22.1556","2.0784"
"","26.6800","22.1894","2.0924"
"","26.7200","22.2209","2.1017"
"","26.7600","22.2546","2.1048"
"","26.8000","22.2901","2.0944"
"","26.8400","22.3217","2.1060"
"","26.8800","22.3547","2.1152"
"","26.9200","22.3885","2.1211"
"","26.9600","22.4219","2.1199"
"","27.0000","22.4555","2.1127"
"","27.0400","22.4888","2.1264"
"","27.0800","22.5212","2.1281"
"","27.1200","22.5547","2.1166"
"","27.1600","22.5879","2.1299"
"","27.2000","22.6220","2.1410"
"","27.2400","22.6559","2.1326"
"","27.2800","22.6879","2.1369"
"","27.3200","22.7223","2.1493"
"","27.3600","22.7563","2.1439"
"","27.4000","22.7879","2.1484"
"","27.4400","22.8221","2.1442"
"","27.4800","22.8546","2.1451"
"","27.5200","22.8877","2.1503"
"","27.5600","22.9231","2.1519"
"","27.6000","22.9548","2.1554"
"","27.6400","22.9881","2.1553"
"","27.6800","23.0225","2.1564"
"","27.7200","23.0546","2.1567"
"","27.7600","23.0892","2.1651"
"","27.8000","23.1233","2.1659"
"","27.8400","23.1538","2.1608"
"","27.8800","23.1881","2.1631"
"","27.9200","23.2224","2.1716"
"","27.9600","23.2552","2.1730"
"","28.0000","23.2889","2.1738"
"","28.0400","23.3218","2.1734"
"","28.0800","23.3545","2.1761"
"","28.1200","23.3896","2.1765"
"","28.1600","23.4223","2.1776"
"","28.2000","23.4543","2.1772"
"","28.2400","23.4885","2.1811"
"","28.2800","23.5220","2.1851"
"","28.3200","23.5555","2.1853"
"","28.3600","23.5893","2.1845"
"","28.4000","23.6204","2.1818"
"","28.4400","23.6551","2.1862"
"","28.4800","23.6893","2.1884"
"","28.5200","23.7220","2.1871"
"","28.5600","23.7557","2.1865"
"","28.6000","23.7875","2.1838"
"","28.6400","23.8212","2.1883"
"","28.6800","23.8559","2.1892"
"","28.7200","23.8884","2.1898"
"","28.7600","23.9218","2.1932"
"","28.8000","23.9552","2.1965"
"","28.8400","23.9884","2.2045"
"","28.8800","24.0226","2.2133"
"","28.9200","24.0562","2.2151"
"","28.9600","24.0879","2.2179"
"","29.0000","24.1216","2.2264"
"","29.0400","24.1547","2.2308"
"","29.0800","24.1892","2.2409"
"","29.1200","24.2226","2.2462"
"","29.1600","24.2537","2.2454"
"","29.2000","24.2881","2.2535"
"","29.2400","24.3232","2.2608"
"","29.2800","24.3553","2.2635"
"","29.3200","24.3882","2.2661"
"","29.3600","24.4220","2.2698"
"","29.4000","24.4524","2.2710"
"","29.4400","24.4896","2.2836"
"","29.4800","24.5229","2.2901"
"","29.5200","24.5533","2.2870"
"","29.5600","24.5888","2.2980"
"","29.6000","24.6224","2.3086"
"","29.6400","24.6550","2.3134"
"","29.6800","24.6898","2.3213"
"","29.7200","24.7208","2.3253"
"","29.7600","24.7542","2.3322"
"","29.8000","24.7895","2.3436"
"","29.8400","24.8216","2.3472"
"","29.8800","24.8545","2.3529"
"","29.9200","24.8884","2.3576"
"","29.9600","24.9217","2.3650"
"","30.0000","24.9553","2.3713"
"","30.0400","24.9888","2.3711"
"","30.0800","25.0216","2.3767"
"","30.1200","25.0547","2.3775"
"","30.1600","25.0876","2.3812"
"","30.2000","25.1225","2.3900"
"","30.2400","25.1558","2.3917"
"","30.2800","25.1879","2.3915"
"","30.3200","25.2222","2.3974"
"","30.3600","25.2559","2.4030"
"","30.4000","25.2875","2.4021"
"","30.4400","25.3224","2.4079"
"","30.4800","25.3545","2.4086"
"","30.5200","25.3870","2.4125"
"","30.5600","25.4232","2.4227"
"","30.6000","25.4549","2.4194"
"","30.6400","25.4880","2.4236"
"","30.6800","25.5225","2.4300"
"","30.7200","25.5549","2.4318"
"","30.7600","25.5891","2.4387"
"","30.8000","25.6233","2.4433"
"","30.8400","25.6539","2.4411"
"","30.8800","25.6879","2.4475"
"","30.9200","25.7223","2.4527"
"","30.9600","25.7547","2.4565"
"","31.0000","25.7888","2.4608"
"","31.0400","25.8215","2.4631"
"","31.0800","25.8548","2.4695"
"","31.1200","25.8895","2.4757"
"","31.1600","25.9223","2.4767"
"","31.2000","25.9543","2.4768"
"","31.2400","25.9881","2.4827"
"","31.2800","26.0222","2.4873"
"","31.3200","26.0553","2.4903"
"","31.3600","26.0899","2.4949"
"","31.4000","26.1204","2.4915"
"","31.4400","26.1547","2.5009"
"","31.4800","26.1893","2.5076"
"","31.5200","26.2219","2.5084"
"","31.5600","26.2553","2.5105"
"","31.6000","26.2878","2.5145"
"","31.6400","26.3211","2.5210"
"","31.6800","26.3561","2.5271"
"","31.7200","26.3883","2.5285"
"","31.7600","26.4215","2.5331"
"","31.8000","26.4553","2.5373"
"","31.8400","26.4886","2.5436"
"","31.8800","26.5226","2.5495"
"","31.9200","26.5558","2.5538"
"","31.9600","26.5874","2.5566"
"","32.0000","26.6218","2.5634"
"","32.0400","26.6550","2.5650"
"","32.0800","26.6886","2.5741"
"","32.1200","26.7226","2.5761"
"","32.1600","26.7538","2.5792"
"","32.2000","26.7882","2.5864"
"","32.2400","26.8233","2.5934"
"","32.2800","26.8552","2.5951"
"","32.3200","26.8882","2.5989"
"","32.3600","26.9223","2.6056"
"","32.4000","26.9534","2.6077"
"","32.4400","26.9889","2.6159"
"","32.4800","27.0231","2.6199"
"","32.5200","27.0535","2.6195"
"","32.5600","27.0889","2.6278"
"","32.6000","27.1225","2.6329"
"","32.6400","27.1548","2.6327"
"","32.6800","27.1897","2.6435"
"","32.7200","27.2206","2.6398"
"","32.7600","27.2539","2.6430"
"","32.8000","27.2900","2.6570"
"","32.8400","27.3223","2.6444"
"","32.8800","27.3548","2.6237"
"","32.9200","27.3886","2.6406"
"","32.9600","27.4214","2.6531"
"","33.0000","27.4557","2.6591"
"","33.0400","27.4887","2.6628"
"","33.0800","27.5212","2.6692"
"","33.1200","27.5549","2.6296"
"","33.1600","27.5876","2.6388"
"","33.2000","27.6225","2.6584"
"","33.2400","27.6556","2.6660"
"","33.2800","27.6877","2.6666"
"","33.3200","27.7225","2.6773"
"","33.3600","27.7560","2.6664"
"","33.4000","27.7881","2.6289"
"","33.4400","27.8220","2.6422"
"","33.4800","27.8548","2.6530"
"","33.5200","27.8870","2.6592"
"","33.5600","27.9228","2.6667"
"","33.6000","27.9555","2.6674"
"","33.6400","27.9876","2.6244"
"","33.6800","28.0229","2.6182"
"","33.7200","28.0546","2.6318"
"","33.7600","28.0888","2.6414"
"","33.8000","28.1234","2.6115"
"","33.8400","28.1535","2.5879"
"","33.8800","28.1883","2.6033"
"","33.9200","28.2224","2.6032"
"","33.9600","28.2547","2.5720"
"","34.0000","28.2891","2.5818"
"","34.0400","28.3214","2.5665"
"","34.0800","28.3551","2.5521"
"","34.1200","28.3896","2.5645"
"","34.1600","28.4223","2.5349"
"","34.2000","28.4544","2.5394"
"","34.2400","28.4881","2.5221"
"","34.2800","28.5222","2.5254"
"","34.3200","28.5554","2.5110"
"","34.3600","28.5896","2.4966"
"","34.4000","28.6207","2.4769"
"","34.4400","28.6542","2.4688"
"","34.4800","28.6891","2.4595"
"","34.5200","28.7217","2.4511"
"","34.5600","28.7555","2.4439"
"","34.6000","28.7881","2.4343"
"","34.6400","28.8211","2.4314"
"","34.6800","28.8562","2.4307"
"","34.7200","28.8880","2.4255"
"","34.7600","28.9212","2.4248"
"","34.8000","28.9553","2.4243"
"","34.8400","28.9882","2.4238"
"","34.8800","29.0224","2.4253"
"","34.9200","29.0558","2.4216"
"","34.9600","29.0874","2.4189"
"","35.0000","29.1214","2.4227"
"","35.0400","29.1548","2.4207"
"","35.0800","29.1888","2.4229"
"","35.1200","29.2226","2.4247"
"","35.1600","29.2538","2.4205"
"","35.2000","29.2882","2.4241"
"","35.2400","29.3232","2.4277"
"","35.2800","29.3550","2.4245"
"","35.3200","29.3885","2.4251"
"","35.3600","29.4223","2.4240"
"","35.4000","29.4539","2.4236"
"","35.4400","29.4889","2.4276"
"","35.4800","29.5230","2.4311"
"","35.5200","29.5537","2.4261"
"","35.5600","29.5884","2.4283"
"","35.6000","29.6229","2.4329"
"","35.6400","29.6544","2.4311"
"","35.6800","29.6895","2.4326"
"","35.7200","29.7211","2.4301"
"","35.7600","29.7543","2.4329"
"","35.8000","29.7895","2.4360"
"","35.8400","29.8220","2.4361"
"","35.8800","29.8545","2.4345"
"","35.9200","29.8885","2.4358"
"","35.9600","29.9214","2.4380"
"","36.0000","29.9558","2.4391"
"","36.0400","29.9892","2.4389"
"","36.0520","30.0000","2.4403"
2,Time,Displacement,Force
,(s),(mm),(kgf)
"","0.0000","0.0000","-0.0016"
"","0.0400","0.0033","-0.0016"
"","0.0800","0.0225","0.0056"
"","0.1200","0.0613","0.0032"
"","0.1600","0.0926","0.0067"
"","0.2000","0.1256","0.0080"
"","0.2400","0.1581","0.0124"
"","0.2800","0.1895","0.0135"
"","0.3200","0.2237","0.0171"
"","0.3600","0.2559","0.0204"
"","0.4000","0.2891","0.0215"
"","0.4400","0.3235","0.0266"
"","0.4800","0.3545","0.0308"
"","0.5200","0.3894","0.0303"
"","0.5600","0.4240","0.0379"
"","0.6000","0.4549","0.0405"
"","0.6400","0.4888","0.0425"
"","0.6800","0.5222","0.0449"
"","0.7200","0.5545","0.0497"
"","0.7600","0.5899","0.0535"
"","0.8000","0.6223","0.0552"
"","0.8400","0.6549","0.0604"
"","0.8800","0.6893","0.0653"
"","0.9200","0.7231","0.0667"
"","0.9600","0.7551","0.0688"
"","1.0000","0.7897","0.0781"
"","1.0400","0.8219","0.0797"
"","1.0800","0.8547","0.0826"
"","1.1200","0.8893","0.0885"
"","1.1600","0.9222","0.0908"
"","1.2000","0.9554","0.0957"
"","1.2400","0.9890","0.1013"
"","1.2800","1.0218","0.1043"
"","1.3200","1.0567","0.1082"
"","1.3600","1.0888","0.1134"
"","1.4000","1.1218","0.1145"
"","1.4400","1.1552","0.1209"
"","1.4800","1.1881","0.1264"
"","1.5200","1.2231","0.1288"
"","1.5600","1.2562","0.1340"
"","1.6000","1.2871","0.1373"
"","1.6400","1.3225","0.1428"
"","1.6800","1.3558","0.1466"
"","1.7200","1.3887","0.1515"
"","1.7600","1.4235","0.1560"
"","1.8000","1.4544","0.1578"
"","1.8400","1.4882","0.1596"
"","1.8800","1.5232","0.1653"
"","1.9200","1.5553","0.1693"
"","1.9600","1.5880","0.1731"
"","2.0000","1.6226","0.1799"
"","2.0400","1.6552","0.1825"
"","2.0800","1.6894","0.1863"
"","2.1200","1.7232","0.1925"
"","2.1600","1.7544","0.1947"
"","2.2000","1.7886","0.1992"
"","2.2400","1.8230","0.2030"
"","2.2800","1.8548","0.2050"
"","2.3200","1.8900","0.2118"
"","2.3600","1.9217","0.2130"
"","2.4000","1.9548","0.2166"
"","2.4400","1.9902","0.2216"
"","2.4800","2.0223","0.2218"
"","2.5200","2.0558","0.2258"
"","2.5600","2.0890","0.2297"
"","2.6000","2.1217","0.2264"
"","2.6400","2.1557","0.2288"
"","2.6800","2.1889","0.2333"
"","2.7200","2.2215","0.2343"
"","2.7600","2.2556","0.2383"
"","2.8000","2.2889","0.2421"
"","2.8400","2.3228","0.2413"
"","2.8800","2.3558","0.2430"
"","2.9200","2.3879","0.2447"
"","2.9600","2.4214","0.2447"
"","3.0000","2.4562","0.2478"
"","3.0400","2.4886","0.2432"
"","3.0800","2.5219","0.2425"
"","3.1200","2.5553","0.2453"
"","3.1600","2.5889","0.2422"
"","3.2000","2.6235","0.2336"
"","3.2400","2.6559","0.2295"
"","3.2800","2.6877","0.2336"
"","3.3200","2.7231","0.2373"
"","3.3600","2.7549","0.2389"
"","3.4000","2.7888","0.2401"
"","3.4400","2.8229","0.2457"
"","3.4800","2.8540","0.2414"
"","3.5200","2.8888","0.2394"
"","3.5600","2.9236","0.2402"
"","3.6000","2.9551","0.2437"
"","3.6400","2.9888","0.2508"
"","3.6800","3.0218","0.2529"
"","3.7200","3.0542","0.2569"
"","3.7600","3.0901","0.2625"
"","3.8000","3.1228","0.2662"
"","3.8400","3.1547","0.2670"
"","3.8800","3.1893","0.2728"
"","3.9200","3.2226","0.2718"
"","3.9600","3.2553","0.2703"
"","4.0000","3.2899","0.2706"
"","4.0400","3.3221","0.2753"
"","4.0800","3.3545","0.2765"
"","4.1200","3.3894","0.2773"
"","4.1600","3.4229","0.2775"
"","4.2000","3.4554","0.2796"
"","4.2400","3.4885","0.2854"
"","4.2800","3.5221","0.2892"
"","4.3200","3.5571","0.2917"
"","4.3600","3.5886","0.2958"
"","4.4000","3.6217","0.2984"
"","4.4400","3.6552","0.3018"
"","4.4800","3.6878","0.3041"
"","4.5200","3.7232","0.3061"
"","4.5600","3.7562","0.3074"
"","4.6000","3.7877","0.3044"
"","4.6400","3.8224","0.3085"
"","4.6800","3.8560","0.3086"
"","4.7200","3.8882","0.3086"
"","4.7600","3.9234","0.3098"
"","4.8000","3.9543","0.3090"
"","4.8400","3.9883","0.3086"
"","4.8800","4.0229","0.3121"
"","4.9200","4.0552","0.3147"
"","4.9600","4.0878","0.3104"
"","5.0000","4.1228","0.3119"
"","5.0400","4.1545","0.3110"
"","5.0800","4.1894","0.3131"
"","5.1200","4.2235","0.3139"
"","5.1600","4.2540","0.3133"
"","5.2000","4.2888","0.3135"
"","5.2400","4.3229","0.3139"
"","5.2800","4.3546","0.3132"
"","5.3200","4.3899","0.3137"
"","5.3600","4.4217","0.3150"
"","5.4000","4.4539","0.3188"
"","5.4400","4.4888","0.3253"
"","5.4800","4.5227","0.3332"
"","5.5200","4.5559","0.3406"
"","5.5600","4.5893","0.3476"
"","5.6000","4.6220","0.3526"
"","5.6400","4.6555","0.3571"
"","5.6800","4.6892","0.3638"
"","5.7200","4.7209","0.3648"
"","5.7600","4.7562","0.3722"
"","5.8000","4.7897","0.3798"
"","5.8400","4.8224","0.3815"
"","5.8800","4.8555","0.3882"
"","5.9200","4.8885","0.3918"
"","5.9600","4.9215","0.3953"
"","6.0000","4.9559","0.3970"
"","6.0400","4.9890","0.4000"
"","6.0800","5.0219","0.4007"
"","6.1200","5.0555","0.4073"
"","6.1600","5.0887","0.4093"
"","6.2000","5.1231","0.4125"
"","6.2400","5.1564","0.4177"
"","6.2800","5.1870","0.4165"
"","6.3200","5.2230","0.4232"
"","6.3600","5.2547","0.4250"
"","6.4000","5.2884","0.4278"
"","6.4400","5.3227","0.4329"
"","6.4800","5.3543","0.4356"
"","6.5200","5.3892","0.4365"
"","6.5600","5.4236","0.4392"
"","6.6000","5.4557","0.4341"
"","6.6400","5.4884","0.4366"
"","6.6800","5.5222","0.4388"
"","6.7200","5.5539","0.4398"
"","6.7600","5.5899","0.4453"
"","6.8000","5.6230","0.4459"
"","6.8400","5.6545","0.4434"
"","6.8800","5.6892","0.4456"
"","6.9200","5.7226","0.4368"
"","6.9600","5.7556","0.4308"
"","7.0000","5.7897","0.4328"
"","7.0400","5.8217","0.4324"
"","7.0800","5.8546","0.4344"
"","7.1200","5.8894","0.4399"
"","7.1600","5.9223","0.4423"
"","7.2000","5.9554","0.4416"
"","7.2400","5.9889","0.4469"
"","7.2800","6.0218","0.4447"
"","7.3200","6.0570","0.4513"
"","7.3600","6.0890","0.4502"
"","7.4000","6.1218","0.4524"
"","7.4400","6.1551","0.4563"
"","7.4800","6.1881","0.4601"
"","7.5200","6.2232","0.4590"
"","7.5600","6.2560","0.4573"
"","7.6000","6.2882","0.4568"
"","7.6400","6.3223","0.4593"
"","7.6800","6.3556","0.4576"
"","7.7200","6.3892","0.4496"
"","7.7600","6.4230","0.4455"
"","7.8000","6.4551","0.4391"
"","7.8400","6.4877","0.4287"
"","7.8800","6.5233","0.4292"
"","7.9200","6.5551","0.4323"
"","7.9600","6.5882","0.4332"
"","8.0000","6.6228","0.4387"
"","8.0400","6.6552","0.4361"
"","8.0800","6.6895","0.4395"
"","8.1200","6.7232","0.4434"
"","8.1600","6.7541","0.4446"
"","8.2000","6.7887","0.4434"
"","8.2400","6.8232","0.4412"
"","8.2800","6.8548","0.4372"
"","8.3200","6.8895","0.4366"
"","8.3600","6.9226","0.4253"
"","8.4000","6.9543","0.4246"
"","8.4400","6.9901","0.4284"
"","8.4800","7.0222","0.4260"
"","8.5200","7.0553","0.4261"
"","8.5600","7.0892","0.4312"
"","8.6000","7.1218","0.4283"
"","8.6400","7.1554","0.4164"
"","8.6800","7.1888","0.4206"
"","8.7200","7.2218","0.4181"
"","8.7600","7.2555","0.4246"
"","8.8000","7.2897","0.4291"
"","8.8400","7.3224","0.4253"
"","8.8800","7.3560","0.4015"
"","8.9200","7.3878","0.3977"
"","8.9600","7.4218","0.4007"
"","9.0000","7.4566","0.4045"
"","9.0400","7.4886","0.3988"
"","9.0800","7.5224","0.3974"
"","9.1200","7.5552","0.3999"
"","9.1600","7.5886","0.3957"
"","9.2000","7.6234","0.3803"
"","9.2400","7.6559","0.3558"
"","9.2800","7.6879","0.3543"
"","9.3200","7.7226","0.3589"
"","9.3600","7.7552","0.3603"
"","9.4000","7.7886","0.3611"
"","9.4400","7.8229","0.3655"
"","9.4800","7.8542","0.3684"
"","9.5200","7.8888","0.3739"
"","9.5600","7.9242","0.3667"
"","9.6000","7.9556","0.3685"
"","9.6400","7.9884","0.3715"
"","9.6800","8.0215","0.3811"
"","9.7200","8.0544","0.3815"
"","9.7600","8.0899","0.3852"
"","9.8000","8.1229","0.3767"
"","9.8400","8.1539","0.3670"
"","9.8800","8.1894","0.3652"
"","9.9200","8.2227","0.3663"
"","9.9600","8.2551","0.3630"
"","10.0000","8.2898","0.3673"
"","10.0400","8.3219","0.3698"
"","10.0800","8.3549","0.3744"
"","10.1200","8.3894","0.3789"
"","10.1600","8.4224","0.3762"
"","10.2000","8.4555","0.3783"
"","10.2400","8.4881","0.3850"
"","10.2800","8.5226","0.3853"
"","10.3200","8.5564","0.3873"
"","10.3600","8.5889","0.3866"
"","10.4000","8.6219","0.3878"
"","10.4400","8.6551","0.3882"
"","10.4800","8.6884","0.3907"
"","10.5200","8.7225","0.3927"
"","10.5600","8.7559","0.3982"
"","10.6000","8.7884","0.4033"
"","10.6400","8.8225","0.4085"
"","10.6800","8.8554","0.4140"
"","10.7200","8.8890","0.4166"
"","10.7600","8.9236","0.4207"
"","10.8000","8.9544","0.4245"
"","10.8400","8.9876","0.4142"
"","10.8800","9.0235","0.4193"
"","10.9200","9.0552","0.4177"
"","10.9600","9.0885","0.4168"
"","11.0000","9.1227","0.4171"
"","11.0400","9.1548","0.4195"
"","11.0800","9.1898","0.4242"
"","11.1200","9.2231","0.4257"
"","11.1600","9.2543","0.4254"
"","11.2000","9.2887","0.4302"
"","11.2400","9.3226","0.4320"
[...]
"","11.1200","9.2235","0.9181"
"","11.1600","9.2581","0.9278"
"","11.2000","9.2885","0.9325"
"","11.2400","9.3225","0.9403"
"","11.2800","9.3585","0.9517"
"","11.3200","9.3899","0.9542"
"","11.3600","9.4232","0.9609"
"","11.4000","9.4581","0.9714"
"","11.4400","9.4901","0.9763"
"","11.4800","9.5247","0.9851"
"","11.5200","9.5577","0.9920"
"","11.5600","9.5889","0.9976"
"","11.6000","9.6234","1.0032"
"","11.6400","9.6570","1.0108"
"","11.6800","9.6899","1.0170"
"","11.7200","9.7250","1.0258"
"","11.7600","9.7570","1.0327"
"","11.8000","9.7892","1.0369"
"","11.8400","9.8253","1.0478"
"","11.8800","9.8572","1.0529"
"","11.9200","9.8893","1.0575"
"","11.9600","9.9236","1.0667"
"","12.0000","9.9565","1.0712"
"","12.0400","9.9909","1.0789"
"","12.0800","10.0243","1.0854"
"","12.1200","10.0558","1.0884"
"","12.1600","10.0911","1.0967"
"","12.2000","10.1239","1.1023"
"","12.2400","10.1573","1.1083"
"","12.2800","10.1907","1.1130"
"","12.3200","10.2225","1.1189"
"","12.3600","10.2563","1.1275"
"","12.4000","10.2910","1.1345"
"","12.4400","10.3237","1.1427"
"","12.4800","10.3574","1.1470"
"","12.5200","10.3900","1.1506"
"","12.5600","10.4238","1.1584"
"","12.6000","10.4580","1.1652"
"","12.6400","10.4904","1.1671"
"","12.6800","10.5224","1.1723"
"","12.7200","10.5567","1.1817"
"","12.7600","10.5905","1.1867"
"","12.8000","10.6236","1.1916"
"","12.8400","10.6581","1.1990"
"","12.8800","10.6897","1.2031"
"","12.9200","10.7241","1.2087"
"","12.9600","10.7582","1.2141"
"","13.0000","10.7903","1.2176"
"","13.0400","10.8244","1.2253"
"","13.0800","10.8563","1.2293"
"","13.1200","10.8885","1.2343"
"","13.1600","10.9255","1.2450"
"","13.2000","10.9570","1.2456"
"","13.2400","10.9894","1.2497"
"","13.2800","11.0237","1.2556"
"","13.3200","11.0553","1.2575"
"","13.3600","11.0911","1.2689"
"","13.4000","11.1255","1.2748"
"","13.4400","11.1561","1.2749"
"","13.4800","11.1906","1.2805"
"","13.5200","11.2244","1.2866"
"","13.5600","11.2576","1.2901"
"","13.6000","11.2903","1.2954"
"","13.6400","11.3238","1.2979"
"","13.6800","11.3570","1.3018"
"","13.7200","11.3913","1.3066"
"","13.7600","11.4243","1.3087"
"","13.8000","11.4561","1.3120"
"","13.8400","11.4898","1.3160"
"","13.8800","11.5232","1.3197"
"","13.9200","11.5576","1.3216"
"","13.9600","11.5904","1.3255"
"","14.0000","11.6238","1.3305"
"","14.0400","11.6576","1.3330"
"","14.0800","11.6908","1.3353"
"","14.1200","11.7240","1.3393"
"","14.1600","11.7578","1.3430"
"","14.2000","11.7890","1.3424"
"","14.2400","11.8228","1.3505"
"","14.2800","11.8583","1.3567"
"","14.3200","11.8897","1.3569"
"","14.3600","11.9240","1.3604"
"","14.4000","11.9576","1.3658"
"","14.4400","11.9899","1.3687"
"","14.4800","12.0256","1.3777"
"","14.5200","12.0577","1.3781"
"","14.5600","12.0889","1.3794"
"","14.6000","12.1234","1.3854"
"","14.6400","12.1567","1.3910"
"","14.6800","12.1897","1.3959"
"","14.7200","12.2243","1.3991"
"","14.7600","12.2578","1.4042"
"","14.8000","12.2896","1.4083"
"","14.8400","12.3255","1.4175"
"","14.8800","12.3572","1.4209"
"","14.9200","12.3895","1.4286"
"","14.9600","12.4239","1.4361"
"","15.0000","12.4563","1.4385"
"","15.0400","12.4915","1.4479"
"","15.0800","12.5245","1.4520"
"","15.1200","12.5559","1.4557"
"","15.1600","12.5911","1.4640"
"","15.2000","12.6244","1.4706"
"","15.2400","12.6571","1.4751"
"","15.2800","12.6913","1.4808"
"","15.3200","12.7225","1.4823"
"","15.3600","12.7565","1.4952"
"","15.4000","12.7910","1.4997"
"","15.4400","12.8239","1.5042"
"","15.4800","12.8576","1.5099"
"","15.5200","12.8897","1.5128"
"","15.5600","12.9237","1.5210"
"","15.6000","12.9581","1.5330"
"","15.6400","12.9897","1.5327"
"","15.6800","13.0227","1.5413"
"","15.7200","13.0570","1.5465"
"","15.7600","13.0902","1.5527"
"","15.8000","13.1238","1.5613"
"","15.8400","13.1578","1.5671"
"","15.8800","13.1893","1.5696"
"","15.9200","13.2238","1.5803"
"","15.9600","13.2580","1.5844"
"","16.0000","13.2898","1.5865"
"","16.0400","13.3242","1.5941"
"","16.0800","13.3562","1.5976"
"","16.1200","13.3886","1.5990"
"","16.1600","13.4252","1.6083"
"","16.2000","13.4573","1.6118"
"","16.2400","13.4893","1.6139"
"","16.2800","13.5246","1.6237"
"","16.3200","13.5575","1.6302"
"","16.3600","13.5902","1.6341"
"","16.4000","13.6250","1.6414"
"","16.4400","13.6561","1.6438"
"","16.4800","13.6898","1.6486"
"","16.5200","13.7242","1.6595"
"","16.5600","13.7570","1.6619"
"","16.6000","13.7903","1.6686"
"","16.6400","13.8230","1.6710"
"","16.6800","13.8572","1.6801"
"","16.7200","13.8914","1.6856"
"","16.7600","13.9245","1.6892"
"","16.8000","13.9558","1.6923"
"","16.8400","13.9899","1.6985"
"","16.8800","14.0234","1.7079"
"","16.9200","14.0576","1.7133"
"","16.9600","14.0906","1.7145"
"","17.0000","14.1230","1.7221"
"","17.0400","14.1580","1.7279"
"","17.0800","14.1908","1.7318"
"","17.1200","14.2237","1.7363"
"","17.1600","14.2576","1.7416"
"","17.2000","14.2888","1.7425"
"","17.2400","14.3229","1.7520"
"","17.2800","14.3582","1.7603"
"","17.3200","14.3898","1.7613"
"","17.3600","14.4232","1.7633"
"","17.4000","14.4582","1.7726"
"","17.4400","14.4901","1.7719"
"","17.4800","14.5247","1.7791"
"","17.5200","14.5577","1.7828"
"","17.5600","14.5889","1.7846"
"","17.6000","14.6236","1.7920"
"","17.6400","14.6570","1.7972"
"","17.6800","14.6898","1.8017"
"","17.7200","14.7248","1.8074"
"","17.7600","14.7568","1.8087"
"","17.8000","14.7898","1.8125"
"","17.8400","14.8251","1.8197"
"","17.8800","14.8569","1.8227"
"","17.9200","14.8896","1.8259"
"","17.9600","14.9236","1.8331"
"","18.0000","14.9560","1.8362"
"","18.0400","14.9911","1.8417"
"","18.0800","15.0241","1.8453"
"","18.1200","15.0558","1.8485"
"","18.1600","15.0910","1.8544"
"","18.2000","15.1242","1.8579"
"","18.2400","15.1569","1.8598"
"","18.2800","15.1906","1.8633"
"","18.3200","15.2223","1.8663"
"","18.3600","15.2564","1.8713"
"","18.4000","15.2912","1.8757"
"","18.4400","15.3243","1.8791"
"","18.4800","15.3573","1.8801"
"","18.5200","15.3906","1.8816"
"","18.5600","15.4238","1.8873"
"","18.6000","15.4581","1.8926"
"","18.6400","15.4900","1.8898"
"","18.6800","15.5225","1.8931"
"","18.7200","15.5572","1.8964"
"","18.7600","15.5901","1.9012"
"","18.8000","15.6240","1.9058"
"","18.8400","15.6575","1.9040"
"","18.8800","15.6898","1.9056"
"","18.9200","15.7238","1.9077"
"","18.9600","15.7582","1.9109"
"","19.0000","15.7903","1.9094"
"","19.0400","15.8241","1.9114"
"","19.0800","15.8566","1.9108"
"","19.1200","15.8888","1.9108"
"","19.1600","15.9251","1.9161"
"","19.2000","15.9576","1.9180"
"","19.2400","15.9889","1.9100"
"","19.2800","16.0243","1.9138"
"","19.3200","16.0576","1.9136"
"","19.3600","16.0902","1.9113"
"","19.4000","16.1247","1.9108"
"","19.4400","16.1563","1.9041"
"","19.4800","16.1895","1.9062"
"","19.5200","16.2245","1.9094"
"","19.5600","16.2570","1.9054"
"","19.6000","16.2903","1.9019"
"","19.6400","16.3231","1.9009"
"","19.6800","16.3566","1.9020"
"","19.7200","16.3917","1.9012"
"","19.7600","16.4241","1.8975"
"","19.8000","16.4568","1.8961"
"","19.8400","16.4897","1.8927"
"","19.8800","16.5236","1.8959"
"","19.9200","16.5573","1.8970"
"","19.9600","16.5903","1.8915"
"","20.0000","16.6239","1.8881"
"","20.0400","16.6575","1.8844"
"","20.0800","16.6907","1.8796"
"","20.1200","16.7233","1.8737"
"","20.1600","16.7576","1.8690"
"","20.2000","16.7897","1.8637"
"","20.2400","16.8227","1.8620"
"","20.2800","16.8580","1.8658"
"","20.3200","16.8905","1.8666"
"","20.3600","16.9235","1.8683"
"","20.4000","16.9580","1.8693"
"","20.4400","16.9900","1.8654"
"","20.4800","17.0251","1.8609"
"","20.5200","17.0577","1.8544"
"","20.5600","17.0888","1.8528"
"","20.6000","17.1238","1.8578"
"","20.6400","17.1570","1.8618"
"","20.6800","17.1895","1.8616"
"","20.7200","17.2246","1.8655"
"","20.7600","17.2568","1.8661"
"","20.8000","17.2903","1.8646"
"","20.8400","17.3249","1.8658"
"","20.8800","17.3569","1.8666"
"","20.9200","17.3901","1.8642"
"","20.9600","17.4232","1.8643"
"","21.0000","17.4567","1.8677"
"","21.0400","17.4906","1.8674"
"","21.0800","17.5242","1.8674"
"","21.1200","17.5561","1.8630"
"","21.1600","17.5909","1.8608"
"","21.2000","17.6245","1.8604"
"","21.2400","17.6566","1.8563"
"","21.2800","17.6911","1.8543"
"","21.3200","17.7229","1.8460"
"","21.3600","17.7564","1.8402"
"","21.4000","17.7906","1.8390"
"","21.4400","17.8242","1.8378"
"","21.4800","17.8577","1.8316"
"","21.5200","17.8900","1.8244"
"","21.5600","17.9241","1.8245"
"","21.6000","17.9580","1.8217"
"","21.6400","17.9900","1.8129"
"","21.6800","18.0223","1.8129"
"","21.7200","18.0576","1.8185"
"","21.7600","18.0896","1.8157"
"","21.8000","18.1246","1.8204"
"","21.8400","18.1575","1.8145"
"","21.8800","18.1893","1.8083"
"","21.9200","18.2242","1.8112"
"","21.9600","18.2577","1.8079"
"","22.0000","18.2904","1.8051"
"","22.0400","18.3239","1.8048"
"","22.0800","18.3566","1.7995"
"","22.1200","18.3890","1.7983"
"","22.1600","18.4248","1.7990"
"","22.2000","18.4576","1.7964"
"","22.2400","18.4885","1.7889"
"","22.2800","18.5248","1.7911"
"","22.3200","18.5575","1.7900"
"","22.3600","18.5905","1.7873"
"","22.4000","18.6244","1.7869"
"","22.4400","18.6565","1.7792"
"","22.4800","18.6896","1.7771"
"","22.5200","18.7246","1.7733"
"","22.5600","18.7569","1.7665"
"","22.6000","18.7907","1.7606"
"","22.6400","18.8234","1.7573"
"","22.6800","18.8571","1.7571"
"","22.7200","18.8913","1.7510"
"","22.7600","18.9244","1.7298"
"","22.8000","18.9569","1.7062"
"","22.8400","18.9898","1.6243"
"","22.8800","19.0234","1.6024"
"","22.9200","19.0573","1.5985"
"","22.9600","19.0904","1.5951"
"","23.0000","19.1232","1.5897"
"","23.0400","19.1581","1.5641"
"","23.0800","19.1907","1.5503"
"","23.1200","19.2236","1.5464"
"","23.1600","19.2577","1.5431"
"","23.2000","19.2897","1.5331"
"","23.2400","19.3225","1.5271"
"","23.2800","19.3582","1.5274"
"","23.3200","19.3902","1.5210"
"","23.3600","19.4234","1.5171"
"","23.4000","19.4573","1.5134"
"","23.4400","19.4881","1.5008"
"","23.4800","19.5240","1.4975"
"","23.5200","19.5586","1.4899"
"","23.5600","19.5896","1.4798"
"","23.6000","19.6245","1.4758"
"","23.6400","19.6569","1.4698"
"","23.6800","19.6902","1.4646"
"","23.7200","19.7248","1.4619"
"","23.7600","19.7567","1.4510"
"","23.8000","19.7904","1.4473"
"","23.8400","19.8251","1.4415"
"","23.8800","19.8565","1.4293"
"","23.9200","19.8902","1.4221"
"","23.9600","19.9229","1.4180"
"","24.0000","19.9562","1.4121"
"","24.0400","19.9912","1.4072"
"","24.0800","20.0238","1.3953"
"","24.1200","20.0561","1.3853"
"","24.1600","20.0908","1.3829"
"","24.2000","20.1244","1.3737"
"","24.2400","20.1570","1.3597"
"","24.2800","20.1910","1.3538"
"","24.3200","20.2229","1.3436"
"","24.3600","20.2561","1.3110"
"","24.4000","20.2910","1.2965"
"","24.4400","20.3240","1.2883"
"","24.4800","20.3573","1.2792"
"","24.5200","20.3905","1.2753"
"","24.5600","20.4236","1.2654"
"","24.6000","20.4582","1.2414"
"","24.6400","20.4896","1.2366"
"","24.6800","20.5232","1.2351"
"","24.7200","20.5571","1.2297"
"","24.7600","20.5894","1.2243"
"","24.8000","20.6246","1.2266"
"","24.8400","20.6580","1.2228"
"","24.8800","20.6892","1.2155"
"","24.9200","20.7235","1.2141"
"","24.9600","20.7574","1.2061"
"","25.0000","20.7906","1.2032"
"","25.0400","20.8243","1.2014"
"","25.0800","20.8564","1.1976"
"","25.1200","20.8889","1.1957"
"","25.1600","20.9248","1.1989"
"","25.2000","20.9574","1.1969"
"","25.2400","20.9892","1.1925"
"","25.2800","21.0247","1.1989"
"","25.3200","21.0575","1.1980"
"","25.3600","21.0900","1.1931"
"","25.4000","21.1248","1.1932"
"","25.4400","21.1560","1.1903"
"","25.4800","21.1896","1.1897"
"","25.5200","21.2247","1.1902"
"","25.5600","21.2563","1.1864"
"","25.6000","21.2907","1.1863"
"","25.6400","21.3238","1.1855"
"","25.6800","21.3565","1.1827"
"","25.7200","21.3914","1.1853"
"","25.7600","21.4236","1.1833"
"","25.8000","21.4570","1.1820"
"","25.8400","21.4899","1.1799"
"","25.8800","21.5228","1.1802"
"","25.9200","21.5578","1.1816"
"","25.9600","21.5908","1.1788"
"","26.0000","21.6232","1.1770"
"","26.0400","21.6580","1.1786"
"","26.0800","21.6905","1.1772"
"","26.1200","21.7235","1.1759"
"","26.1600","21.7569","1.1765"
"","26.2000","21.7900","1.1743"
"","26.2400","21.8231","1.1714"
"","26.2800","21.8585","1.1729"
"","26.3200","21.8905","1.1723"
"","26.3600","21.9238","1.1715"
"","26.4000","21.9580","1.1698"
"","26.4400","21.9902","1.1679"
"","26.4800","22.0253","1.1683"
"","26.5200","22.0580","1.1632"
"","26.5600","22.0879","1.1577"
"","26.6000","22.1243","1.1639"
"","26.6400","22.1575","1.1615"
"","26.6800","22.1895","1.1580"
"","26.7200","22.2245","1.1578"
"","26.7600","22.2567","1.1536"
"","26.8000","22.2903","1.1542"
"","26.8400","22.3244","1.1542"
"","26.8800","22.3569","1.1488"
"","26.9200","22.3900","1.1509"
"","26.9600","22.4236","1.1487"
"","27.0000","22.4567","1.1457"
"","27.0400","22.4905","1.1433"
"","27.0800","22.5245","1.1440"
"","27.1200","22.5562","1.1442"
"","27.1600","22.5909","1.1424"
"","27.2000","22.6243","1.1403"
"","27.2400","22.6570","1.1357"
"","27.2800","22.6909","1.1369"
"","27.3200","22.7230","1.1352"
"","27.3600","22.7562","1.1340"
"","27.4000","22.7907","1.1268"
"","27.4400","22.8238","1.1193"
"","27.4800","22.8576","1.0844"
"","27.5200","22.8905","1.0678"
"","27.5600","22.9233","1.0646"
"","27.6000","22.9576","1.0627"
"","27.6400","22.9894","1.0574"
"","27.6800","23.0233","1.0558"
"","27.7200","23.0574","1.0533"
"","27.7600","23.0894","1.0474"
"","27.8000","23.1247","1.0457"
"","27.8400","23.1578","1.0397"
"","27.8800","23.1894","1.0341"
"","27.9200","23.2239","1.0314"
"","27.9600","23.2582","1.0302"
"","28.0000","23.2901","1.0251"
"","28.0400","23.3239","1.0203"
"","28.0800","23.3568","1.0170"
"","28.1200","23.3891","1.0112"
"","28.1600","23.4249","1.0122"
"","28.2000","23.4573","1.0064"
"","28.2400","23.4891","0.9993"
"","28.2800","23.5247","1.0015"
"","28.3200","23.5574","0.9958"
"","28.3600","23.5904","0.9915"
"","28.4000","23.6246","0.9903"
"","28.4400","23.6563","0.9849"
"","28.4800","23.6899","0.9815"
"","28.5200","23.7242","0.9773"
"","28.5600","23.7569","0.9731"
"","28.6000","23.7905","0.9717"
"","28.6400","23.8235","0.9656"
"","28.6800","23.8569","0.9566"
"","28.7200","23.8909","0.9515"
"","28.7600","23.9240","0.9465"
"","28.8000","23.9569","0.9418"
"","28.8400","23.9902","0.9338"
"","28.8800","24.0227","0.9309"
"","28.9200","24.0575","0.9261"
"","28.9600","24.0905","0.9187"
"","29.0000","24.1235","0.9115"
"","29.0400","24.1579","0.9063"
"","29.0800","24.1903","0.9015"
"","29.1200","24.2240","0.8970"
"","29.1600","24.2574","0.8925"
"","29.2000","24.2892","0.8894"
"","29.2400","24.3230","0.8874"
"","29.2800","24.3578","0.8894"
"","29.3200","24.3904","0.8861"
"","29.3600","24.4233","0.8838"
"","29.4000","24.4577","0.8869"
"","29.4400","24.4902","0.8851"
"","29.4800","24.5251","0.8852"
"","29.5200","24.5577","0.8825"
"","29.5600","24.5885","0.8802"
"","29.6000","24.6240","0.8863"
"","29.6400","24.6567","0.8819"
"","29.6800","24.6898","0.8840"
"","29.7200","24.7238","0.8856"
"","29.7600","24.7568","0.8853"
"","29.8000","24.7903","0.8842"
"","29.8400","24.8253","0.8867"
"","29.8800","24.8567","0.8821"
"","29.9200","24.8895","0.8801"
"","29.9600","24.9231","0.8837"
"","30.0000","24.9558","0.8840"
"","30.0400","24.9907","0.8840"
"","30.0800","25.0236","0.8817"
"","30.1200","25.0564","0.8808"
"","30.1600","25.0903","0.8828"
"","30.2000","25.1244","0.8846"
"","30.2400","25.1572","0.8820"
"","30.2800","25.1908","0.8828"
"","30.3200","25.2229","0.8820"
"","30.3600","25.2563","0.8826"
"","30.4000","25.2911","0.8850"
"","30.4400","25.3240","0.8820"
"","30.4800","25.3574","0.8804"
"","30.5200","25.3906","0.8816"
"","30.5600","25.4229","0.8813"
"","30.6000","25.4585","0.8855"
"","30.6400","25.4902","0.8812"
"","30.6800","25.5232","0.8822"
"","30.7200","25.5571","0.8843"
"","30.7600","25.5893","0.8824"
"","30.8000","25.6243","0.8839"
"","30.8400","25.6585","0.8836"
"","30.8800","25.6890","0.8786"
"","30.9200","25.7238","0.8803"
"","30.9600","25.7581","0.8823"
"","31.0000","25.7898","0.8801"
"","31.0400","25.8242","0.8830"
"","31.0800","25.8564","0.8804"
"","31.1200","25.8891","0.8821"
"","31.1600","25.9244","0.8834"
"","31.2000","25.9573","0.8810"
"","31.2400","25.9895","0.8820"
"","31.2800","26.0246","0.8831"
"","31.3200","26.0574","0.8837"
"","31.3600","26.0900","0.8819"
"","31.4000","26.1248","0.8851"
"","31.4400","26.1562","0.8803"
"","31.4800","26.1896","0.8812"
"","31.5200","26.2242","0.8832"
"","31.5600","26.2566","0.8799"
"","31.6000","26.2910","0.8831"
"","31.6400","26.3233","0.8812"
"","31.6800","26.3568","0.8817"
"","31.7200","26.3907","0.8817"
"","31.7600","26.4232","0.8811"
"","31.8000","26.4570","0.8816"
"","31.8400","26.4906","0.8833"
"","31.8800","26.5232","0.8804"
"","31.9200","26.5573","0.8817"
"","31.9600","26.5906","0.8815"
"","32.0000","26.6232","0.8802"
"","32.0400","26.6579","0.8814"
"","32.0800","26.6905","0.8824"
"","32.1200","26.7240","0.8818"
"","32.1600","26.7574","0.8818"
"","32.2000","26.7894","0.8805"
"","32.2400","26.8230","0.8805"
"","32.2800","26.8581","0.8824"
"","32.3200","26.8906","0.8807"
"","32.3600","26.9233","0.8793"
"","32.4000","26.9580","0.8824"
"","32.4400","26.9906","0.8782"
"","32.4800","27.0248","0.8798"
"","32.5200","27.0580","0.8793"
"","32.5600","27.0884","0.8778"
"","32.6000","27.1240","0.8817"
"","32.6400","27.1570","0.8800"
"","32.6800","27.1898","0.8785"
"","32.7200","27.2243","0.8798"
"","32.7600","27.2568","0.8803"
"","32.8000","27.2905","0.8818"
"","32.8400","27.3255","0.8835"
"","32.8800","27.3571","0.8789"
"","32.9200","27.3895","0.8787"
"","32.9600","27.4236","0.8816"
"","33.0000","27.4559","0.8778"
"","33.0400","27.4909","0.8795"
"","33.0800","27.5244","0.8801"
"","33.1200","27.5565","0.8781"
"","33.1600","27.5902","0.8786"
"","33.2000","27.6245","0.8811"
"","33.2400","27.6572","0.8783"
"","33.2800","27.6909","0.8785"
"","33.3200","27.7230","0.8781"
"","33.3600","27.7565","0.8779"
"","33.4000","27.7907","0.8810"
"","33.4400","27.8243","0.8771"
"","33.4800","27.8574","0.8748"
"","33.5200","27.8906","0.8766"
"","33.5600","27.9229","0.8762"
"","33.6000","27.9581","0.8780"
"","33.6400","27.9909","0.8755"
"","33.6800","28.0227","0.8724"
"","33.7200","28.0569","0.8760"
"","33.7600","28.0892","0.8724"
"","33.8000","28.1245","0.8755"
"","33.8400","28.1584","0.8744"
"","33.8800","28.1893","0.8708"
"","33.9200","28.2238","0.8731"
"","33.9600","28.2585","0.8755"
"","34.0000","28.2894","0.8711"
"","34.0400","28.3246","0.8742"
"","34.0800","28.3568","0.8725"
"","34.1200","28.3888","0.8706"
"","34.1600","28.4247","0.8757"
"","34.2000","28.4574","0.8728"
"","34.2400","28.4891","0.8730"
"","34.2800","28.5248","0.8758"
"","34.3200","28.5576","0.8730"
"","34.3600","28.5903","0.8721"
"","34.4000","28.6246","0.8765"
"","34.4400","28.6564","0.8745"
"","34.4800","28.6898","0.8748"
"","34.5200","28.7245","0.8758"
"","34.5600","28.7565","0.8718"
"","34.6000","28.7908","0.8759"
"","34.6400","28.8237","0.8741"
"","34.6800","28.8564","0.8739"
"","34.7200","28.8911","0.8762"
"","34.7600","28.9241","0.8734"
"","34.8000","28.9567","0.8746"
"","34.8400","28.9901","0.8769"
"","34.8800","29.0230","0.8750"
"","34.9200","29.0573","0.8751"
"","34.9600","29.0907","0.8770"
"","35.0000","29.1230","0.8758"
"","35.0400","29.1574","0.8759"
"","35.0800","29.1905","0.8785"
"","35.1200","29.2237","0.8737"
"","35.1600","29.2574","0.8733"
"","35.2000","29.2890","0.8746"
"","35.2400","29.3227","0.8768"
"","35.2800","29.3582","0.8776"
"","35.3200","29.3902","0.8740"
"","35.3600","29.4234","0.8751"
"","35.4000","29.4580","0.8766"
"","35.4400","29.4899","0.8770"
"","35.4800","29.5250","0.8791"
"","35.5200","29.5579","0.8776"
"","35.5600","29.5884","0.8729"
"","35.6000","29.6237","0.8774"
"","35.6400","29.6576","0.8768"
"","35.6800","29.6895","0.8734"
"","35.7200","29.7241","0.8772"
"","35.7600","29.7568","0.8756"
"","35.8000","29.7901","0.8770"
"","35.8400","29.8252","0.8777"
"","35.8800","29.8574","0.8752"
"","35.9200","29.8894","0.8749"
"","35.9600","29.9235","0.8771"
"","36.0000","29.9562","0.8771"
"","36.0400","29.9906","0.8772"
"","36.0520","30.0001","0.8768"