File: Data/Test_3.csv
Data : Criteria 1,,"True"
Data : Data capture scheme,,"Default settings"
Data : Interval 1,(ms),"20.00"
Data : Measurement 1,,"Time"
End of test : Criteria 1,,"Measurement level"
End of test : Measurement 1,,"Displacement"
End of test : Value 1,(mm),"30.00"
Compressive strain (Displacement) : Primary source,,"Displacement"

Results Table 1
,Area under curve,Maximum Force,Displacement at Maximum Force,Modulus (Automatic Young's),Break location,Compressive displacement at Maximum Force,Compressive strain (Displacement) at Maximum Force,Compressive stress at Maximum Force,Energy at Maximum Force,Energy to X-intercept at Modulus (Automatic Young's)
,(J),(kgf),(mm),(kgf/mm^2),,(mm),(%),(kgf/mm^2),(J),(J)
"1","0.7543","3.38","20.66","3.68","-----","20.66","20.66","0.34","0.48","0.00"
"2","0.7628","3.40","23.94","3.96","-----","23.94","23.94","0.34","0.61","0.00"
"3","0.4958","2.35","20.48","2.53","-----","20.48","20.48","0.24","0.33","-----"
"4","0.4935","2.53","17.71","3.47","-----","17.71","17.71","0.25","0.32","-----"
"5","0.6631","3.46","16.58","3.42","-----","16.58","16.58","0.35","0.34","0.00"
"6","0.5248","2.80","18.77","2.75","-----","18.77","18.77","0.28","0.34","0.00"
"7","0.4595","3.58","27.27","2.27","-----","27.27","27.27","0.36","0.36","0.02"
"8","0.6146","3.76","23.45","2.24","-----","23.45","23.45","0.38","0.43","0.01"
"9","-----","2.88","21.69","1.92","-----","21.69","21.69","0.29","0.27","0.01"
"10","0.3518","2.07","19.02","1.89","-----","19.02","19.02","0.21","0.16","0.01"
"11","0.4372","3.07","25.24","1.12","-----","25.24","25.24","0.31","0.31","0.00"
"12","0.5549","2.87","19.61","2.99","-----","19.61","19.61","0.29","0.37","0.00"
"13","0.5013","2.44","15.94","3.32","-----","15.94","15.94","0.24","0.26","0.00"
"14","0.8803","4.41","21.82","3.73","-----","21.82","21.82","0.44","0.60","0.00"
"15","0.8495","4.19","19.60","3.32","-----","19.60","19.60","0.42","0.48","0.00"
"16","0.8943","4.25","17.56","4.09","-----","17.56","17.56","0.43","0.46","0.00"
"17","0.8021","3.71","19.41","3.48","-----","19.41","19.41","0.37","0.48","-----"
"18","0.7233","3.34","19.47","3.58","-----","19.47","19.47","0.33","0.44","0.00"
"19","0.7812","3.67","18.40","3.45","-----","18.40","18.40","0.37","0.44","-----"
"20","0.5308","2.57","18.16","3.89","-----","18.16","18.16","0.26","0.36","-----"
"21","0.5192","2.43","16.12","3.64","-----","16.12","16.12","0.24","0.28","-----"
"22","0.9445","4.24","20.19","4.24","-----","20.19","20.19","0.42","0.58","0.00"
"23","0.9599","4.54","20.24","3.70","-----","20.24","20.24","0.45","0.56","0.00"
"24","0.9532","4.52","20.14","4.20","-----","20.14","20.14","0.45","0.60","0.00"
"25","0.9877","4.36","19.39","4.07","-----","19.39","19.39","0.44","0.57","-----"
"26","0.6140","2.83","14.77","3.74","-----","14.77","14.77","0.28","0.28","0.00"
"27","0.6268","3.13","12.11","4.19","-----","12.11","12.11","0.31","0.25","-----"
"28","0.8037","3.67","15.29","3.94","-----","15.29","15.29","0.37","0.36","-----"
"29","0.9934","4.53","21.56","3.93","-----","21.56","21.56","0.45","0.66","-----"
"30","0.4899","2.65","16.37","3.04","-----","16.37","16.37","0.27","0.27","0.00"

Results Table 2


1,Time,Displacement,Force
,(s),(mm),(kgf)
"","0.0000","0.0000","0.0010"
"","0.0400","0.0039","0.0023"
"","0.0800","0.0269","0.0139"
"","0.1200","0.0621","0.0181"
"","0.1600","0.0936","0.0278"
"","0.2000","0.1276","0.0374"
"","0.2400","0.1595","0.0413"
"","0.2800","0.1927","0.0471"
"","0.3200","0.2248","0.0570"
"","0.3600","0.2588","0.0593"
"","0.4000","0.2931","0.0655"
"","0.4400","0.3260","0.0740"
"","0.4800","0.3589","0.0779"
"","0.5200","0.3925","0.0854"
"","0.5600","0.4251","0.0895"
"","0.6000","0.4598","0.0934"
"","0.6400","0.4928","0.1022"
"","0.6800","0.5237","0.1052"
"","0.7200","0.5590","0.1121"
"","0.7600","0.5933","0.1204"
"","0.8000","0.6259","0.1251"
"","0.8400","0.6596","0.1318"
"","0.8800","0.6913","0.1382"
"","0.9200","0.7250","0.1420"
"","0.9600","0.7607","0.1499"
"","1.0000","0.7918","0.1587"
"","1.0400","0.8250","0.1620"
"","1.0800","0.8592","0.1699"
"","1.1200","0.8915","0.1759"
"","1.1600","0.9263","0.1830"
"","1.2000","0.9605","0.1901"
"","1.2400","0.9916","0.1951"
"","1.2800","1.0257","0.2021"
"","1.3200","1.0595","0.2091"
"","1.3600","1.0921","0.2160"
"","1.4000","1.1256","0.2243"
"","1.4400","1.1583","0.2301"
"","1.4800","1.1915","0.2364"
"","1.5200","1.2268","0.2469"
"","1.5600","1.2595","0.2503"
"","1.6000","1.2922","0.2565"
"","1.6400","1.3251","0.2652"
"","1.6800","1.3593","0.2712"
"","1.7200","1.3926","0.2770"
"","1.7600","1.4254","0.2878"
"","1.8000","1.4583","0.2937"
"","1.8400","1.4916","0.2989"
"","1.8800","1.5252","0.3080"
"","1.9200","1.5593","0.3161"
"","1.9600","1.5932","0.3227"
"","2.0000","1.6250","0.3308"
"","2.0400","1.6587","0.3382"
"","2.0800","1.6933","0.3477"
"","2.1200","1.7252","0.3540"
"","2.1600","1.7586","0.3599"
"","2.2000","1.7922","0.3682"
"","2.2400","1.8254","0.3754"
"","2.2800","1.8604","0.3824"
"","2.3200","1.8925","0.3902"
"","2.3600","1.9258","0.3970"
"","2.4000","1.9589","0.4067"
"","2.4400","1.9915","0.4140"
"","2.4800","2.0259","0.4230"
"","2.5200","2.0594","0.4310"
"","2.5600","2.0910","0.4370"
"","2.6000","2.1251","0.4444"
"","2.6400","2.1603","0.4552"
"","2.6800","2.1927","0.4584"
"","2.7200","2.2258","0.4680"
"","2.7600","2.2595","0.4771"
"","2.8000","2.2916","0.4843"
"","2.8400","2.3265","0.4927"
"","2.8800","2.3589","0.5013"
"","2.9200","2.3903","0.5054"
"","2.9600","2.4261","0.5186"
"","3.0000","2.4594","0.5266"
"","3.0400","2.4925","0.5312"
"","3.0800","2.5269","0.5427"
"","3.1200","2.5581","0.5497"
"","3.1600","2.5915","0.5583"
"","3.2000","2.6269","0.5694"
"","3.2400","2.6589","0.5732"
"","3.2800","2.6920","0.5845"
"","3.3200","2.7245","0.5936"
"","3.3600","2.7582","0.6001"
"","3.4000","2.7929","0.6098"
"","3.4400","2.8256","0.6172"
"","3.4800","2.8588","0.6250"
"","3.5200","2.8921","0.6337"
"","3.5600","2.9250","0.6430"
"","3.6000","2.9590","0.6499"
"","3.6400","2.9924","0.6592"
"","3.6800","3.0249","0.6694"
"","3.7200","3.0589","0.6768"
"","3.7600","3.0930","0.6883"
"","3.8000","3.1254","0.6966"
"","3.8400","3.1601","0.7050"
"","3.8800","3.1906","0.7130"
"","3.9200","3.2246","0.7216"
"","3.9600","3.2611","0.7345"
"","4.0000","3.2917","0.7422"
"","4.0400","3.3251","0.7495"
"","4.0800","3.3595","0.7621"
"","4.1200","3.3912","0.7687"
"","4.1600","3.4257","0.7814"
"","4.2000","3.4606","0.7928"
"","4.2400","3.4909","0.7996"
"","4.2800","3.5256","0.8098"
"","4.3200","3.5597","0.8223"
"","4.3600","3.5919","0.8294"
"","4.4000","3.6260","0.8421"
"","4.4400","3.6579","0.8514"
"","4.4800","3.6918","0.8626"
"","4.5200","3.7267","0.8748"
"","4.5600","3.7592","0.8811"
"","4.6000","3.7916","0.8928"
"","4.6400","3.8257","0.9060"
"","4.6800","3.8593","0.9166"
"","4.7200","3.8922","0.9263"
"","4.7600","3.9257","0.9371"
"","4.8000","3.9578","0.9464"
"","4.8400","3.9920","0.9575"
"","4.8800","4.0251","0.9692"
"","4.9200","4.0589","0.9819"
"","4.9600","4.0933","0.9919"
"","5.0000","4.1249","1.0019"
"","5.0400","4.1587","1.0127"
"","5.0800","4.1928","1.0255"
"","5.1200","4.2250","1.0350"
"","5.1600","4.2589","1.0465"
"","5.2000","4.2916","1.0582"
"","5.2400","4.3252","1.0683"
"","5.2800","4.3598","1.0811"
"","5.3200","4.3921","1.0922"
"","5.3600","4.4250","1.1034"
"","5.4000","4.4596","1.1140"
"","5.4400","4.4919","1.1253"
"","5.4800","4.5256","1.1363"
"","5.5200","4.5594","1.1511"
"","5.5600","4.5910","1.1590"
"","5.6000","4.6254","1.1718"
"","5.6400","4.6600","1.1858"
"","5.6800","4.6927","1.1960"
"","5.7200","4.7255","1.2070"
"","5.7600","4.7594","1.2184"
"","5.8000","4.7922","1.2299"
"","5.8400","4.8264","1.2409"
"","5.8800","4.8578","1.2494"
"","5.9200","4.8908","1.2629"
"","5.9600","4.9260","1.2770"
"","6.0000","4.9592","1.2868"
"","6.0400","4.9922","1.2988"
"","6.0800","5.0267","1.3129"
"","6.1200","5.0583","1.3213"
"","6.1600","5.0916","1.3336"
"","6.2000","5.1265","1.3487"
"","6.2400","5.1590","1.3598"
"","6.2800","5.1918","1.3679"
"","6.3200","5.2246","1.3779"
"","6.3600","5.2587","1.3924"
"","6.4000","5.2926","1.4033"
"","6.4400","5.3256","1.4153"
"","6.4800","5.3591","1.4299"
"","6.5200","5.3925","1.4386"
"","6.5600","5.4248","1.4510"
"","6.6000","5.4598","1.4655"
"","6.6400","5.4925","1.4749"
"","6.6800","5.5243","1.4863"
"","6.7200","5.5591","1.5003"
"","6.7600","5.5927","1.5128"
"","6.8000","5.6257","1.5272"
"","6.8400","5.6595","1.5390"
"","6.8800","5.6915","1.5504"
"","6.9200","5.7246","1.5624"
"","6.9600","5.7605","1.5774"
"","7.0000","5.7916","1.5878"
"","7.0400","5.8250","1.5986"
"","7.0800","5.8595","1.6147"
"","7.1200","5.8913","1.6236"
"","7.1600","5.9264","1.6401"
"","7.2000","5.9602","1.6559"
"","7.2400","5.9916","1.6630"
"","7.2800","6.0260","1.6773"
"","7.3200","6.0595","1.6899"
"","7.3600","6.0921","1.7012"
"","7.4000","6.1255","1.7134"
"","7.4400","6.1582","1.7260"
"","7.4800","6.1920","1.7415"
"","7.5200","6.2265","1.7567"
"","7.5600","6.2596","1.7707"
"","7.6000","6.2915","1.7763"
"","7.6400","6.3256","1.7922"
"","7.6800","6.3589","1.8052"
"","7.7200","6.3927","1.8189"
"","7.7600","6.4260","1.8290"
"","7.8000","6.4581","1.8454"
"","7.8400","6.4924","1.8576"
"","7.8800","6.5249","1.8660"
"","7.9200","6.5593","1.8817"
"","7.9600","6.5930","1.8975"
"","8.0000","6.6248","1.9051"
"","8.0400","6.6585","1.9173"
"","8.0800","6.6935","1.9307"
"","8.1200","6.7247","1.9389"
"","8.1600","6.7589","1.9529"
"","8.2000","6.7922","1.9647"
"","8.2400","6.8246","1.9769"
"","8.2800","6.8605","1.9944"
"","8.3200","6.8925","2.0032"
"","8.3600","6.9251","2.0119"
"","8.4000","6.9599","2.0293"
"","8.4400","6.9915","2.0370"
"","8.4800","7.0252","2.0496"
"","8.5200","7.0598","2.0627"
"","8.5600","7.0904","2.0708"
"","8.6000","7.1251","2.0865"
"","8.6400","7.1602","2.1031"
"","8.6800","7.1920","2.1105"
"","8.7200","7.2258","2.1255"
"","8.7600","7.2589","2.1372"
"","8.8000","7.2914","2.1498"
"","8.8400","7.3268","2.1640"
"","8.8800","7.3582","2.1729"
"","8.9200","7.3908","2.1846"
"","8.9600","7.4263","2.2009"
"","9.0000","7.4593","2.2137"
"","9.0400","7.4921","2.2232"
"","9.0800","7.5273","2.2363"
"","9.1200","7.5581","2.2442"
"","9.1600","7.5916","2.2578"
"","9.2000","7.6271","2.2728"
"","9.2400","7.6590","2.2840"
"","9.2800","7.6924","2.2927"
"","9.3200","7.7244","2.3013"
"","9.3600","7.7582","2.3186"
"","9.4000","7.7933","2.3323"
"","9.4400","7.8255","2.3354"
"","9.4800","7.8588","2.3474"
"","9.5200","7.8928","2.3585"
"","9.5600","7.9247","2.3672"
"","9.6000","7.9593","2.3851"
"","9.6400","7.9922","2.3949"
"","9.6800","8.0244","2.4037"
"","9.7200","8.0589","2.4193"
"","9.7600","8.0926","2.4311"
"","9.8000","8.1256","2.4415"
"","9.8400","8.1601","2.4527"
"","9.8800","8.1915","2.4608"
"","9.9200","8.2245","2.4717"
"","9.9600","8.2608","2.4870"
"","10.0000","8.2916","2.4937"
"","10.0400","8.3248","2.5028"
"","10.0800","8.3596","2.5164"
"","10.1200","8.3912","2.5236"
"","10.1600","8.4254","2.5365"
"","10.2000","8.4608","2.5479"
"","10.2400","8.4907","2.5510"
"","10.2800","8.5257","2.5620"
"","10.3200","8.5600","2.5743"
"","10.3600","8.5916","2.5819"
"","10.4000","8.6259","2.5915"
"","10.4400","8.6581","2.5974"
"","10.4800","8.6915","2.6086"
"","10.5200","8.7269","2.6219"
"","10.5600","8.7594","2.6308"
"","10.6000","8.7920","2.6371"
"","10.6400","8.8261","2.6444"
"","10.6800","8.8585","2.6539"
"","10.7200","8.8927","2.6617"
"","10.7600","8.9262","2.6707"
"","10.8000","8.9575","2.6777"
"","10.8400","8.9921","2.6872"
"","10.8800","9.0254","2.6947"
"","10.9200","9.0584","2.7046"
"","10.9600","9.0933","2.7140"
"","11.0000","9.1255","2.7205"
"","11.0400","9.1584","2.7258"
"","11.0800","9.1923","2.7324"
"","11.1200","9.2250","2.7428"
"","11.1600","9.2584","2.7509"
"","11.2000","9.2919","2.7565"
"","11.2400","9.3251","2.7642"
"","11.2800","9.3600","2.7737"
"","11.3200","9.3927","2.7784"
"","11.3600","9.4246","2.7835"
"","11.4000","9.4600","2.7923"
"","11.4400","9.4916","2.7957"
"","11.4800","9.5254","2.8066"
"","11.5200","9.5597","2.8125"
"","11.5600","9.5908","2.8132"
"","11.6000","9.6253","2.8239"
"","11.6400","9.6601","2.8329"
"","11.6800","9.6921","2.8346"
"","11.7200","9.7259","2.8406"
"","11.7600","9.7595","2.8475"
"","11.8000","9.7916","2.8537"
"","11.8400","9.8268","2.8609"
"","11.8800","9.8590","2.8631"
"","11.9200","9.8899","2.8675"
"","11.9600","9.9260","2.8764"
"","12.0000","9.9592","2.8822"
"","12.0400","9.9923","2.8871"
"","12.0800","10.0268","2.8957"
"","12.1200","10.0585","2.8972"
"","12.1600","10.0917","2.9032"
"","12.2000","10.1261","2.9082"
"","12.2400","10.1593","2.9167"
"","12.2800","10.1920","2.9202"
"","12.3200","10.2248","2.9229"
"","12.3600","10.2589","2.9324"
"","12.4000","10.2930","2.9397"
"","12.4400","10.3259","2.9419"
"","12.4800","10.3589","2.9477"
"","12.5200","10.3928","2.9503"
"","12.5600","10.4247","2.9522"
"","12.6000","10.4597","2.9629"
"","12.6400","10.4924","2.9614"
"","12.6800","10.5243","2.9635"
"","12.7200","10.5595","2.9755"
"","12.7600","10.5925","2.9762"
"","12.8000","10.6254","2.9803"
"","12.8400","10.6599","2.9875"
"","12.8800","10.6923","2.9859"
"","12.9200","10.7244","2.9900"
"","12.9600","10.7604","3.0024"
"","13.0000","10.7921","3.0046"
"","13.0400","10.8246","3.0062"
"","13.0800","10.8594","3.0133"
"","13.1200","10.8911","3.0137"
"","13.1600","10.9257","3.0220"
"","13.2000","10.9604","3.0305"
"","13.2400","10.9913","3.0275"
"","13.2800","11.0256","3.0335"
"","13.3200","11.0595","3.0400"
"","13.3600","11.0918","3.0453"
"","13.4000","11.1258","3.0484"
"","13.4400","11.1584","3.0504"
"","13.4800","11.1914","3.0570"
"","13.5200","11.2271","3.0632"
"","13.5600","11.2594","3.0665"
"","13.6000","11.2920","3.0712"
"","13.6400","11.3258","3.0753"
"","13.6800","11.3588","3.0814"
"","13.7200","11.3930","3.0890"
"","13.7600","11.4252","3.0868"
"","13.8000","11.4583","3.0917"
"","13.8400","11.4924","3.0987"
"","13.8800","11.5260","3.1014"
"","13.9200","11.5585","3.1049"
"","13.9600","11.5930","3.1114"
"","14.0000","11.6258","3.1140"
"","14.0400","11.6584","3.1169"
"","14.0800","11.6933","3.1233"
"","14.1200","11.7250","3.1236"
"","14.1600","11.7583","3.1266"
"","14.2000","11.7920","3.1306"
"","14.2400","11.8251","3.1368"
"","14.2800","11.8598","3.1411"
"","14.3200","11.8928","3.1406"
"","14.3600","11.9251","3.1461"
"","14.4000","11.9598","3.1527"
"","14.4400","11.9920","3.1532"
"","14.4800","12.0258","3.1590"
"","14.5200","12.0595","3.1601"
"","14.5600","12.0907","3.1565"
"","14.6000","12.1251","3.1662"
"","14.6400","12.1600","3.1729"
"","14.6800","12.1922","3.1726"
"","14.7200","12.2260","3.1759"
"","14.7600","12.2584","3.1725"
"","14.8000","12.2919","3.1775"
"","14.8400","12.3262","3.1821"
"","14.8800","12.3594","3.1844"
"","14.9200","12.3901","3.1809"
"","14.9600","12.4258","3.1876"
"","15.0000","12.4597","3.1927"
"","15.0400","12.4920","3.1924"
"","15.0800","12.5273","3.1961"
"","15.1200","12.5583","3.1955"
"","15.1600","12.5917","3.1982"
"","15.2000","12.6263","3.2047"
"","15.2400","12.6589","3.2081"
"","15.2800","12.6917","3.2047"
"","15.3200","12.7252","3.2075"
"","15.3600","12.7586","3.2149"
"","15.4000","12.7929","3.2172"
"","15.4400","12.8258","3.2180"
"","15.4800","12.8585","3.2204"
"","15.5200","12.8927","3.2233"
"","15.5600","12.9254","3.2238"
"","15.6000","12.9591","3.2312"
"","15.6400","12.9928","3.2308"
"","15.6800","13.0242","3.2279"
"","15.7200","13.0595","3.2366"
"","15.7600","13.0921","3.2381"
"","15.8000","13.1259","3.2408"
"","15.8400","13.1602","3.2443"
"","15.8800","13.1915","3.2356"
"","15.9200","13.2244","3.2419"
"","15.9600","13.2601","3.2503"
"","16.0000","13.2920","3.2485"
"","16.0400","13.3244","3.2498"
"","16.0800","13.3601","3.2555"
"","16.1200","13.3909","3.2517"
"","16.1600","13.4264","3.2599"
"","16.2000","13.4608","3.2635"
"","16.2400","13.4907","3.2550"
"","16.2800","13.5254","3.2568"
"","16.3200","13.5597","3.2638"
"","16.3600","13.5914","3.2658"
"","16.4000","13.6261","3.2664"
"","16.4400","13.6582","3.2654"
"","16.4800","13.6910","3.2648"
"","16.5200","13.7270","3.2734"
"","16.5600","13.7594","3.2746"
"","16.6000","13.7916","3.2716"
"","16.6400","13.8261","3.2754"
"","16.6800","13.8583","3.2768"
"","16.7200","13.8927","3.2807"
"","16.7600","13.9254","3.2792"
"","16.8000","13.9585","3.2804"
"","16.8400","13.9918","3.2809"
"","16.8800","14.0257","3.2818"
"","16.9200","14.0587","3.2858"
"","16.9600","14.0927","3.2852"
"","17.0000","14.1255","3.2861"
"","17.0400","14.1584","3.2895"
"","17.0800","14.1935","3.2900"
"","17.1200","14.2246","3.2887"
"","17.1600","14.2585","3.2924"
"","17.2000","14.2920","3.2936"
"","17.2400","14.3244","3.2936"
"","17.2800","14.3603","3.3036"
"","17.3200","14.3931","3.3013"
"","17.3600","14.4247","3.3009"
"","17.4000","14.4596","3.3052"
"","17.4400","14.4917","3.3041"
"","17.4800","14.5253","3.3097"
"","17.5200","14.5600","3.3117"
"","17.5600","14.5912","3.3093"
"","17.6000","14.6246","3.3086"
"","17.6400","14.6604","3.3165"
"","17.6800","14.6923","3.3165"
"","17.7200","14.7259","3.3165"
"","17.7600","14.7594","3.3163"
"","17.8000","14.7914","3.3155"
"","17.8400","14.8265","3.3205"
"","17.8800","14.8597","3.3221"
"","17.9200","14.8904","3.3186"
"","17.9600","14.9254","3.3240"
"","18.0000","14.9589","3.3278"
"","18.0400","14.9920","3.3287"
"","18.0800","15.0269","3.3311"
"","18.1200","15.0583","3.3288"
"","18.1600","15.0914","3.3286"
"","18.2000","15.1265","3.3310"
"","18.2400","15.1591","3.3329"
"","18.2800","15.1916","3.3290"
"","18.3200","15.2254","3.3305"
"","18.3600","15.2582","3.3410"
"","18.4000","15.2934","3.3396"
"","18.4400","15.3261","3.3364"
"","18.4800","15.3581","3.3368"
"","18.5200","15.3926","3.3387"
"","18.5600","15.4255","3.3391"
"","18.6000","15.4592","3.3400"
"","18.6400","15.4924","3.3369"
"","18.6800","15.5244","3.3359"
"","18.7200","15.5590","3.3399"
"","18.7600","15.5924","3.3404"
"","18.8000","15.6261","3.3436"
"","18.8400","15.6599","3.3447"
"","18.8800","15.6918","3.3357"
"","18.9200","15.7241","3.3387"
"","18.9600","15.7599","3.3464"
"","19.0000","15.7924","3.3431"
"","19.0400","15.8247","3.3409"
"","19.0800","15.8592","3.3432"
"","19.1200","15.8916","3.3460"
"","19.1600","15.9259","3.3455"
"","19.2000","15.9607","3.3498"
"","19.2400","15.9914","3.3426"
"","19.2800","16.0253","3.3418"
"","19.3200","16.0600","3.3471"
"","19.3600","16.0917","3.3435"
"","19.4000","16.1259","3.3436"
"","19.4400","16.1583","3.3416"
"","19.4800","16.1912","3.3429"
"","19.5200","16.2269","3.3474"
"","19.5600","16.2597","3.3470"
"","19.6000","16.2918","3.3422"
"","19.6400","16.3260","3.3409"
"","19.6800","16.3586","3.3423"
"","19.7200","16.3922","3.3450"
"","19.7600","16.4252","3.3441"
"","19.8000","16.4583","3.3450"
"","19.8400","16.4921","3.3471"
"","19.8800","16.5258","3.3464"
"","19.9200","16.5591","3.3517"
"","19.9600","16.5924","3.3476"
"","20.0000","16.6254","3.3491"
"","20.0400","16.6585","3.3517"
"","20.0800","16.6936","3.3538"
"","20.1200","16.7252","3.3524"
"","20.1600","16.7586","3.3564"
"","20.2000","16.7915","3.3570"
"","20.2400","16.8254","3.3612"
"","20.2800","16.8597","3.3632"
"","20.3200","16.8933","3.3624"
"","20.3600","16.9246","3.3590"
"","20.4000","16.9598","3.3637"
"","20.4400","16.9917","3.3613"
"","20.4800","17.0255","3.3648"
"","20.5200","17.0602","3.3687"
"","20.5600","17.0908","3.3602"
"","20.6000","17.1250","3.3640"
"","20.6400","17.1603","3.3707"
"","20.6800","17.1923","3.3672"
"","20.7200","17.2259","3.3672"
"","20.7600","17.2591","3.3641"
"","20.8000","17.2915","3.3667"
"","20.8400","17.3261","3.3669"
"","20.8800","17.3590","3.3691"
"","20.9200","17.3905","3.3632"
"","20.9600","17.4251","3.3655"
"","21.0000","17.4593","3.3699"
"","21.0400","17.4924","3.3685"
"","21.0800","17.5267","3.3677"
"","21.1200","17.5586","3.3641"
"","21.1600","17.5915","3.3655"
"","21.2000","17.6259","3.3664"
"","21.2400","17.6594","3.3709"
"","21.2800","17.6915","3.3670"
"","21.3200","17.7255","3.3644"
"","21.3600","17.7584","3.3683"
"","21.4000","17.7934","3.3717"
"","21.4400","17.8258","3.3659"
"","21.4800","17.8582","3.3633"
"","21.5200","17.8923","3.3644"
"","21.5600","17.9254","3.3681"
"","21.6000","17.9593","3.3707"
"","21.6400","17.9927","3.3658"
"","21.6800","18.0242","3.3615"
"","21.7200","18.0587","3.3674"
"","21.7600","18.0925","3.3641"
"","21.8000","18.1263","3.3673"
"","21.8400","18.1602","3.3665"
"","21.8800","18.1917","3.3594"
"","21.9200","18.2248","3.3618"
"","21.9600","18.2596","3.3656"
"","22.0000","18.2924","3.3664"
"","22.0400","18.3247","3.3644"
"","22.0800","18.3595","3.3657"
"","22.1200","18.3915","3.3630"
"","22.1600","18.4260","3.3681"
"","22.2000","18.4601","3.3728"
"","22.2400","18.4916","3.3690"
"","22.2800","18.5258","3.3694"
"","22.3200","18.5596","3.3699"
"","22.3600","18.5912","3.3668"
"","22.4000","18.6261","3.3686"
"","22.4400","18.6584","3.3677"
"","22.4800","18.6911","3.3663"
"","22.5200","18.7269","3.3695"
"","22.5600","18.7600","3.3694"
"","22.6000","18.7918","3.3647"
"","22.6400","18.8261","3.3641"
"","22.6800","18.8582","3.3625"
"","22.7200","18.8927","3.3692"
"","22.7600","18.9253","3.3684"
"","22.8000","18.9578","3.3682"
"","22.8400","18.9919","3.3691"
"","22.8800","19.0251","3.3670"
"","22.9200","19.0590","3.3749"
"","22.9600","19.0925","3.3702"
"","23.0000","19.1252","3.3636"
"","23.0400","19.1585","3.3658"
"","23.0800","19.1934","3.3667"
"","23.1200","19.2254","3.3633"
"","23.1600","19.2582","3.3629"
"","23.2000","19.2908","3.3577"
"","23.2400","19.3250","3.3632"
"","23.2800","19.3604","3.3686"
"","23.3200","19.3928","3.3627"
"","23.3600","19.4247","3.3603"
"","23.4000","19.4600","3.3655"
"","23.4400","19.4918","3.3604"
"","23.4800","19.5253","3.3672"
"","23.5200","19.5600","3.3686"
"","23.5600","19.5912","3.3627"
"","23.6000","19.6251","3.3658"
"","23.6400","19.6601","3.3693"
"","23.6800","19.6919","3.3689"
"","23.7200","19.7262","3.3689"
"","23.7600","19.7590","3.3671"
"","23.8000","19.7915","3.3642"
"","23.8400","19.8265","3.3665"
"","23.8800","19.8594","3.3644"
"","23.9200","19.8905","3.3580"
"","23.9600","19.9250","3.3591"
"","24.0000","19.9591","3.3617"
"","24.0400","19.9923","3.3624"
"","24.0800","20.0270","3.3595"
"","24.1200","20.0585","3.3580"
"","24.1600","20.0910","3.3560"
"","24.2000","20.1267","3.3618"
"","24.2400","20.1587","3.3630"
"","24.2800","20.1925","3.3626"
"","24.3200","20.2246","3.3578"
"","24.3600","20.2585","3.3644"
"","24.4000","20.2932","3.3652"
"","24.4400","20.3260","3.3657"
"","24.4800","20.3583","3.3652"
"","24.5200","20.3923","3.3661"
"","24.5600","20.4252","3.3667"
"","24.6000","20.4597","3.3740"
"","24.6400","20.4918","3.3673"
"","24.6800","20.5243","3.3647"
"","24.7200","20.5593","3.3695"
"","24.7600","20.5928","3.3713"
"","24.8000","20.6257","3.3714"
"","24.8400","20.6608","3.3765"
"","24.8800","20.6914","3.3669"
"","24.9200","20.7244","3.3684"
"","24.9600","20.7597","3.3726"
"","25.0000","20.7917","3.3667"
"","25.0400","20.8248","3.3675"
"","25.0800","20.8596","3.3691"
"","25.1200","20.8922","3.3654"
"","25.1600","20.9259","3.3655"
"","25.2000","20.9607","3.3666"
"","25.2400","20.9910","3.3570"
"","25.2800","21.0262","3.3575"
"","25.3200","21.0598","3.3514"
"","25.3600","21.0917","3.3323"
"","25.4000","21.1258","3.3269"
"","25.4400","21.1587","3.3241"
"","25.4800","21.1915","3.3195"
"","25.5200","21.2268","3.3187"
"","25.5600","21.2597","3.3171"
"","25.6000","21.2918","3.3160"
"","25.6400","21.3253","3.3118"
"","25.6800","21.3587","3.3162"
"","25.7200","21.3927","3.3161"
"","25.7600","21.4260","3.3126"
"","25.8000","21.4573","3.3072"
"","25.8400","21.4928","3.3087"
"","25.8800","21.5255","3.3045"
"","25.9200","21.5594","3.3063"
"","25.9600","21.5929","3.2976"
"","26.0000","21.6246","3.2893"
"","26.0400","21.6590","3.2944"
"","26.0800","21.6931","3.2953"
"","26.1200","21.7258","3.2923"
"","26.1600","21.7582","3.2867"
"","26.2000","21.7916","3.2837"
"","26.2400","21.8253","3.2878"
"","26.2800","21.8598","3.2886"
"","26.3200","21.8930","3.2827"
"","26.3600","21.9249","3.2757"
"","26.4000","21.9593","3.2726"
"","26.4400","21.9918","3.2643"
"","26.4800","22.0257","3.2664"
"","26.5200","22.0596","3.2644"
"","26.5600","22.0913","3.2598"
"","26.6000","22.1252","3.2619"
"","26.6400","22.1597","3.2605"
"","26.6800","22.1920","3.2596"
"","26.7200","22.2258","3.2571"
"","26.7600","22.2597","3.2562"
"","26.8000","22.2908","3.2481"
"","26.8400","22.3269","3.2552"
"","26.8800","22.3589","3.2508"
"","26.9200","22.3907","3.2469"
"","26.9600","22.4259","3.2488"
"","27.0000","22.4587","3.2493"
"","27.0400","22.4928","3.2533"
"","27.0800","22.5264","3.2505"
"","27.1200","22.5589","3.2475"
"","27.1600","22.5909","3.2410"
"","27.2000","22.6258","3.2454"
"","27.2400","22.6595","3.2498"
"","27.2800","22.6916","3.2414"
"","27.3200","22.7250","3.2377"
"","27.3600","22.7587","3.2439"
"","27.4000","22.7930","3.2421"
"","27.4400","22.8265","3.2373"
"","27.4800","22.8586","3.2339"
"","27.5200","22.8920","3.2314"
"","27.5600","22.9256","3.2333"
"","27.6000","22.9597","3.2353"
"","27.6400","22.9924","3.2283"
"","27.6800","23.0246","3.2268"
"","27.7200","23.0587","3.2298"
"","27.7600","23.0929","3.2324"
"","27.8000","23.1256","3.2292"
"","27.8400","23.1598","3.2289"
"","27.8800","23.1913","3.2237"
"","27.9200","23.2244","3.2266"
"","27.9600","23.2605","3.2305"
"","28.0000","23.2913","3.2258"
"","28.0400","23.3253","3.2276"
"","28.0800","23.3593","3.2286"
"","28.1200","23.3920","3.2270"
"","28.1600","23.4258","3.2294"
"","28.2000","23.4599","3.2303"
"","28.2400","23.4919","3.2242"
"","28.2800","23.5256","3.2286"
"","28.3200","23.5594","3.2263"
"","28.3600","23.5917","3.2275"
"","28.4000","23.6256","3.2233"
"","28.4400","23.6588","3.2241"
"","28.4800","23.6909","3.2204"
"","28.5200","23.7263","3.2217"
"","28.5600","23.7601","3.2285"
"","28.6000","23.7920","3.2240"
"","28.6400","23.8251","3.2204"
"","28.6800","23.8587","3.2213"
"","28.7200","23.8925","3.2245"
"","28.7600","23.9259","3.2219"
"","28.8000","23.9579","3.2187"
"","28.8400","23.9921","3.2197"
"","28.8800","24.0254","3.2182"
"","28.9200","24.0594","3.2216"
"","28.9600","24.0932","3.2178"
"","29.0000","24.1240","3.2087"
"","29.0400","24.1586","3.2152"
"","29.0800","24.1934","3.2179"
"","29.1200","24.2249","3.2107"
"","29.1600","24.2583","3.2127"
"","29.2000","24.2913","3.2098"
"","29.2400","24.3251","3.2116"
"","29.2800","24.3601","3.2135"
"","29.3200","24.3925","3.2056"
"","29.3600","24.4250","3.2046"
"","29.4000","24.4592","3.2061"
"","29.4400","24.4926","3.2059"
"","29.4800","24.5253","3.2051"
"","29.5200","24.5592","3.2039"
"","29.5600","24.5912","3.2000"
"","29.6000","24.6254","3.2053"
"","29.6400","24.6601","3.2069"
"","29.6800","24.6920","3.2041"
"","29.7200","24.7261","3.2037"
"","29.7600","24.7592","3.1984"
"","29.8000","24.7913","3.1949"
"","29.8400","24.8266","3.1993"
"","29.8800","24.8588","3.1956"
"","29.9200","24.8905","3.1909"
"","29.9600","24.9263","3.1960"
"","30.0000","24.9582","3.1929"
"","30.0400","24.9931","3.1985"
"","30.0800","25.0270","3.1967"
"","30.1200","25.0578","3.1864"
"","30.1600","25.0916","3.1884"
"","30.2000","25.1262","3.1888"
"","30.2400","25.1591","3.1906"
"","30.2800","25.1923","3.1870"
"","30.3200","25.2246","3.1788"
"","30.3600","25.2586","3.1798"
"","30.4000","25.2930","3.1780"
"","30.4400","25.3264","3.1750"
"","30.4800","25.3582","3.1740"
"","30.5200","25.3919","3.1703"
"","30.5600","25.4252","3.1685"
"","30.6000","25.4594","3.1693"
"","30.6400","25.4920","3.1618"
"","30.6800","25.5244","3.1565"
"","30.7200","25.5592","3.1638"
"","30.7600","25.5926","3.1577"
"","30.8000","25.6255","3.1568"
"","30.8400","25.6602","3.1564"
"","30.8800","25.6909","3.1476"
"","30.9200","25.7248","3.1455"
"","30.9600","25.7606","3.1478"
"","31.0000","25.7911","3.1370"
"","31.0400","25.8247","3.1359"
"","31.0800","25.8595","3.1357"
"","31.1200","25.8918","3.1303"
"","31.1600","25.9260","3.1270"
"","31.2000","25.9603","3.1251"
"","31.2400","25.9912","3.1148"
"","31.2800","26.0257","3.1132"
"","31.3200","26.0599","3.1100"
"","31.3600","26.0918","3.1042"
"","31.4000","26.1255","3.1026"
"","31.4400","26.1590","3.1002"
"","31.4800","26.1913","3.0978"
"","31.5200","26.2269","3.1006"
"","31.5600","26.2598","3.0965"
"","31.6000","26.2919","3.0900"
"","31.6400","26.3253","3.0862"
"","31.6800","26.3595","3.0850"
"","31.7200","26.3923","3.0815"
"","31.7600","26.4265","3.0774"
"","31.8000","26.4578","3.0706"
"","31.8400","26.4919","3.0673"
"","31.8800","26.5257","3.0628"
"","31.9200","26.5595","3.0629"
"","31.9600","26.5931","3.0600"
"","32.0000","26.6237","3.0459"
"","32.0400","26.6596","3.0478"
"","32.0800","26.6934","3.0369"
"","32.1200","26.7249","3.0259"
"","32.1600","26.7587","3.0241"
"","32.2000","26.7918","3.0152"
"","32.2400","26.8253","3.0137"
"","32.2800","26.8604","3.0160"
"","32.3200","26.8930","3.0049"
"","32.3600","26.9250","2.9976"
"","32.4000","26.9589","2.9925"
"","32.4400","26.9926","2.9915"
"","32.4800","27.0255","2.9851"
"","32.5200","27.0591","2.9743"
"","32.5600","27.0907","2.9617"
"","32.6000","27.1251","2.9614"
"","32.6400","27.1600","2.9572"
"","32.6800","27.1921","2.9466"
"","32.7200","27.2256","2.9375"
"","32.7600","27.2593","2.9296"
"","32.8000","27.2907","2.9182"
"","32.8400","27.3265","2.9152"
"","32.8800","27.3593","2.8716"
"","32.9200","27.3906","2.8431"
"","32.9600","27.4261","2.8410"
"","33.0000","27.4582","2.8316"
"","33.0400","27.4930","2.8341"
"","33.0800","27.5272","2.8297"
"","33.1200","27.5581","2.8133"
"","33.1600","27.5917","2.8051"
"","33.2000","27.6263","2.8024"
"","33.2400","27.6591","2.7966"
"","33.2800","27.6922","2.7882"
"","33.3200","27.7248","2.7809"
"","33.3600","27.7586","2.7804"
"","33.4000","27.7930","2.7769"
"","33.4400","27.8267","2.7696"
"","33.4800","27.8586","2.7616"
"","33.5200","27.8920","2.7548"
"","33.5600","27.9252","2.7502"
"","33.6000","27.9592","2.7474"
"","33.6400","27.9924","2.7410"
"","33.6800","28.0240","2.7327"
"","33.7200","28.0592","2.7319"
"","33.7600","28.0929","2.7236"
"","33.8000","28.1253","2.7142"
"","33.8400","28.1601","2.7129"
"","33.8800","28.1912","2.7032"
"","33.9200","28.2247","2.7021"
"","33.9600","28.2606","2.7043"
"","34.0000","28.2911","2.6915"
"","34.0400","28.3247","2.6874"
"","34.0800","28.3596","2.6855"
"","34.1200","28.3918","2.6787"
"","34.1600","28.4258","2.6714"
"","34.2000","28.4599","2.6653"
"","34.2400","28.4913","2.6547"
"","34.2800","28.5254","2.6504"
"","34.3200","28.5591","2.6477"
"","34.3600","28.5918","2.6449"
"","34.4000","28.6255","2.6432"
"","34.4400","28.6588","2.6402"
"","34.4800","28.6911","2.6390"
"","34.5200","28.7263","2.6363"
"","34.5600","28.7597","2.6321"
"","34.6000","28.7918","2.6268"
"","34.6400","28.8258","2.6230"
"","34.6800","28.8585","2.6234"
"","34.7200","28.8924","2.6237"
"","34.7600","28.9262","2.6192"
"","34.8000","28.9572","2.6142"
"","34.8400","28.9923","2.6127"
"","34.8800","29.0261","2.6093"
"","34.9200","29.0591","2.6031"
"","34.9600","29.0933","2.5984"
"","35.0000","29.1246","2.5862"
"","35.0400","29.1586","2.5784"
"","35.0800","29.1934","2.5702"
"","35.1200","29.2252","2.5554"
"","35.1600","29.2582","2.5497"
"","35.2000","29.2917","2.5419"
"","35.2400","29.3259","2.5385"
"","35.2800","29.3597","2.5267"
"","35.3200","29.3924","2.5123"
"","35.3600","29.4249","2.4934"
"","35.4000","29.4593","2.4720"
"","35.4400","29.4922","2.4536"
"","35.4800","29.5255","2.4422"
"","35.5200","29.5595","2.4334"
"","35.5600","29.5910","2.4056"
"","35.6000","29.6255","2.3690"
"","35.6400","29.6602","2.3534"
"","35.6800","29.6920","2.3395"
"","35.7200","29.7258","2.3300"
"","35.7600","29.7596","2.3246"
"","35.8000","29.7905","2.3124"
"","35.8400","29.8263","2.3099"
"","35.8800","29.8598","2.3032"
"","35.9200","29.8902","2.2760"
"","35.9600","29.9260","2.2650"
"","36.0000","29.9592","2.2537"
"","36.0400","29.9919","2.2363"
"","36.0500","30.0001","2.2222"
2,Time,Displacement,Force
,(s),(mm),(kgf)
"","0.0000","0.0000","-0.0042"
"","0.0400","0.0094","0.0031"
"","0.0800","0.0486","0.0288"
"","0.1200","0.0807","0.0468"
"","0.1600","0.1123","0.0578"
"","0.2000","0.1446","0.0655"
"","0.2400","0.1787","0.0765"
"","0.2800","0.2097","0.0849"
"","0.3200","0.2437","0.0889"
"","0.3600","0.2768","0.0996"
"","0.4000","0.3092","0.1074"
"","0.4400","0.3444","0.1126"
"","0.4800","0.3766","0.1237"
"","0.5200","0.4091","0.1325"
"","0.5600","0.4432","0.1384"
"","0.6000","0.4760","0.1484"
"","0.6400","0.5097","0.1570"
"","0.6800","0.5432","0.1655"
"","0.7200","0.5748","0.1738"
"","0.7600","0.6087","0.1817"
"","0.8000","0.6443","0.1923"
"","0.8400","0.6758","0.2007"
"","0.8800","0.7095","0.2094"
"","0.9200","0.7434","0.2181"
"","0.9600","0.7748","0.2256"
"","1.0000","0.8100","0.2371"
"","1.0400","0.8423","0.2429"
"","1.0800","0.8743","0.2503"
"","1.1200","0.9096","0.2629"
"","1.1600","0.9433","0.2725"
"","1.2000","0.9760","0.2803"
"","1.2400","1.0106","0.2906"
"","1.2800","1.0413","0.2990"
"","1.3200","1.0757","0.3096"
"","1.3600","1.1106","0.3200"
"","1.4000","1.1423","0.3265"
"","1.4400","1.1764","0.3377"
"","1.4800","1.2083","0.3476"
"","1.5200","1.2426","0.3580"
"","1.5600","1.2766","0.3661"
"","1.6000","1.3095","0.3774"
"","1.6400","1.3425","0.3864"
"","1.6800","1.3761","0.3979"
"","1.7200","1.4090","0.4072"
"","1.7600","1.4435","0.4180"
"","1.8000","1.4761","0.4295"
"","1.8400","1.5079","0.4365"
"","1.8800","1.5424","0.4495"
"","1.9200","1.5770","0.4625"
"","1.9600","1.6093","0.4731"
"","2.0000","1.6431","0.4857"
"","2.0400","1.6754","0.4974"
"","2.0800","1.7089","0.5059"
"","2.1200","1.7445","0.5208"
"","2.1600","1.7758","0.5342"
"","2.2000","1.8090","0.5459"
"","2.2400","1.8432","0.5596"
"","2.2800","1.8752","0.5708"
"","2.3200","1.9101","0.5830"
"","2.3600","1.9441","0.5983"
"","2.4000","1.9749","0.6081"
"","2.4400","2.0094","0.6222"
"","2.4800","2.0432","0.6361"
"","2.5200","2.0759","0.6461"
"","2.5600","2.1093","0.6598"
"","2.6000","2.1421","0.6719"
"","2.6400","2.1753","0.6858"
"","2.6800","2.2107","0.6994"
"","2.7200","2.2433","0.7122"
"","2.7600","2.2756","0.7242"
"","2.8000","2.3091","0.7357"
"","2.8400","2.3431","0.7493"
"","2.8800","2.3763","0.7621"
"","2.9200","2.4094","0.7761"
"","2.9600","2.4422","0.7887"
"","3.0000","2.4754","0.7995"
"","3.0400","2.5093","0.8142"
"","3.0800","2.5432","0.8292"
"","3.1200","2.5768","0.8409"
"","3.1600","2.6091","0.8536"
"","3.2000","2.6423","0.8653"
"","3.2400","2.6772","0.8788"
"","3.2800","2.7087","0.8902"
"","3.3200","2.7421","0.9040"
"","3.3600","2.7760","0.9165"
"","3.4000","2.8093","0.9298"
"","3.4400","2.8441","0.9424"
"","3.4800","2.8760","0.9551"
"","3.5200","2.9095","0.9665"
"","3.5600","2.9430","0.9794"
"","3.6000","2.9754","0.9922"
"","3.6400","3.0095","1.0070"
"","3.6800","3.0433","1.0201"
"","3.7200","3.0748","1.0276"
"","3.7600","3.1091","1.0423"
"","3.8000","3.1441","1.0586"
"","3.8400","3.1762","1.0688"
"","3.8800","3.2094","1.0817"
"","3.9200","3.2433","1.0949"
"","3.9600","3.2753","1.1073"
"","4.0000","3.3101","1.1193"
"","4.0400","3.3425","1.1326"
"","4.0800","3.3745","1.1438"
"","4.1200","3.4099","1.1602"
"","4.1600","3.4433","1.1752"
"","4.2000","3.4761","1.1850"
"","4.2400","3.5105","1.1984"
"","4.2800","3.5416","1.2102"
"","4.3200","3.5755","1.2239"
"","4.3600","3.6109","1.2404"
"","4.4000","3.6427","1.2513"
"","4.4400","3.6761","1.2642"
"","4.4800","3.7086","1.2761"
"","4.5200","3.7421","1.2896"
"","4.5600","3.7764","1.3030"
"","4.6000","3.8094","1.3171"
"","4.6400","3.8426","1.3275"
"","4.6800","3.8759","1.3410"
"","4.7200","3.9088","1.3545"
"","4.7600","3.9429","1.3697"
"","4.8000","3.9763","1.3804"
"","4.8400","4.0086","1.3937"
"","4.8800","4.0426","1.4085"
"","4.9200","4.0768","1.4233"
"","4.9600","4.1091","1.4345"
"","5.0000","4.1438","1.4485"
"","5.0400","4.1745","1.4560"
"","5.0800","4.2088","1.4736"
"","5.1200","4.2445","1.4914"
"","5.1600","4.2756","1.4986"
"","5.2000","4.3088","1.5162"
"","5.2400","4.3435","1.5312"
"","5.2800","4.3750","1.5401"
"","5.3200","4.4095","1.5542"
"","5.3600","4.4440","1.5684"
"","5.4000","4.4748","1.5775"
"","5.4400","4.5093","1.5935"
"","5.4800","4.5432","1.6085"
"","5.5200","4.5757","1.6194"
"","5.5600","4.6097","1.6337"
"","5.6000","4.6419","1.6445"
"","5.6400","4.6757","1.6604"
"","5.6800","4.7105","1.6753"
"","5.7200","4.7431","1.6877"
"","5.7600","4.7752","1.6984"
"","5.8000","4.8099","1.7101"
"","5.8400","4.8430","1.7199"
"","5.8800","4.8758","1.7293"
"","5.9200","4.9097","1.7424"
"","5.9600","4.9419","1.7542"
"","6.0000","4.9760","1.7652"
"","6.0400","5.0089","1.7767"
"","6.0800","5.0426","1.7905"
"","6.1200","5.0768","1.8046"
"","6.1600","5.1089","1.8170"
"","6.2000","5.1424","1.8288"
"","6.2400","5.1768","1.8429"
"","6.2800","5.2087","1.8559"
"","6.3200","5.2423","1.8672"
"","6.3600","5.2758","1.8802"
"","6.4000","5.3089","1.8937"
"","6.4400","5.3436","1.9068"
"","6.4800","5.3761","1.9127"
"","6.5200","5.4088","1.9255"
"","6.5600","5.4433","1.9392"
"","6.6000","5.4755","1.9479"
"","6.6400","5.5094","1.9590"
"","6.6800","5.5431","1.9701"
"","6.7200","5.5751","1.9779"
"","6.7600","5.6090","1.9924"
"","6.8000","5.6440","2.0069"
"","6.8400","5.6763","2.0154"
"","6.8800","5.7093","2.0241"
"","6.9200","5.7430","2.0354"
"","6.9600","5.7762","2.0490"
"","7.0000","5.8098","2.0593"
"","7.0400","5.8421","2.0677"
"","7.0800","5.8743","2.0771"
"","7.1200","5.9097","2.0913"
"","7.1600","5.9431","2.1040"
"","7.2000","5.9758","2.1114"
"","7.2400","6.0107","2.1250"
"","7.2800","6.0421","2.1340"
"","7.3200","6.0752","2.1439"
"","7.3600","6.1102","2.1558"
"","7.4000","6.1429","2.1678"
"","7.4400","6.1755","2.1756"
"","7.4800","6.2086","2.1848"
"","7.5200","6.2426","2.2011"
"","7.5600","6.2766","2.2089"
"","7.6000","6.3099","2.2178"
"","7.6400","6.3427","2.2291"
"","7.6800","6.3761","2.2367"
"","7.7200","6.4087","2.2415"
"","7.7600","6.4435","2.2559"
"","7.8000","6.4763","2.2651"
"","7.8400","6.5082","2.2730"
"","7.8800","6.5429","2.2859"
"","7.9200","6.5766","2.2946"
"","7.9600","6.6098","2.3037"
"","8.0000","6.6432","2.3119"
"","8.0400","6.6750","2.3171"
"","8.0800","6.7085","2.3288"
"","8.1200","6.7437","2.3409"
"","8.1600","6.7756","2.3459"
"","8.2000","6.8087","2.3551"
"","8.2400","6.8435","2.3658"
"","8.2800","6.8751","2.3703"
"","8.3200","6.9102","2.3842"
"","8.3600","6.9442","2.3959"
"","8.4000","6.9753","2.3958"
"","8.4400","7.0097","2.4081"
"","8.4800","7.0437","2.4171"
"","8.5200","7.0755","2.4233"
"","8.5600","7.1094","2.4304"
"","8.6000","7.1424","2.4372"
"","8.6400","7.1757","2.4489"
"","8.6800","7.2107","2.4583"
"","8.7200","7.2429","2.4625"
"","8.7600","7.2757","2.4702"
"","8.8000","7.3094","2.4776"
"","8.8400","7.3425","2.4898"
"","8.8800","7.3765","2.5001"
"","8.9200","7.4097","2.5024"
"","8.9600","7.4420","2.5101"
"","9.0000","7.4762","2.5190"
"","9.0400","7.5087","2.5221"
"","9.0800","7.5432","2.5325"
"","9.1200","7.5768","2.5401"
"","9.1600","7.6089","2.5420"
"","9.2000","7.6421","2.5479"
"","9.2400","7.6775","2.5626"
"","9.2800","7.7085","2.5634"
"","9.3200","7.7423","2.5701"
"","9.3600","7.7763","2.5784"
"","9.4000","7.8085","2.5866"
"","9.4400","7.8440","2.5964"
"","9.4800","7.8764","2.5974"
"","9.5200","7.9088","2.6015"
"","9.5600","7.9435","2.6109"
"","9.6000","7.9754","2.6134"
"","9.6400","8.0089","2.6209"
"","9.6800","8.0438","2.6289"
"","9.7200","8.0743","2.6275"
"","9.7600","8.1089","2.6405"
"","9.8000","8.1439","2.6517"
"","9.8400","8.1757","2.6570"
"","9.8800","8.2090","2.6589"
"","9.9200","8.2423","2.6656"
"","9.9600","8.2756","2.6753"
"","10.0000","8.3108","2.6844"
"","10.0400","8.3423","2.6868"
"","10.0800","8.3747","2.6899"
"","10.1200","8.4099","2.7021"
"","10.1600","8.4431","2.7095"
"","10.2000","8.4760","2.7176"
"","10.2400","8.5111","2.7239"
"","10.2800","8.5420","2.7276"
"","10.3200","8.5751","2.7325"
"","10.3600","8.6108","2.7408"
"","10.4000","8.6427","2.7456"
"","10.4400","8.6757","2.7494"
"","10.4800","8.7089","2.7557"
"","10.5200","8.7421","2.7640"
"","10.5600","8.7769","2.7712"
"","10.6000","8.8094","2.7736"
"","10.6400","8.8425","2.7847"
"","10.6800","8.8765","2.7951"
"","10.7200","8.9087","2.7994"
"","10.7600","8.9432","2.8092"
"","10.8000","8.9761","2.8120"
"","10.8400","9.0083","2.8170"
"","10.8800","9.0428","2.8267"
"","10.9200","9.0765","2.8300"
"","10.9600","9.1096","2.8382"
"","11.0000","9.1438","2.8439"
"","11.0400","9.1751","2.8445"
"","11.0800","9.2081","2.8511"
"","11.1200","9.2445","2.8636"
[...]
"","11.1200","9.2220","2.0187"
"","11.1600","9.2564","2.0253"
"","11.2000","9.2913","2.0349"
"","11.2400","9.3231","2.0365"
"","11.2800","9.3566","2.0421"
"","11.3200","9.3892","2.0453"
"","11.3600","9.4228","2.0532"
"","11.4000","9.4574","2.0595"
"","11.4400","9.4899","2.0615"
"","11.4800","9.5222","2.0652"
"","11.5200","9.5572","2.0728"
"","11.5600","9.5900","2.0753"
"","11.6000","9.6225","2.0779"
"","11.6400","9.6577","2.0863"
"","11.6800","9.6896","2.0852"
"","11.7200","9.7215","2.0892"
"","11.7600","9.7580","2.0982"
"","11.8000","9.7894","2.1030"
"","11.8400","9.8233","2.1026"
"","11.8800","9.8567","2.1084"
"","11.9200","9.8887","2.1103"
"","11.9600","9.9241","2.1187"
"","12.0000","9.9571","2.1205"
"","12.0400","9.9890","2.1240"
"","12.0800","10.0229","2.1291"
"","12.1200","10.0564","2.1370"
"","12.1600","10.0896","2.1416"
"","12.2000","10.1242","2.1466"
"","12.2400","10.1559","2.1469"
"","12.2800","10.1893","2.1526"
"","12.3200","10.2244","2.1639"
"","12.3600","10.2570","2.1676"
"","12.4000","10.2902","2.1713"
"","12.4400","10.3222","2.1748"
"","12.4800","10.3558","2.1811"
"","12.5200","10.3904","2.1892"
"","12.5600","10.4233","2.1911"
"","12.6000","10.4557","2.1980"
"","12.6400","10.4905","2.2039"
"","12.6800","10.5237","2.2072"
"","12.7200","10.5562","2.2109"
"","12.7600","10.5907","2.2178"
"","12.8000","10.6222","2.2220"
"","12.8400","10.6559","2.2260"
"","12.8800","10.6903","2.2338"
"","12.9200","10.7225","2.2373"
"","12.9600","10.7571","2.2430"
"","13.0000","10.7890","2.2444"
"","13.0400","10.8234","2.2489"
"","13.0800","10.8579","2.2569"
"","13.1200","10.8898","2.2573"
"","13.1600","10.9228","2.2630"
"","13.2000","10.9569","2.2685"
"","13.2400","10.9889","2.2710"
"","13.2800","11.0238","2.2797"
"","13.3200","11.0569","2.2827"
"","13.3600","11.0892","2.2849"
"","13.4000","11.1229","2.2894"
"","13.4400","11.1571","2.2945"
"","13.4800","11.1894","2.2982"
"","13.5200","11.2233","2.3025"
"","13.5600","11.2562","2.3069"
"","13.6000","11.2887","2.3118"
"","13.6400","11.3241","2.3191"
"","13.6800","11.3577","2.3233"
"","13.7200","11.3882","2.3252"
"","13.7600","11.4232","2.3317"
"","13.8000","11.4569","2.3410"
"","13.8400","11.4898","2.3426"
"","13.8800","11.5240","2.3488"
"","13.9200","11.5553","2.3526"
"","13.9600","11.5893","2.3569"
"","14.0000","11.6228","2.3611"
"","14.0400","11.6572","2.3686"
"","14.0800","11.6898","2.3715"
"","14.1200","11.7223","2.3708"
"","14.1600","11.7568","2.3796"
"","14.2000","11.7909","2.3864"
"","14.2400","11.8231","2.3859"
"","14.2800","11.8567","2.3912"
"","14.3200","11.8892","2.3901"
"","14.3600","11.9223","2.3935"
"","14.4000","11.9574","2.4031"
"","14.4400","11.9897","2.4014"
"","14.4800","12.0222","2.4041"
"","14.5200","12.0573","2.4109"
"","14.5600","12.0897","2.4154"
"","14.6000","12.1234","2.4192"
"","14.6400","12.1578","2.4229"
"","14.6800","12.1891","2.4238"
"","14.7200","12.2217","2.4272"
"","14.7600","12.2577","2.4359"
"","14.8000","12.2896","2.4360"
"","14.8400","12.3227","2.4392"
"","14.8800","12.3570","2.4422"
"","14.9200","12.3889","2.4467"
"","14.9600","12.4237","2.4512"
"","15.0000","12.4571","2.4574"
"","15.0400","12.4888","2.4566"
"","15.0800","12.5225","2.4592"
"","15.1200","12.5565","2.4657"
"","15.1600","12.5896","2.4715"
"","15.2000","12.6237","2.4690"
"","15.2400","12.6561","2.4706"
"","15.2800","12.6894","2.4731"
"","15.3200","12.7241","2.4771"
"","15.3600","12.7574","2.4812"
"","15.4000","12.7896","2.4826"
"","15.4400","12.8222","2.4814"
"","15.4800","12.8558","2.4872"
"","15.5200","12.8905","2.4950"
"","15.5600","12.9227","2.4939"
"","15.6000","12.9566","2.4995"
"","15.6400","12.9900","2.5025"
"","15.6800","13.0234","2.5047"
"","15.7200","13.0569","2.5090"
"","15.7600","13.0902","2.5120"
"","15.8000","13.1217","2.5143"
"","15.8400","13.1559","2.5197"
"","15.8800","13.1901","2.5234"
"","15.9200","13.2227","2.5283"
"","15.9600","13.2570","2.5306"
"","16.0000","13.2892","2.5305"
"","16.0400","13.3229","2.5345"
"","16.0800","13.3577","2.5413"
"","16.1200","13.3897","2.5403"
"","16.1600","13.4224","2.5422"
"","16.2000","13.4566","2.5481"
"","16.2400","13.4893","2.5498"
"","16.2800","13.5234","2.5545"
"","16.3200","13.5575","2.5571"
"","16.3600","13.5894","2.5570"
"","16.4000","13.6227","2.5609"
"","16.4400","13.6572","2.5633"
"","16.4800","13.6895","2.5656"
"","16.5200","13.7237","2.5699"
"","16.5600","13.7560","2.5681"
"","16.6000","13.7887","2.5725"
"","16.6400","13.8242","2.5773"
"","16.6800","13.8572","2.5801"
"","16.7200","13.8890","2.5807"
"","16.7600","13.9229","2.5798"
"","16.8000","13.9565","2.5862"
"","16.8400","13.9901","2.5866"
"","16.8800","14.0235","2.5860"
"","16.9200","14.0552","2.5858"
"","16.9600","14.0897","2.5896"
"","17.0000","14.1227","2.5923"
"","17.0400","14.1569","2.5962"
"","17.0800","14.1901","2.5950"
"","17.1200","14.2224","2.5936"
"","17.1600","14.2568","2.5986"
"","17.2000","14.2911","2.6009"
"","17.2400","14.3228","2.5970"
"","17.2800","14.3566","2.5987"
"","17.3200","14.3889","2.5979"
"","17.3600","14.4229","2.5998"
"","17.4000","14.4575","2.6055"
"","17.4400","14.4896","2.6016"
"","17.4800","14.5220","2.6008"
"","17.5200","14.5568","2.6062"
"","17.5600","14.5901","2.6060"
"","17.6000","14.6231","2.6077"
"","17.6400","14.6579","2.6102"
"","17.6800","14.6892","2.6047"
"","17.7200","14.7222","2.6064"
"","17.7600","14.7577","2.6103"
"","17.8000","14.7895","2.6094"
"","17.8400","14.8231","2.6101"
"","17.8800","14.8561","2.6091"
"","17.9200","14.8891","2.6110"
"","17.9600","14.9241","2.6151"
"","18.0000","14.9573","2.6162"
"","18.0400","14.9885","2.6118"
"","18.0800","15.0229","2.6145"
"","18.1200","15.0561","2.6190"
"","18.1600","15.0899","2.6206"
"","18.2000","15.1242","2.6209"
"","18.2400","15.1555","2.6166"
"","18.2800","15.1901","2.6230"
"","18.3200","15.2241","2.6233"
"","18.3600","15.2570","2.6224"
"","18.4000","15.2899","2.6237"
"","18.4400","15.3220","2.6184"
"","18.4800","15.3556","2.6261"
"","18.5200","15.3903","2.6314"
"","18.5600","15.4230","2.6299"
"","18.6000","15.4561","2.6313"
"","18.6400","15.4903","2.6344"
"","18.6800","15.5233","2.6353"
"","18.7200","15.5570","2.6377"
"","18.7600","15.5900","2.6360"
"","18.8000","15.6219","2.6345"
"","18.8400","15.6566","2.6399"
"","18.8800","15.6897","2.6411"
"","18.9200","15.7227","2.6416"
"","18.9600","15.7575","2.6462"
"","19.0000","15.7890","2.6414"
"","19.0400","15.8228","2.6413"
"","19.0800","15.8581","2.6474"
"","19.1200","15.8895","2.6445"
"","19.1600","15.9221","2.6430"
"","19.2000","15.9576","2.6471"
"","19.2400","15.9889","2.6452"
"","19.2800","16.0240","2.6487"
"","19.3200","16.0577","2.6496"
"","19.3600","16.0889","2.6421"
"","19.4000","16.1231","2.6427"
"","19.4400","16.1567","2.6456"
"","19.4800","16.1898","2.6469"
"","19.5200","16.2235","2.6467"
"","19.5600","16.2558","2.6460"
"","19.6000","16.2886","2.6470"
"","19.6400","16.3243","2.6499"
"","19.6800","16.3568","2.6514"
"","19.7200","16.3891","2.6496"
"","19.7600","16.4232","2.6485"
"","19.8000","16.4567","2.6502"
"","19.8400","16.4900","2.6495"
"","19.8800","16.5234","2.6468"
"","19.9200","16.5552","2.6460"
"","19.9600","16.5896","2.6446"
"","20.0000","16.6230","2.6468"
"","20.0400","16.6568","2.6480"
"","20.0800","16.6898","2.6425"
"","20.1200","16.7223","2.6406"
"","20.1600","16.7566","2.6427"
"","20.2000","16.7912","2.6445"
"","20.2400","16.8224","2.6373"
"","20.2800","16.8567","2.6419"
"","20.3200","16.8894","2.6385"
"","20.3600","16.9223","2.6380"
"","20.4000","16.9580","2.6436"
"","20.4400","16.9895","2.6377"
"","20.4800","17.0223","2.6336"
"","20.5200","17.0570","2.6339"
"","20.5600","17.0902","2.6340"
"","20.6000","17.1233","2.6316"
"","20.6400","17.1576","2.6283"
"","20.6800","17.1890","2.6249"
"","20.7200","17.2225","2.6253"
"","20.7600","17.2577","2.6291"
"","20.8000","17.2893","2.6240"
"","20.8400","17.3231","2.6247"
"","20.8800","17.3566","2.6252"
"","20.9200","17.3887","2.6223"
"","20.9600","17.4243","2.6277"
"","21.0000","17.4576","2.6266"
"","21.0400","17.4886","2.6201"
"","21.0800","17.5232","2.6196"
"","21.1200","17.5562","2.6166"
"","21.1600","17.5897","2.6221"
"","21.2000","17.6239","2.6192"
"","21.2400","17.6559","2.6166"
"","21.2800","17.6899","2.6154"
"","21.3200","17.7237","2.6155"
"","21.3600","17.7573","2.6150"
"","21.4000","17.7897","2.6112"
"","21.4400","17.8219","2.6057"
"","21.4800","17.8554","2.6111"
"","21.5200","17.8909","2.6129"
"","21.5600","17.9229","2.6069"
"","21.6000","17.9561","2.6076"
"","21.6400","17.9901","2.6044"
"","21.6800","18.0230","2.6033"
"","21.7200","18.0570","2.6061"
"","21.7600","18.0901","2.6026"
"","21.8000","18.1218","2.5968"
"","21.8400","18.1561","2.5989"
"","21.8800","18.1901","2.5993"
"","21.9200","18.2229","2.5986"
"","21.9600","18.2569","2.5963"
"","22.0000","18.2891","2.5927"
"","22.0400","18.3227","2.5929"
"","22.0800","18.3580","2.5967"
"","22.1200","18.3898","2.5903"
"","22.1600","18.4216","2.5870"
"","22.2000","18.4571","2.5891"
"","22.2400","18.4894","2.5876"
"","22.2800","18.5233","2.5857"
"","22.3200","18.5573","2.5851"
"","22.3600","18.5894","2.5822"
"","22.4000","18.6231","2.5821"
"","22.4400","18.6573","2.5819"
"","22.4800","18.6893","2.5775"
"","22.5200","18.7236","2.5772"
"","22.5600","18.7558","2.5755"
"","22.6000","18.7884","2.5741"
"","22.6400","18.8244","2.5757"
"","22.6800","18.8573","2.5759"
"","22.7200","18.8888","2.5697"
"","22.7600","18.9234","2.5664"
"","22.8000","18.9567","2.5669"
"","22.8400","18.9900","2.5669"
"","22.8800","19.0236","2.5640"
"","22.9200","19.0556","2.5586"
"","22.9600","19.0889","2.5574"
"","23.0000","19.1236","2.5611"
"","23.0400","19.1564","2.5580"
"","23.0800","19.1905","2.5551"
"","23.1200","19.2220","2.5491"
"","23.1600","19.2565","2.5516"
"","23.2000","19.2908","2.5546"
"","23.2400","19.3231","2.5487"
"","23.2800","19.3562","2.5459"
"","23.3200","19.3892","2.5400"
"","23.3600","19.4219","2.5371"
"","23.4000","19.4580","2.5440"
"","23.4400","19.4897","2.5374"
"","23.4800","19.5222","2.5349"
"","23.5200","19.5566","2.5367"
"","23.5600","19.5904","2.5327"
"","23.6000","19.6228","2.5308"
"","23.6400","19.6578","2.5276"
"","23.6800","19.6889","2.5165"
"","23.7200","19.7224","2.5145"
"","23.7600","19.7578","2.5150"
"","23.8000","19.7897","2.5106"
"","23.8400","19.8228","2.5086"
"","23.8800","19.8563","2.5056"
"","23.9200","19.8885","2.5030"
"","23.9600","19.9231","2.5024"
"","24.0000","19.9580","2.5042"
"","24.0400","19.9892","2.4972"
"","24.0800","20.0236","2.4944"
"","24.1200","20.0565","2.4902"
"","24.1600","20.0902","2.4898"
"","24.2000","20.1239","2.4875"
"","24.2400","20.1562","2.4816"
"","24.2800","20.1898","2.4826"
"","24.3200","20.2243","2.4811"
"","24.3600","20.2569","2.4772"
"","24.4000","20.2902","2.4726"
"","24.4400","20.3218","2.4645"
"","24.4800","20.3555","2.4644"
"","24.5200","20.3906","2.4649"
"","24.5600","20.4232","2.4600"
"","24.6000","20.4553","2.4568"
"","24.6400","20.4902","2.4547"
"","24.6800","20.5226","2.4513"
"","24.7200","20.5570","2.4511"
"","24.7600","20.5906","2.4452"
"","24.8000","20.6225","2.4369"
"","24.8400","20.6565","2.4366"
"","24.8800","20.6901","2.4293"
"","24.9200","20.7227","2.4208"
"","24.9600","20.7568","2.4101"
"","25.0000","20.7893","2.4000"
"","25.0400","20.8226","2.3929"
"","25.0800","20.8585","2.3914"
"","25.1200","20.8892","2.3761"
"","25.1600","20.9227","2.3704"
"","25.2000","20.9573","2.3656"
"","25.2400","20.9888","2.3523"
"","25.2800","21.0236","2.3484"
"","25.3200","21.0576","2.3380"
"","25.3600","21.0885","2.3273"
"","25.4000","21.1237","2.3223"
"","25.4400","21.1572","2.3159"
"","25.4800","21.1893","2.3070"
"","25.5200","21.2240","2.2953"
"","25.5600","21.2557","2.2616"
"","25.6000","21.2884","2.2411"
"","25.6400","21.3243","2.2337"
"","25.6800","21.3567","2.2169"
"","25.7200","21.3894","2.1978"
"","25.7600","21.4237","2.1773"
"","25.8000","21.4566","2.1550"
"","25.8400","21.4901","2.1283"
"","25.8800","21.5234","2.1073"
"","25.9200","21.5553","2.0928"
"","25.9600","21.5890","2.0683"
"","26.0000","21.6235","2.0432"
"","26.0400","21.6567","1.9312"
"","26.0800","21.6903","1.8519"
"","26.1200","21.7222","1.8336"
"","26.1600","21.7564","1.8272"
"","26.2000","21.7915","1.8162"
"","26.2400","21.8227","1.8054"
"","26.2800","21.8565","1.7996"
"","26.3200","21.8897","1.7941"
"","26.3600","21.9212","1.7869"
"","26.4000","21.9577","1.7852"
"","26.4400","21.9902","1.7766"
"","26.4800","22.0221","1.7674"
"","26.5200","22.0575","1.7681"
"","26.5600","22.0903","1.7625"
"","26.6000","22.1229","1.7514"
"","26.6400","22.1578","1.7462"
"","26.6800","22.1887","1.7382"
"","26.7200","22.2226","1.7311"
"","26.7600","22.2579","1.7305"
"","26.8000","22.2891","1.7175"
"","26.8400","22.3228","1.7095"
"","26.8800","22.3567","1.7012"
"","26.9200","22.3888","1.6932"
"","26.9600","22.4241","1.6903"
"","27.0000","22.4577","1.6840"
"","27.0400","22.4884","1.6651"
"","27.0800","22.5230","1.6544"
"","27.1200","22.5565","1.6458"
"","27.1600","22.5893","1.6332"
"","27.2000","22.6239","1.6173"
"","27.2400","22.6563","1.5719"
"","27.2800","22.6892","1.5179"
"","27.3200","22.7244","1.5064"
"","27.3600","22.7569","1.4976"
"","27.4000","22.7901","1.4817"
"","27.4400","22.8220","1.4688"
"","27.4800","22.8552","1.4584"
"","27.5200","22.8910","1.4228"
"","27.5600","22.9229","1.3960"
"","27.6000","22.9559","1.3871"
"","27.6400","22.9901","1.3800"
"","27.6800","23.0229","1.3689"
"","27.7200","23.0576","1.3608"
"","27.7600","23.0907","1.3539"
"","27.8000","23.1214","1.3430"
"","27.8400","23.1558","1.3427"
"","27.8800","23.1902","1.3394"
"","27.9200","23.2221","1.3232"
"","27.9600","23.2566","1.3164"
"","28.0000","23.2896","1.3034"
"","28.0400","23.3227","1.2901"
"","28.0800","23.3581","1.2807"
"","28.1200","23.3896","1.2587"
"","28.1600","23.4221","1.2386"
"","28.2000","23.4570","1.2241"
"","28.2400","23.4894","1.2095"
"","28.2800","23.5232","1.2041"
"","28.3200","23.5578","1.1980"
"","28.3600","23.5882","1.1824"
"","28.4000","23.6235","1.1652"
"","28.4400","23.6574","1.1488"
"","28.4800","23.6888","1.1330"
"","28.5200","23.7240","1.1283"
"","28.5600","23.7557","1.1224"
"","28.6000","23.7887","1.1174"
"","28.6400","23.8242","1.1174"
"","28.6800","23.8568","1.1087"
"","28.7200","23.8891","1.1020"
"","28.7600","23.9239","1.0957"
"","28.8000","23.9564","1.0910"
"","28.8400","23.9901","1.0853"
"","28.8800","24.0237","1.0848"
"","28.9200","24.0549","1.0757"
"","28.9600","24.0893","1.0740"
"","29.0000","24.1236","1.0739"
"","29.0400","24.1568","1.0703"
"","29.0800","24.1901","1.0675"
"","29.1200","24.2221","1.0627"
"","29.1600","24.2562","1.0572"
"","29.2000","24.2909","1.0527"
"","29.2400","24.3234","1.0462"
"","29.2800","24.3558","1.0395"
"","29.3200","24.3896","1.0387"
"","29.3600","24.4217","1.0340"
"","29.4000","24.4580","1.0326"
"","29.4400","24.4897","1.0250"
"","29.4800","24.5215","1.0179"
"","29.5200","24.5574","1.0200"
"","29.5600","24.5897","1.0111"
"","29.6000","24.6228","1.0059"
"","29.6400","24.6578","1.0052"
"","29.6800","24.6886","0.9976"
"","29.7200","24.7221","0.9967"
"","29.7600","24.7583","0.9937"
"","29.8000","24.7891","0.9855"
"","29.8400","24.8224","0.9752"
"","29.8800","24.8570","0.9674"
"","29.9200","24.8888","0.9567"
"","29.9600","24.9238","0.9442"
"","30.0000","24.9575","0.8680"
"","30.0400","24.9889","0.8460"
"","30.0800","25.0230","0.8469"
"","30.1200","25.0566","0.8479"
"","30.1600","25.0896","0.8447"
"","30.2000","25.1237","0.8447"
"","30.2400","25.1566","0.8467"
"","30.2800","25.1898","0.8448"
"","30.3200","25.2244","0.8486"
"","30.3600","25.2566","0.8408"
"","30.4000","25.2902","0.8396"
"","30.4400","25.3221","0.8413"
"","30.4800","25.3559","0.8424"
"","30.5200","25.3907","0.8443"
"","30.5600","25.4232","0.8438"
"","30.6000","25.4559","0.8440"
"","30.6400","25.4907","0.8455"
"","30.6800","25.5228","0.8443"
"","30.7200","25.5575","0.8469"
"","30.7600","25.5906","0.8477"
"","30.8000","25.6221","0.8455"
"","30.8400","25.6559","0.8476"
"","30.8800","25.6904","0.8488"
"","30.9200","25.7222","0.8467"
"","30.9600","25.7566","0.8495"
"","31.0000","25.7900","0.8496"
"","31.0400","25.8230","0.8501"
"","31.0800","25.8580","0.8525"
"","31.1200","25.8897","0.8512"
"","31.1600","25.9222","0.8491"
"","31.2000","25.9570","0.8511"
"","31.2400","25.9892","0.8503"
"","31.2800","26.0234","0.8510"
"","31.3200","26.0576","0.8540"
"","31.3600","26.0879","0.8517"
"","31.4000","26.1237","0.8551"
"","31.4400","26.1574","0.8562"
"","31.4800","26.1888","0.8519"
"","31.5200","26.2239","0.8561"
"","31.5600","26.2560","0.8563"
"","31.6000","26.2884","0.8561"
"","31.6400","26.3242","0.8598"
"","31.6800","26.3566","0.8589"
"","31.7200","26.3894","0.8582"
"","31.7600","26.4235","0.8603"
"","31.8000","26.4570","0.8603"
"","31.8400","26.4899","0.8591"
"","31.8800","26.5235","0.8591"
"","31.9200","26.5551","0.8581"
"","31.9600","26.5890","0.8613"
"","32.0000","26.6235","0.8624"
"","32.0400","26.6571","0.8617"
"","32.0800","26.6902","0.8596"
"","32.1200","26.7226","0.8625"
"","32.1600","26.7565","0.8618"
"","32.2000","26.7905","0.8638"
"","32.2400","26.8230","0.8613"
"","32.2800","26.8568","0.8603"
"","32.3200","26.8893","0.8581"
"","32.3600","26.9217","0.8575"
"","32.4000","26.9580","0.8613"
"","32.4400","26.9898","0.8579"
"","32.4800","27.0215","0.8540"
"","32.5200","27.0574","0.8596"
"","32.5600","27.0900","0.8574"
"","32.6000","27.1230","0.8581"
"","32.6400","27.1575","0.8589"
"","32.6800","27.1887","0.8574"
"","32.7200","27.2225","0.8583"
"","32.7600","27.2578","0.8626"
"","32.8000","27.2896","0.8588"
"","32.8400","27.3224","0.8614"
"","32.8800","27.3569","0.8631"
"","32.9200","27.3887","0.8608"
"","32.9600","27.4236","0.8623"
"","33.0000","27.4573","0.8628"
"","33.0400","27.4884","0.8592"
"","33.0800","27.5229","0.8641"
"","33.1200","27.5564","0.8637"
"","33.1600","27.5892","0.8633"
"","33.2000","27.6235","0.8643"
"","33.2400","27.6562","0.8639"
"","33.2800","27.6897","0.8649"
"","33.3200","27.7242","0.8677"
"","33.3600","27.7556","0.8637"
"","33.4000","27.7888","0.8639"
"","33.4400","27.8230","0.8668"
"","33.4800","27.8557","0.8657"
"","33.5200","27.8911","0.8686"
"","33.5600","27.9232","0.8685"
"","33.6000","27.9563","0.8672"
"","33.6400","27.9900","0.8691"
"","33.6800","28.0234","0.8686"
"","33.7200","28.0573","0.8702"
"","33.7600","28.0903","0.8703"
"","33.8000","28.1223","0.8687"
"","33.8400","28.1562","0.8727"
"","33.8800","28.1900","0.8701"
"","33.9200","28.2224","0.8715"
"","33.9600","28.2567","0.8723"
"","34.0000","28.2897","0.8714"
"","34.0400","28.3226","0.8724"
"","34.0800","28.3568","0.8732"
"","34.1200","28.3880","0.8694"
"","34.1600","28.4228","0.8736"
"","34.2000","28.4576","0.8727"
"","34.2400","28.4896","0.8745"
"","34.2800","28.5238","0.8759"
"","34.3200","28.5575","0.8773"
"","34.3600","28.5890","0.8735"
"","34.4000","28.6234","0.8763"
"","34.4400","28.6579","0.8781"
"","34.4800","28.6890","0.8743"
"","34.5200","28.7237","0.8788"
"","34.5600","28.7560","0.8796"
"","34.6000","28.7885","0.8782"
"","34.6400","28.8242","0.8825"
"","34.6800","28.8566","0.8791"
"","34.7200","28.8890","0.8813"
"","34.7600","28.9221","0.8818"
"","34.8000","28.9546","0.8803"
"","34.8400","28.9885","0.8825"
"","34.8800","29.0242","0.8872"
"","34.9200","29.0570","0.8849"
"","34.9600","29.0904","0.8848"
"","35.0000","29.1239","0.8848"
"","35.0400","29.1575","0.8870"
"","35.0800","29.1908","0.8863"
"","35.1200","29.2226","0.8834"
"","35.1600","29.2562","0.8876"
"","35.2000","29.2908","0.8871"
"","35.2400","29.3233","0.8865"
"","35.2800","29.3567","0.8886"
"","35.3200","29.3895","0.8868"
"","35.3600","29.4221","0.8875"
"","35.4000","29.4574","0.8934"
"","35.4400","29.4899","0.8895"
"","35.4800","29.5222","0.8888"
"","35.5200","29.5575","0.8920"
"","35.5600","29.5899","0.8900"
"","35.6000","29.6231","0.8910"
"","35.6400","29.6579","0.8925"
"","35.6800","29.6884","0.8875"
"","35.7200","29.7223","0.8912"
"","35.7600","29.7582","0.8961"
"","35.8000","29.7900","0.8922"
"","35.8400","29.8226","0.8927"
"","35.8800","29.8566","0.8960"
"","35.9200","29.8895","0.8942"
"","35.9600","29.9238","0.8950"
"","36.0000","29.9573","0.8962"
"","36.0400","29.9890","0.8925"
"","36.0540","30.0001","0.8921"