File: Data/Test_2.csv
Data : Criteria 1,,"True"
Data : Data capture scheme,,"Default settings"
Data : Interval 1,(ms),"20.00"
Data : Measurement 1,,"Time"
End of test : Criteria 1,,"Measurement level"
End of test : Measurement 1,,"Displacement"
End of test : Value 1,(mm),"30.00"
Compressive strain (Displacement) : Primary source,,"Displacement"

Results Table 1
,Area under curve,Maximum Force,Displacement at Maximum Force,Modulus (Automatic Young's),Break location,Compressive displacement at Maximum Force,Compressive strain (Displacement) at Maximum Force,Compressive stress at Maximum Force,Energy at Maximum Force,Energy to X-intercept at Modulus (Automatic Young's)
,(J),(kgf),(mm),(kgf/mm^2),,(mm),(%),(kgf/mm^2),(J),(J)
"1","0.3786","2.45","29.59","1.76","-----","29.59","29.59","0.24","0.37","0.01"
"2","0.3718","2.21","24.19","0.96","-----","24.19","24.19","0.22","0.26","0.00"
"3","0.3395","1.91","20.19","1.61","-----","20.19","20.19","0.19","0.20","0.00"
"4","0.3818","2.01","16.48","1.79","-----","16.48","16.48","0.20","0.16","0.00"
"5","0.4905","2.74","20.39","2.30","-----","20.39","20.39","0.27","0.33","0.00"
"6","-----","0.00","0.00","-----","-----","0.00","0.00","0.00","0.00","-----"
"7","-----","2.00","17.67","2.91","-----","17.67","17.67","0.20","0.22","0.01"
"8","0.3605","1.99","15.26","2.62","-----","15.26","15.26","0.20","0.18","0.00"
"9","0.4294","3.67","29.99","0.97","-----","29.99","29.99","0.37","0.43","0.00"
"10","0.6059","3.93","26.86","1.41","-----","26.86","26.86","0.39","0.50","0.00"
"11","0.4423","2.84","30.00","2.21","-----","30.00","30.00","0.28","0.44","0.01"
"12","0.4687","3.15","22.49","1.46","-----","22.49","22.49","0.32","0.29","0.00"
"13","0.3720","2.11","23.29","2.34","-----","23.29","23.29","0.21","0.26","0.02"
"14","0.3131","1.91","19.89","0.59","-----","19.89","19.89","0.19","0.15","0.00"
"15","0.3807","2.33","25.18","2.39","-----","25.18","25.18","0.23","0.30","0.02"
"16","0.4432","2.57","23.07","1.39","-----","23.07","23.07","0.26","0.31","0.00"
"17","0.3319","2.44","25.87","1.05","-----","25.87","25.87","0.24","0.25","0.00"
"18","0.3137","2.03","22.43","1.24","-----","22.43","22.43","0.20","0.18","0.00"
"19","0.4285","2.48","22.69","2.14","-----","22.69","22.69","0.25","0.28","0.03"
"20","0.3512","2.33","29.97","1.26","-----","29.97","29.97","0.23","0.35","0.00"
"21","0.3063","2.13","21.44","0.93","-----","21.44","21.44","0.21","0.20","0.00"
"22","0.2796","1.74","16.01","1.29","-----","16.01","16.01","0.17","0.11","0.00"
"23","0.2811","1.85","23.95","1.52","-----","23.95","23.95","0.18","0.18","0.00"
"24","0.3128","2.14","21.61","1.25","-----","21.61","21.61","0.21","0.19","0.00"
"25","0.4450","2.66","25.13","1.23","-----","25.13","25.13","0.27","0.33","0.00"
"26","0.5012","3.30","26.46","1.78","-----","26.46","26.46","0.33","0.40","0.00"
"27","0.4562","2.84","21.53","1.18","-----","21.53","21.53","0.28","0.27","0.00"
"28","0.3276","2.21","20.09","2.22","-----","20.09","20.09","0.22","0.17","0.01"
"29","0.3514","2.14","20.70","2.13","-----","20.70","20.70","0.21","0.20","0.01"
"30","0.4033","2.31","24.19","2.23","-----","24.19","24.19","0.23","0.28","0.02"
"31","0.3362","1.86","19.58","1.83","-----","19.58","19.58","0.19","0.22","0.00"

Results Table 2


1,Time,Displacement,Force
,(s),(mm),(kgf)
"","0.0000","0.0000","-0.0004"
"","0.0400","0.0030","0.0016"
"","0.0800","0.0212","0.0046"
"","0.1200","0.0603","0.0074"
"","0.1600","0.0901","0.0087"
"","0.2000","0.1230","0.0052"
"","0.2400","0.1565","0.0113"
"","0.2800","0.1899","0.0117"
"","0.3200","0.2213","0.0094"
"","0.3600","0.2541","0.0153"
"","0.4000","0.2878","0.0164"
"","0.4400","0.3221","0.0196"
"","0.4800","0.3543","0.0238"
"","0.5200","0.3871","0.0235"
"","0.5600","0.4219","0.0308"
"","0.6000","0.4539","0.0323"
"","0.6400","0.4881","0.0313"
"","0.6800","0.5211","0.0362"
"","0.7200","0.5539","0.0411"
"","0.7600","0.5878","0.0408"
"","0.8000","0.6210","0.0459"
"","0.8400","0.6539","0.0474"
"","0.8800","0.6890","0.0544"
"","0.9200","0.7201","0.0527"
"","0.9600","0.7533","0.0552"
"","1.0000","0.7891","0.0618"
"","1.0400","0.8214","0.0615"
"","1.0800","0.8540","0.0623"
"","1.1200","0.8885","0.0686"
"","1.1600","0.9203","0.0733"
"","1.2000","0.9551","0.0728"
"","1.2400","0.9874","0.0751"
"","1.2800","1.0196","0.0810"
"","1.3200","1.0548","0.0804"
"","1.3600","1.0877","0.0846"
"","1.4000","1.1210","0.0898"
"","1.4400","1.1557","0.0909"
"","1.4800","1.1873","0.0936"
"","1.5200","1.2197","0.0959"
"","1.5600","1.2556","0.1021"
"","1.6000","1.2877","0.1020"
"","1.6400","1.3199","0.1038"
"","1.6800","1.3539","0.1104"
"","1.7200","1.3878","0.1108"
"","1.7600","1.4218","0.1129"
"","1.8000","1.4550","0.1196"
"","1.8400","1.4873","0.1175"
"","1.8800","1.5215","0.1245"
"","1.9200","1.5539","0.1275"
"","1.9600","1.5878","0.1266"
"","2.0000","1.6218","0.1331"
"","2.0400","1.6530","0.1344"
"","2.0800","1.6872","0.1363"
"","2.1200","1.7217","0.1405"
"","2.1600","1.7544","0.1436"
"","2.2000","1.7884","0.1463"
"","2.2400","1.8207","0.1483"
"","2.2800","1.8529","0.1526"
"","2.3200","1.8897","0.1549"
"","2.3600","1.9209","0.1588"
"","2.4000","1.9529","0.1592"
"","2.4400","1.9882","0.1652"
"","2.4800","2.0207","0.1668"
"","2.5200","2.0541","0.1680"
"","2.5600","2.0892","0.1740"
"","2.6000","2.1206","0.1759"
"","2.6400","2.1531","0.1780"
"","2.6800","2.1891","0.1838"
"","2.7200","2.2207","0.1833"
"","2.7600","2.2539","0.1848"
"","2.8000","2.2874","0.1898"
"","2.8400","2.3205","0.1916"
"","2.8800","2.3554","0.1934"
"","2.9200","2.3890","0.1962"
"","2.9600","2.4201","0.1965"
"","3.0000","2.4545","0.2023"
"","3.0400","2.4877","0.2035"
"","3.0800","2.5212","0.2035"
"","3.1200","2.5548","0.2066"
"","3.1600","2.5869","0.2069"
"","3.2000","2.6212","0.2091"
"","3.2400","2.6550","0.2124"
"","3.2800","2.6878","0.2135"
"","3.3200","2.7221","0.2127"
"","3.3600","2.7535","0.2159"
"","3.4000","2.7870","0.2160"
"","3.4400","2.8222","0.2168"
"","3.4800","2.8539","0.2193"
"","3.5200","2.8870","0.2219"
"","3.5600","2.9211","0.2267"
"","3.6000","2.9542","0.2278"
"","3.6400","2.9880","0.2274"
"","3.6800","3.0220","0.2308"
"","3.7200","3.0533","0.2319"
"","3.7600","3.0881","0.2342"
"","3.8000","3.1205","0.2350"
"","3.8400","3.1537","0.2345"
"","3.8800","3.1886","0.2317"
"","3.9200","3.2203","0.2295"
"","3.9600","3.2536","0.2297"
"","4.0000","3.2890","0.2335"
"","4.0400","3.3214","0.2304"
"","4.0800","3.3539","0.2220"
"","4.1200","3.3884","0.2169"
"","4.1600","3.4200","0.2087"
"","4.2000","3.4546","0.2065"
"","4.2400","3.4886","0.2105"
"","4.2800","3.5191","0.2105"
"","4.3200","3.5545","0.2155"
"","4.3600","3.5881","0.2205"
"","4.4000","3.6205","0.2219"
"","4.4400","3.6556","0.2228"
"","4.4800","3.6873","0.2221"
"","4.5200","3.7200","0.2191"
"","4.5600","3.7549","0.2252"
"","4.6000","3.7884","0.2267"
"","4.6400","3.8198","0.2273"
"","4.6800","3.8539","0.2323"
"","4.7200","3.8879","0.2366"
"","4.7600","3.9217","0.2403"
"","4.8000","3.9549","0.2439"
"","4.8400","3.9873","0.2454"
"","4.8800","4.0214","0.2493"
"","4.9200","4.0541","0.2553"
"","4.9600","4.0875","0.2577"
"","5.0000","4.1214","0.2616"
"","5.0400","4.1532","0.2643"
"","5.0800","4.1875","0.2661"
"","5.1200","4.2219","0.2652"
"","5.1600","4.2545","0.2583"
"","5.2000","4.2882","0.2518"
"","5.2400","4.3209","0.2520"
"","5.2800","4.3532","0.2562"
"","5.3200","4.3890","0.2613"
"","5.3600","4.4208","0.2627"
"","5.4000","4.4526","0.2628"
"","5.4400","4.4887","0.2688"
"","5.4800","4.5214","0.2693"
"","5.5200","4.5535","0.2744"
"","5.5600","4.5892","0.2795"
"","5.6000","4.6206","0.2814"
"","5.6400","4.6532","0.2860"
"","5.6800","4.6886","0.2914"
"","5.7200","4.7210","0.2934"
"","5.7600","4.7542","0.2984"
"","5.8000","4.7874","0.3036"
"","5.8400","4.8204","0.3037"
"","5.8800","4.8552","0.3088"
"","5.9200","4.8890","0.3111"
"","5.9600","4.9195","0.3110"
"","6.0000","4.9543","0.3176"
"","6.0400","4.9880","0.3186"
"","6.0800","5.0207","0.3207"
"","6.1200","5.0548","0.3226"
"","6.1600","5.0868","0.3230"
"","6.2000","5.1208","0.3269"
"","6.2400","5.1551","0.3302"
"","6.2800","5.1880","0.3304"
"","6.3200","5.2218","0.3347"
"","6.3600","5.2535","0.3361"
"","6.4000","5.2868","0.3372"
"","6.4400","5.3218","0.3441"
"","6.4800","5.3543","0.3472"
"","6.5200","5.3870","0.3491"
"","6.5600","5.4212","0.3538"
"","6.6000","5.4539","0.3556"
"","6.6400","5.4880","0.3573"
"","6.6800","5.5212","0.3626"
"","6.7200","5.5536","0.3632"
"","6.7600","5.5877","0.3661"
"","6.8000","5.6209","0.3698"
"","6.8400","5.6543","0.3714"
"","6.8800","5.6884","0.3744"
"","6.9200","5.7204","0.3775"
"","6.9600","5.7531","0.3813"
"","7.0000","5.7891","0.3853"
"","7.0400","5.8216","0.3877"
"","7.0800","5.8541","0.3889"
"","7.1200","5.8881","0.3945"
"","7.1600","5.9207","0.3979"
"","7.2000","5.9552","0.4004"
"","7.2400","5.9880","0.4024"
"","7.2800","6.0188","0.4032"
"","7.3200","6.0547","0.4079"
"","7.3600","6.0877","0.4082"
"","7.4000","6.1207","0.4107"
"","7.4400","6.1550","0.4097"
"","7.4800","6.1875","0.4111"
"","7.5200","6.2199","0.4127"
"","7.5600","6.2551","0.4159"
"","7.6000","6.2881","0.4187"
"","7.6400","6.3201","0.4205"
"","7.6800","6.3534","0.4215"
"","7.7200","6.3881","0.4229"
"","7.7600","6.4218","0.4225"
"","7.8000","6.4545","0.4255"
"","7.8400","6.4878","0.4270"
"","7.8800","6.5205","0.4309"
"","7.9200","6.5544","0.4324"
"","7.9600","6.5876","0.4339"
"","8.0000","6.6210","0.4355"
"","8.0400","6.6529","0.4390"
"","8.0800","6.6875","0.4409"
"","8.1200","6.7215","0.4440"
"","8.1600","6.7546","0.4465"
"","8.2000","6.7883","0.4431"
"","8.2400","6.8206","0.4424"
"","8.2800","6.8534","0.4434"
"","8.3200","6.8893","0.4454"
"","8.3600","6.9208","0.4457"
"","8.4000","6.9530","0.4467"
"","8.4400","6.9881","0.4488"
"","8.4800","7.0212","0.4493"
"","8.5200","7.0543","0.4500"
"","8.5600","7.0891","0.4522"
"","8.6000","7.1206","0.4522"
"","8.6400","7.1534","0.4546"
"","8.6800","7.1884","0.4613"
"","8.7200","7.2210","0.4609"
"","8.7600","7.2543","0.4642"
"","8.8000","7.2871","0.4683"
"","8.8400","7.3202","0.4707"
"","8.8800","7.3553","0.4749"
"","8.9200","7.3891","0.4782"
"","8.9600","7.4201","0.4731"
"","9.0000","7.4536","0.4766"
"","9.0400","7.4872","0.4811"
"","9.0800","7.5213","0.4810"
"","9.1200","7.5549","0.4828"
"","9.1600","7.5873","0.4819"
"","9.2000","7.6206","0.4845"
"","9.2400","7.6554","0.4876"
"","9.2800","7.6881","0.4890"
"","9.3200","7.7217","0.4857"
"","9.3600","7.7535","0.4862"
"","9.4000","7.7869","0.4836"
"","9.4400","7.8218","0.4834"
"","9.4800","7.8541","0.4788"
"","9.5200","7.8872","0.4805"
"","9.5600","7.9210","0.4827"
"","9.6000","7.9543","0.4832"
"","9.6400","7.9881","0.4844"
"","9.6800","8.0219","0.4914"
"","9.7200","8.0531","0.4918"
"","9.7600","8.0879","0.4959"
"","9.8000","8.1216","0.4982"
"","9.8400","8.1538","0.4997"
"","9.8800","8.1882","0.5029"
"","9.9200","8.2205","0.5024"
"","9.9600","8.2535","0.4996"
"","10.0000","8.2892","0.5042"
"","10.0400","8.3209","0.5072"
"","10.0800","8.3542","0.5072"
"","10.1200","8.3881","0.5107"
"","10.1600","8.4205","0.5095"
"","10.2000","8.4546","0.4971"
"","10.2400","8.4889","0.5000"
"","10.2800","8.5190","0.4996"
"","10.3200","8.5546","0.5042"
"","10.3600","8.5877","0.5049"
"","10.4000","8.6205","0.5063"
"","10.4400","8.6550","0.5059"
"","10.4800","8.6877","0.5049"
"","10.5200","8.7205","0.5072"
"","10.5600","8.7554","0.5145"
"","10.6000","8.7890","0.5163"
"","10.6400","8.8201","0.5163"
"","10.6800","8.8547","0.5225"
"","10.7200","8.8868","0.5234"
"","10.7600","8.9221","0.5267"
"","10.8000","8.9547","0.5258"
"","10.8400","8.9875","0.5290"
"","10.8800","9.0209","0.5288"
"","10.9200","9.0548","0.5320"
"","10.9600","9.0876","0.5324"
"","11.0000","9.1214","0.5324"
"","11.0400","9.1530","0.5337"
"","11.0800","9.1878","0.5327"
"","11.1200","9.2218","0.5373"
"","11.1600","9.2545","0.5378"
"","11.2000","9.2883","0.5399"
"","11.2400","9.3209","0.5413"
"","11.2800","9.3528","0.5435"
"","11.3200","9.3893","0.5453"
"","11.3600","9.4210","0.5448"
"","11.4000","9.4527","0.5443"
"","11.4400","9.4880","0.5470"
"","11.4800","9.5206","0.5483"
"","11.5200","9.5550","0.5503"
"","11.5600","9.5888","0.5522"
"","11.6000","9.6203","0.5530"
"","11.6400","9.6533","0.5551"
"","11.6800","9.6886","0.5583"
"","11.7200","9.7208","0.5579"
"","11.7600","9.7540","0.5599"
"","11.8000","9.7877","0.5631"
"","11.8400","9.8205","0.5648"
"","11.8800","9.8550","0.5675"
"","11.9200","9.8889","0.5731"
"","11.9600","9.9202","0.5746"
"","12.0000","9.9539","0.5796"
"","12.0400","9.9877","0.5838"
"","12.0800","10.0212","0.5865"
"","12.1200","10.0549","0.5899"
"","12.1600","10.0869","0.5912"
"","12.2000","10.1210","0.5930"
"","12.2400","10.1553","0.5977"
"","12.2800","10.1879","0.5991"
"","12.3200","10.2216","0.5993"
"","12.3600","10.2537","0.6080"
"","12.4000","10.2874","0.6181"
"","12.4400","10.3212","0.6269"
"","12.4800","10.3537","0.6328"
"","12.5200","10.3874","0.6407"
"","12.5600","10.4207","0.6469"
"","12.6000","10.4536","0.6550"
"","12.6400","10.4884","0.6623"
"","12.6800","10.5212","0.6677"
"","12.7200","10.5532","0.6734"
"","12.7600","10.5880","0.6822"
"","12.8000","10.6213","0.6897"
"","12.8400","10.6540","0.6953"
"","12.8800","10.6880","0.7019"
"","12.9200","10.7200","0.7066"
"","12.9600","10.7536","0.7139"
"","13.0000","10.7890","0.7222"
"","13.0400","10.8211","0.7239"
"","13.0800","10.8539","0.7288"
"","13.1200","10.8880","0.7371"
"","13.1600","10.9202","0.7417"
"","13.2000","10.9547","0.7498"
"","13.2400","10.9887","0.7591"
"","13.2800","11.0192","0.7629"
"","13.3200","11.0548","0.7718"
"","13.3600","11.0890","0.7784"
"","13.4000","11.1204","0.7827"
"","13.4400","11.1553","0.7899"
"","13.4800","11.1872","0.7947"
"","13.5200","11.2203","0.8022"
"","13.5600","11.2551","0.8090"
"","13.6000","11.2878","0.8150"
"","13.6400","11.3202","0.8173"
"","13.6800","11.3540","0.8257"
"","13.7200","11.3874","0.8324"
"","13.7600","11.4215","0.8386"
"","13.8000","11.4553","0.8454"
"","13.8400","11.4870","0.8479"
"","13.8800","11.5213","0.8550"
"","13.9200","11.5544","0.8634"
"","13.9600","11.5879","0.8692"
"","14.0000","11.6213","0.8735"
"","14.0400","11.6529","0.8776"
"","14.0800","11.6877","0.8884"
"","14.1200","11.7222","0.8941"
"","14.1600","11.7544","0.8966"
"","14.2000","11.7874","0.9043"
"","14.2400","11.8206","0.9111"
"","14.2800","11.8534","0.9142"
"","14.3200","11.8886","0.9233"
"","14.3600","11.9211","0.9271"
"","14.4000","11.9523","0.9305"
"","14.4400","11.9882","0.9375"
"","14.4800","12.0211","0.9407"
"","14.5200","12.0547","0.9497"
"","14.5600","12.0891","0.9583"
"","14.6000","12.1200","0.9615"
"","14.6400","12.1537","0.9675"
"","14.6800","12.1886","0.9746"
"","14.7200","12.2205","0.9778"
"","14.7600","12.2543","0.9836"
"","14.8000","12.2877","0.9904"
"","14.8400","12.3203","0.9982"
"","14.8800","12.3553","1.0030"
"","14.9200","12.3891","1.0117"
"","14.9600","12.4203","1.0159"
"","15.0000","12.4543","1.0225"
"","15.0400","12.4880","1.0294"
"","15.0800","12.5209","1.0368"
"","15.1200","12.5546","1.0386"
"","15.1600","12.5875","1.0426"
"","15.2000","12.6209","1.0493"
"","15.2400","12.6550","1.0590"
"","15.2800","12.6884","1.0638"
"","15.3200","12.7218","1.0677"
"","15.3600","12.7532","1.0700"
"","15.4000","12.7869","1.0784"
"","15.4400","12.8219","1.0876"
"","15.4800","12.8543","1.0914"
"","15.5200","12.8875","1.0966"
"","15.5600","12.9211","1.1022"
"","15.6000","12.9539","1.1072"
"","15.6400","12.9888","1.1156"
"","15.6800","13.0212","1.1169"
"","15.7200","13.0528","1.1212"
"","15.7600","13.0884","1.1298"
"","15.8000","13.1212","1.1345"
"","15.8400","13.1542","1.1377"
"","15.8800","13.1883","1.1439"
"","15.9200","13.2198","1.1466"
"","15.9600","13.2539","1.1509"
"","16.0000","13.2886","1.1562"
"","16.0400","13.3209","1.1587"
"","16.0800","13.3540","1.1678"
"","16.1200","13.3883","1.1750"
"","16.1600","13.4201","1.1770"
"","16.2000","13.4548","1.1867"
"","16.2400","13.4881","1.1933"
"","16.2800","13.5196","1.1975"
"","16.3200","13.5545","1.2063"
"","16.3600","13.5885","1.2150"
"","16.4000","13.6205","1.2194"
"","16.4400","13.6546","1.2248"
"","16.4800","13.6874","1.2301"
"","16.5200","13.7203","1.2341"
"","16.5600","13.7551","1.2406"
"","16.6000","13.7877","1.2428"
"","16.6400","13.8207","1.2470"
"","16.6800","13.8536","1.2512"
"","16.7200","13.8876","1.2543"
"","16.7600","13.9225","1.2601"
"","16.8000","13.9545","1.2621"
"","16.8400","13.9872","1.2672"
"","16.8800","14.0212","1.2765"
"","16.9200","14.0544","1.2815"
"","16.9600","14.0883","1.2893"
"","17.0000","14.1212","1.2943"
"","17.0400","14.1529","1.2987"
"","17.0800","14.1877","1.3084"
"","17.1200","14.2221","1.3149"
"","17.1600","14.2542","1.3189"
"","17.2000","14.2882","1.3246"
"","17.2400","14.3205","1.3304"
"","17.2800","14.3532","1.3367"
"","17.3200","14.3892","1.3456"
"","17.3600","14.4207","1.3488"
"","17.4000","14.4525","1.3546"
"","17.4400","14.4883","1.3663"
"","17.4800","14.5210","1.3681"
"","17.5200","14.5551","1.3741"
"","17.5600","14.5891","1.3797"
"","17.6000","14.6204","1.3816"
"","17.6400","14.6532","1.3879"
"","17.6800","14.6884","1.3963"
"","17.7200","14.7202","1.3989"
"","17.7600","14.7546","1.4022"
"","17.8000","14.7873","1.4037"
"","17.8400","14.8202","1.4087"
"","17.8800","14.8556","1.4140"
"","17.9200","14.8884","1.4172"
"","17.9600","14.9205","1.4215"
"","18.0000","14.9539","1.4247"
"","18.0400","14.9880","1.4316"
"","18.0800","15.0211","1.4377"
"","18.1200","15.0545","1.4401"
"","18.1600","15.0869","1.4446"
"","18.2000","15.1210","1.4502"
"","18.2400","15.1551","1.4554"
"","18.2800","15.1880","1.4596"
"","18.3200","15.2218","1.4646"
"","18.3600","15.2538","1.4680"
"","18.4000","15.2866","1.4735"
"","18.4400","15.3221","1.4789"
"","18.4800","15.3541","1.4804"
"","18.5200","15.3875","1.4848"
"","18.5600","15.4207","1.4854"
"","18.6000","15.4533","1.4832"
"","18.6400","15.4883","1.4781"
"","18.6800","15.5212","1.4692"
"","18.7200","15.5529","1.4677"
"","18.7600","15.5879","1.4753"
"","18.8000","15.6213","1.4784"
"","18.8400","15.6540","1.4800"
"","18.8800","15.6881","1.4829"
"","18.9200","15.7198","1.4835"
"","18.9600","15.7540","1.4867"
"","19.0000","15.7890","1.4780"
"","19.0400","15.8209","1.4653"
"","19.0800","15.8536","1.4675"
"","19.1200","15.8884","1.4701"
"","19.1600","15.9199","1.4696"
"","19.2000","15.9552","1.4757"
"","19.2400","15.9878","1.4761"
"","19.2800","16.0200","1.4773"
"","19.3200","16.0548","1.4782"
"","19.3600","16.0885","1.4778"
"","19.4000","16.1199","1.4714"
"","19.4400","16.1549","1.4712"
"","19.4800","16.1870","1.4703"
"","19.5200","16.2204","1.4723"
"","19.5600","16.2561","1.4765"
"","19.6000","16.2872","1.4732"
"","19.6400","16.3207","1.4744"
"","19.6800","16.3541","1.4781"
"","19.7200","16.3877","1.4829"
"","19.7600","16.4214","1.4831"
"","19.8000","16.4551","1.4837"
"","19.8400","16.4870","1.4848"
"","19.8800","16.5209","1.4854"
"","19.9200","16.5540","1.4880"
"","19.9600","16.5884","1.4889"
"","20.0000","16.6215","1.4880"
"","20.0400","16.6530","1.4849"
"","20.0800","16.6878","1.4904"
"","20.1200","16.7221","1.4913"
"","20.1600","16.7545","1.4866"
"","20.2000","16.7879","1.4868"
"","20.2400","16.8208","1.4866"
"","20.2800","16.8537","1.4876"
"","20.3200","16.8889","1.4903"
"","20.3600","16.9211","1.4840"
"","20.4000","16.9525","1.4838"
"","20.4400","16.9879","1.4880"
"","20.4800","17.0210","1.4857"
"","20.5200","17.0540","1.4846"
"","20.5600","17.0892","1.4871"
"","20.6000","17.1192","1.4826"
"","20.6400","17.1544","1.4921"
"","20.6800","17.1891","1.4979"
"","20.7200","17.2205","1.4994"
"","20.7600","17.2545","1.5037"
"","20.8000","17.2885","1.5083"
"","20.8400","17.3202","1.5083"
"","20.8800","17.3554","1.5156"
"","20.9200","17.3885","1.5203"
"","20.9600","17.4202","1.5235"
"","21.0000","17.4546","1.5282"
"","21.0400","17.4880","1.5364"
"","21.0800","17.5211","1.5413"
"","21.1200","17.5541","1.5443"
"","21.1600","17.5873","1.5484"
"","21.2000","17.6207","1.5510"
"","21.2400","17.6550","1.5549"
"","21.2800","17.6886","1.5580"
"","21.3200","17.7211","1.5600"
"","21.3600","17.7539","1.5658"
"","21.4000","17.7869","1.5753"
"","21.4400","17.8221","1.5831"
"","21.4800","17.8540","1.5884"
"","21.5200","17.8870","1.5978"
"","21.5600","17.9218","1.6037"
"","21.6000","17.9535","1.6075"
"","21.6400","17.9891","1.6173"
"","21.6800","18.0214","1.6190"
"","21.7200","18.0534","1.6222"
"","21.7600","18.0879","1.6332"
"","21.8000","18.1216","1.6380"
"","21.8400","18.1536","1.6400"
"","21.8800","18.1883","1.6457"
"","21.9200","18.2202","1.6512"
"","21.9600","18.2539","1.6578"
"","22.0000","18.2891","1.6631"
"","22.0400","18.3207","1.6650"
"","22.0800","18.3541","1.6704"
"","22.1200","18.3880","1.6759"
"","22.1600","18.4203","1.6826"
"","22.2000","18.4553","1.6933"
"","22.2400","18.4881","1.6945"
"","22.2800","18.5199","1.6987"
"","22.3200","18.5539","1.7054"
"","22.3600","18.5890","1.7127"
"","22.4000","18.6201","1.7112"
"","22.4400","18.6545","1.7052"
"","22.4800","18.6873","1.7036"
"","22.5200","18.7201","1.7101"
"","22.5600","18.7561","1.7190"
"","22.6000","18.7870","1.7189"
"","22.6400","18.8206","1.7229"
"","22.6800","18.8541","1.7310"
"","22.7200","18.8875","1.7372"
"","22.7600","18.9221","1.7456"
"","22.8000","18.9549","1.7476"
"","22.8400","18.9864","1.7494"
"","22.8800","19.0206","1.7602"
"","22.9200","19.0543","1.7675"
"","22.9600","19.0881","1.7777"
"","23.0000","19.1213","1.7819"
"","23.0400","19.1528","1.7845"
"","23.0800","19.1879","1.8000"
"","23.1200","19.2222","1.8078"
"","23.1600","19.2538","1.8091"
"","23.2000","19.2887","1.8191"
"","23.2400","19.3204","1.8249"
"","23.2800","19.3537","1.8337"
"","23.3200","19.3889","1.8425"
"","23.3600","19.4211","1.8473"
"","23.4000","19.4528","1.8521"
"","23.4400","19.4880","1.8615"
"","23.4800","19.5210","1.8698"
"","23.5200","19.5546","1.8775"
"","23.5600","19.5893","1.8860"
"","23.6000","19.6195","1.8856"
"","23.6400","19.6541","1.8971"
"","23.6800","19.6888","1.9046"
"","23.7200","19.7204","1.9060"
"","23.7600","19.7542","1.9140"
"","23.8000","19.7875","1.9177"
"","23.8400","19.8206","1.9240"
"","23.8800","19.8549","1.9313"
"","23.9200","19.8884","1.9351"
"","23.9600","19.9204","1.9377"
"","24.0000","19.9540","1.9417"
"","24.0400","19.9875","1.9518"
"","24.0800","20.0209","1.9552"
"","24.1200","20.0544","1.9555"
"","24.1600","20.0869","1.9663"
"","24.2000","20.1211","1.9702"
"","24.2400","20.1550","1.9758"
"","24.2800","20.1880","1.9804"
"","24.3200","20.2214","1.9874"
"","24.3600","20.2537","1.9916"
"","24.4000","20.2868","1.9935"
"","24.4400","20.3218","2.0038"
"","24.4800","20.3545","2.0064"
"","24.5200","20.3873","2.0077"
"","24.5600","20.4210","2.0133"
"","24.6000","20.4531","2.0109"
"","24.6400","20.4889","2.0235"
"","24.6800","20.5216","2.0312"
"","24.7200","20.5531","2.0241"
"","24.7600","20.5881","2.0359"
"","24.8000","20.6211","2.0416"
"","24.8400","20.6539","2.0420"
"","24.8800","20.6882","2.0514"
"","24.9200","20.7197","2.0521"
"","24.9600","20.7543","2.0552"
"","25.0000","20.7890","2.0589"
"","25.0400","20.8204","2.0581"
"","25.0800","20.8540","2.0558"
"","25.1200","20.8882","2.0642"
"","25.1600","20.9202","2.0699"
"","25.2000","20.9548","2.0784"
"","25.2400","20.9886","2.0699"
"","25.2800","21.0199","2.0741"
"","25.3200","21.0544","2.0868"
"","25.3600","21.0887","2.0863"
"","25.4000","21.1201","2.0832"
"","25.4400","21.1546","2.0924"
"","25.4800","21.1867","2.0958"
"","25.5200","21.2207","2.0971"
"","25.5600","21.2563","2.1077"
"","25.6000","21.2872","2.1048"
"","25.6400","21.3208","2.1085"
"","25.6800","21.3543","2.1137"
"","25.7200","21.3874","2.1119"
"","25.7600","21.4216","2.1164"
"","25.8000","21.4548","2.1087"
"","25.8400","21.4871","2.1091"
"","25.8800","21.5210","2.1088"
"","25.9200","21.5540","2.1026"
"","25.9600","21.5884","2.1112"
"","26.0000","21.6216","2.1059"
"","26.0400","21.6524","2.1050"
"","26.0800","21.6880","2.1130"
"","26.1200","21.7222","2.1109"
"","26.1600","21.7541","2.1166"
"","26.2000","21.7886","2.1223"
"","26.2400","21.8211","2.1197"
"","26.2800","21.8533","2.1201"
"","26.3200","21.8883","2.1232"
"","26.3600","21.9210","2.1292"
"","26.4000","21.9525","2.1271"
"","26.4400","21.9883","2.1334"
"","26.4800","22.0210","2.1381"
"","26.5200","22.0543","2.1373"
"","26.5600","22.0898","2.1449"
"","26.6000","22.1199","2.1347"
"","26.6400","22.1535","2.1348"
"","26.6800","22.1890","2.1439"
"","26.7200","22.2202","2.1384"
"","26.7600","22.2544","2.1454"
"","26.8000","22.2879","2.1487"
"","26.8400","22.3202","2.1491"
"","26.8800","22.3554","2.1573"
"","26.9200","22.3877","2.1592"
"","26.9600","22.4206","2.1590"
"","27.0000","22.4547","2.1638"
"","27.0400","22.4871","2.1639"
"","27.0800","22.5213","2.1727"
"","27.1200","22.5548","2.1760"
"","27.1600","22.5871","2.1750"
"","27.2000","22.6210","2.1818"
"","27.2400","22.6552","2.1854"
"","27.2800","22.6884","2.1883"
"","27.3200","22.7213","2.1873"
"","27.3600","22.7537","2.1879"
"","27.4000","22.7867","2.1948"
"","27.4400","22.8219","2.1970"
"","27.4800","22.8537","2.1915"
"","27.5200","22.8869","2.1949"
"","27.5600","22.9217","2.1985"
"","27.6000","22.9539","2.1960"
"","27.6400","22.9882","2.2032"
"","27.6800","23.0219","2.2030"
"","27.7200","23.0532","2.1985"
"","27.7600","23.0879","2.2025"
"","27.8000","23.1217","2.2060"
"","27.8400","23.1534","2.2051"
"","27.8800","23.1883","2.2106"
"","27.9200","23.2205","2.2116"
"","27.9600","23.2540","2.2156"
"","28.0000","23.2892","2.2208"
"","28.0400","23.3201","2.2184"
"","28.0800","23.3540","2.2232"
"","28.1200","23.3883","2.2254"
"","28.1600","23.4202","2.2238"
"","28.2000","23.4550","2.2234"
"","28.2400","23.4889","2.2151"
"","28.2800","23.5194","2.2096"
"","28.3200","23.5543","2.2159"
"","28.3600","23.5884","2.2204"
"","28.4000","23.6201","2.2193"
"","28.4400","23.6546","2.2228"
"","28.4800","23.6874","2.2237"
"","28.5200","23.7198","2.2238"
"","28.5600","23.7557","2.2274"
"","28.6000","23.7879","2.2259"
"","28.6400","23.8200","2.2230"
"","28.6800","23.8543","2.2246"
"","28.7200","23.8872","2.2255"
"","28.7600","23.9218","2.2249"
"","28.8000","23.9549","2.2096"
"","28.8400","23.9868","2.2029"
"","28.8800","24.0212","2.2031"
"","28.9200","24.0540","2.2035"
"","28.9600","24.0882","2.2069"
"","29.0000","24.1215","2.2047"
"","29.0400","24.1528","2.1969"
"","29.0800","24.1877","2.2044"
"","29.1200","24.2221","2.2043"
"","29.1600","24.2542","2.1988"
"","29.2000","24.2885","2.2007"
"","29.2400","24.3206","2.1973"
"","29.2800","24.3534","2.1955"
"","29.3200","24.3889","2.1985"
"","29.3600","24.4214","2.1920"
"","29.4000","24.4527","2.1886"
"","29.4400","24.4888","2.1930"
"","29.4800","24.5207","2.1860"
"","29.5200","24.5543","2.1837"
"","29.5600","24.5895","2.1847"
"","29.6000","24.6202","2.1816"
"","29.6400","24.6538","2.1825"
"","29.6800","24.6890","2.1868"
"","29.7200","24.7203","2.1843"
"","29.7600","24.7536","2.1839"
"","29.8000","24.7875","2.1865"
"","29.8400","24.8203","2.1892"
"","29.8800","24.8552","2.1934"
"","29.9200","24.8879","2.1941"
"","29.9600","24.9209","2.1950"
"","30.0000","24.9546","2.1941"
"","30.0400","24.9861","2.1918"
"","30.0800","25.0208","2.2024"
"","30.1200","25.0557","2.2028"
"","30.1600","25.0875","2.1866"
"","30.2000","25.1210","2.1857"
"","30.2400","25.1551","2.1898"
"","30.2800","25.1882","2.1934"
"","30.3200","25.2211","2.1943"
"","30.3600","25.2537","2.1944"
"","30.4000","25.2873","2.2003"
"","30.4400","25.3216","2.2042"
"","30.4800","25.3539","2.2057"
"","30.5200","25.3867","2.2100"
"","30.5600","25.4215","2.2143"
"","30.6000","25.4543","2.2160"
"","30.6400","25.4878","2.2169"
"","30.6800","25.5217","2.2172"
"","30.7200","25.5532","2.2136"
"","30.7600","25.5875","2.2158"
"","30.8000","25.6212","2.2127"
"","30.8400","25.6541","2.2147"
"","30.8800","25.6879","2.2139"
"","30.9200","25.7202","2.2139"
"","30.9600","25.7540","2.2190"
"","31.0000","25.7893","2.2233"
"","31.0400","25.8205","2.2198"
"","31.0800","25.8541","2.2234"
"","31.1200","25.8883","2.2278"
"","31.1600","25.9202","2.2291"
"","31.2000","25.9552","2.2346"
"","31.2400","25.9883","2.2324"
"","31.2800","26.0199","2.2315"
"","31.3200","26.0546","2.2353"
"","31.3600","26.0884","2.2406"
"","31.4000","26.1209","2.2431"
"","31.4400","26.1549","2.2460"
"","31.4800","26.1869","2.2437"
"","31.5200","26.2196","2.2478"
"","31.5600","26.2554","2.2540"
"","31.6000","26.2885","2.2561"
"","31.6400","26.3198","2.2512"
"","31.6800","26.3545","2.2557"
"","31.7200","26.3874","2.2601"
"","31.7600","26.4218","2.2647"
"","31.8000","26.4545","2.2628"
"","31.8400","26.4872","2.2625"
"","31.8800","26.5207","2.2650"
"","31.9200","26.5541","2.2671"
"","31.9600","26.5879","2.2714"
"","32.0000","26.6212","2.2716"
"","32.0400","26.6526","2.2692"
"","32.0800","26.6878","2.2760"
"","32.1200","26.7219","2.2790"
"","32.1600","26.7541","2.2762"
"","32.2000","26.7880","2.2809"
"","32.2400","26.8208","2.2793"
"","32.2800","26.8533","2.2812"
"","32.3200","26.8891","2.2885"
"","32.3600","26.9206","2.2835"
"","32.4000","26.9537","2.2851"
"","32.4400","26.9880","2.2885"
"","32.4800","27.0207","2.2864"
"","32.5200","27.0541","2.2904"
"","32.5600","27.0891","2.2943"
"","32.6000","27.1205","2.2913"
"","32.6400","27.1529","2.2883"
"","32.6800","27.1890","2.2993"
"","32.7200","27.2201","2.2964"
"","32.7600","27.2538","2.2980"
"","32.8000","27.2882","2.3013"
"","32.8400","27.3205","2.3043"
"","32.8800","27.3557","2.3096"
"","32.9200","27.3884","2.3082"
"","32.9600","27.4207","2.3079"
"","33.0000","27.4548","2.3103"
"","33.0400","27.4877","2.3121"
"","33.0800","27.5213","2.3158"
"","33.1200","27.5552","2.3171"
"","33.1600","27.5874","2.3174"
"","33.2000","27.6205","2.3226"
"","33.2400","27.6547","2.3239"
"","33.2800","27.6883","2.3289"
"","33.3200","27.7214","2.3300"
"","33.3600","27.7530","2.3262"
"","33.4000","27.7880","2.3343"
"","33.4400","27.8211","2.3351"
"","33.4800","27.8527","2.3307"
"","33.5200","27.8872","2.3372"
"","33.5600","27.9218","2.3427"
"","33.6000","27.9547","2.3411"
"","33.6400","27.9879","2.3440"
"","33.6800","28.0223","2.3482"
"","33.7200","28.0530","2.3449"
"","33.7600","28.0880","2.3531"
"","33.8000","28.1211","2.3525"
"","33.8400","28.1534","2.3527"
"","33.8800","28.1885","2.3582"
"","33.9200","28.2203","2.3587"
"","33.9600","28.2536","2.3608"
"","34.0000","28.2893","2.3659"
"","34.0400","28.3211","2.3653"
"","34.0800","28.3537","2.3643"
"","34.1200","28.3886","2.3698"
"","34.1600","28.4201","2.3684"
"","34.2000","28.4549","2.3755"
"","34.2400","28.4883","2.3762"
"","34.2800","28.5196","2.3738"
"","34.3200","28.5548","2.3801"
"","34.3600","28.5880","2.3847"
"","34.4000","28.6208","2.3846"
"","34.4400","28.6547","2.3876"
"","34.4800","28.6873","2.3881"
"","34.5200","28.7201","2.3914"
"","34.5600","28.7555","2.3965"
"","34.6000","28.7888","2.4007"
"","34.6400","28.8195","2.3971"
"","34.6800","28.8543","2.3995"
"","34.7200","28.8878","2.4042"
"","34.7600","28.9216","2.4083"
"","34.8000","28.9549","2.4067"
"","34.8400","28.9867","2.4090"
"","34.8800","29.0212","2.4147"
"","34.9200","29.0543","2.4179"
"","34.9600","29.0873","2.4208"
"","35.0000","29.1213","2.4216"
"","35.0400","29.1533","2.4210"
"","35.0800","29.1876","2.4270"
"","35.1200","29.2218","2.4288"
"","35.1600","29.2544","2.4312"
"","35.2000","29.2882","2.4318"
"","35.2400","29.3210","2.4309"
"","35.2800","29.3533","2.4319"
"","35.3200","29.3891","2.4375"
"","35.3600","29.4211","2.4349"
"","35.4000","29.4531","2.4358"
"","35.4400","29.4883","2.4396"
"","35.4800","29.5205","2.4392"
"","35.5200","29.5543","2.4418"
"","35.5600","29.5892","2.4456"
"","35.6000","29.6207","2.4420"
"","35.6400","29.6534","2.4380"
"","35.6800","29.6887","2.4305"
"","35.7200","29.7205","2.4258"
"","35.7600","29.7540","2.4164"
"","35.8000","29.7883","2.4039"
"","35.8400","29.8197","2.3710"
"","35.8800","29.8551","2.3520"
"","35.9200","29.8889","2.3435"
"","35.9600","29.9200","2.3253"
"","36.0000","29.9547","2.3099"
"","36.0400","29.9874","2.2877"
"","36.0550","30.0008","2.2815"
2,Time,Displacement,Force
,(s),(mm),(kgf)
"","0.0000","0.0000","0.0014"
"","0.0400","0.0037","0.0023"
"","0.0800","0.0246","0.0040"
"","0.1200","0.0626","0.0046"
"","0.1600","0.0914","0.0115"
"","0.2000","0.1270","0.0118"
"","0.2400","0.1598","0.0112"
"","0.2800","0.1918","0.0151"
"","0.3200","0.2269","0.0187"
"","0.3600","0.2579","0.0192"
"","0.4000","0.2910","0.0195"
"","0.4400","0.3256","0.0250"
"","0.4800","0.3574","0.0265"
"","0.5200","0.3904","0.0278"
"","0.5600","0.4242","0.0311"
"","0.6000","0.4572","0.0286"
"","0.6400","0.4915","0.0305"
"","0.6800","0.5247","0.0345"
"","0.7200","0.5570","0.0371"
"","0.7600","0.5906","0.0416"
"","0.8000","0.6242","0.0421"
"","0.8400","0.6576","0.0437"
"","0.8800","0.6909","0.0495"
"","0.9200","0.7235","0.0487"
"","0.9600","0.7575","0.0498"
"","1.0000","0.7913","0.0581"
"","1.0400","0.8243","0.0611"
"","1.0800","0.8581","0.0587"
"","1.1200","0.8902","0.0660"
"","1.1600","0.9229","0.0691"
"","1.2000","0.9587","0.0737"
"","1.2400","0.9906","0.0755"
"","1.2800","1.0231","0.0778"
"","1.3200","1.0581","0.0830"
"","1.3600","1.0898","0.0831"
"","1.4000","1.1244","0.0845"
"","1.4400","1.1589","0.0904"
"","1.4800","1.1890","0.0921"
"","1.5200","1.2238","0.0965"
"","1.5600","1.2589","0.1005"
"","1.6000","1.2908","0.1012"
"","1.6400","1.3242","0.1047"
"","1.6800","1.3576","0.1094"
"","1.7200","1.3905","0.1111"
"","1.7600","1.4255","0.1165"
"","1.8000","1.4587","0.1186"
"","1.8400","1.4895","0.1188"
"","1.8800","1.5242","0.1249"
"","1.9200","1.5568","0.1273"
"","1.9600","1.5907","0.1264"
"","2.0000","1.6245","0.1339"
"","2.0400","1.6566","0.1349"
"","2.0800","1.6912","0.1387"
"","2.1200","1.7247","0.1430"
"","2.1600","1.7574","0.1448"
"","2.2000","1.7910","0.1435"
"","2.2400","1.8242","0.1491"
"","2.2800","1.8565","0.1485"
"","2.3200","1.8921","0.1527"
"","2.3600","1.9238","0.1550"
"","2.4000","1.9575","0.1574"
"","2.4400","1.9907","0.1619"
"","2.4800","2.0236","0.1639"
"","2.5200","2.0583","0.1655"
"","2.5600","2.0917","0.1695"
"","2.6000","2.1235","0.1715"
"","2.6400","2.1576","0.1730"
"","2.6800","2.1908","0.1759"
"","2.7200","2.2243","0.1787"
"","2.7600","2.2576","0.1829"
"","2.8000","2.2898","0.1851"
"","2.8400","2.3238","0.1873"
"","2.8800","2.3588","0.1922"
"","2.9200","2.3910","0.1953"
"","2.9600","2.4242","0.1963"
"","3.0000","2.4577","0.2005"
"","3.0400","2.4896","0.2018"
"","3.0800","2.5253","0.2029"
"","3.1200","2.5578","0.2065"
"","3.1600","2.5889","0.2080"
"","3.2000","2.6245","0.2143"
"","3.2400","2.6584","0.2163"
"","3.2800","2.6907","0.2173"
"","3.3200","2.7257","0.2206"
"","3.3600","2.7570","0.2201"
"","3.4000","2.7904","0.2216"
"","3.4400","2.8248","0.2274"
"","3.4800","2.8574","0.2272"
"","3.5200","2.8903","0.2306"
"","3.5600","2.9238","0.2342"
"","3.6000","2.9575","0.2338"
"","3.6400","2.9912","0.2338"
"","3.6800","3.0250","0.2335"
"","3.7200","3.0574","0.2249"
"","3.7600","3.0901","0.2228"
"","3.8000","3.1243","0.2242"
"","3.8400","3.1577","0.2206"
"","3.8800","3.1913","0.2216"
"","3.9200","3.2231","0.2165"
"","3.9600","3.2577","0.1884"
"","4.0000","3.2912","0.1870"
"","4.0400","3.3242","0.1902"
"","4.0800","3.3581","0.1929"
"","4.1200","3.3906","0.2003"
"","4.1600","3.4230","0.2053"
"","4.2000","3.4590","0.2119"
"","4.2400","3.4904","0.2125"
"","4.2800","3.5231","0.2162"
"","4.3200","3.5587","0.2201"
"","4.3600","3.5905","0.2157"
"","4.4000","3.6248","0.2160"
"","4.4400","3.6591","0.2225"
"","4.4800","3.6895","0.2271"
"","4.5200","3.7239","0.2317"
"","4.5600","3.7586","0.2407"
"","4.6000","3.7904","0.2441"
"","4.6400","3.8243","0.2497"
"","4.6800","3.8575","0.2551"
"","4.7200","3.8903","0.2587"
"","4.7600","3.9255","0.2678"
"","4.8000","3.9582","0.2712"
"","4.8400","3.9905","0.2720"
"","4.8800","4.0243","0.2811"
"","4.9200","4.0572","0.2839"
"","4.9600","4.0911","0.2863"
"","5.0000","4.1244","0.2909"
"","5.0400","4.1567","0.2961"
"","5.0800","4.1908","0.2962"
"","5.1200","4.2249","0.3037"
"","5.1600","4.2577","0.3061"
"","5.2000","4.2910","0.3100"
"","5.2400","4.3236","0.3128"
"","5.2800","4.3569","0.3149"
"","5.3200","4.3911","0.3181"
"","5.3600","4.4242","0.3239"
"","5.4000","4.4568","0.3248"
"","5.4400","4.4908","0.3296"
"","5.4800","4.5239","0.3304"
"","5.5200","4.5581","0.3356"
"","5.5600","4.5916","0.3392"
"","5.6000","4.6235","0.3378"
"","5.6400","4.6581","0.3426"
"","5.6800","4.6909","0.3482"
"","5.7200","4.7241","0.3488"
"","5.7600","4.7583","0.3521"
"","5.8000","4.7897","0.3546"
"","5.8400","4.8240","0.3576"
"","5.8800","4.8586","0.3624"
"","5.9200","4.8907","0.3665"
"","5.9600","4.9243","0.3674"
"","6.0000","4.9577","0.3732"
"","6.0400","4.9893","0.3750"
"","6.0800","5.0252","0.3786"
"","6.1200","5.0581","0.3780"
"","6.1600","5.0888","0.3779"
"","6.2000","5.1243","0.3847"
"","6.2400","5.1581","0.3870"
"","6.2800","5.1908","0.3871"
"","6.3200","5.2254","0.3907"
"","6.3600","5.2575","0.3921"
"","6.4000","5.2898","0.3984"
"","6.4400","5.3251","0.4030"
"","6.4800","5.3572","0.4036"
"","6.5200","5.3905","0.4075"
"","6.5600","5.4243","0.4122"
"","6.6000","5.4568","0.4146"
"","6.6400","5.4919","0.4184"
"","6.6800","5.5249","0.4210"
"","6.7200","5.5569","0.4234"
"","6.7600","5.5910","0.4262"
"","6.8000","5.6240","0.4288"
"","6.8400","5.6577","0.4327"
"","6.8800","5.6909","0.4374"
"","6.9200","5.7230","0.4395"
"","6.9600","5.7583","0.4435"
"","7.0000","5.7915","0.4476"
"","7.0400","5.8239","0.4518"
"","7.0800","5.8578","0.4520"
"","7.1200","5.8903","0.4586"
"","7.1600","5.9230","0.4611"
"","7.2000","5.9584","0.4639"
"","7.2400","5.9913","0.4680"
"","7.2800","6.0228","0.4687"
"","7.3200","6.0582","0.4749"
"","7.3600","6.0908","0.4774"
"","7.4000","6.1248","0.4814"
"","7.4400","6.1590","0.4831"
"","7.4800","6.1889","0.4817"
"","7.5200","6.2239","0.4869"
"","7.5600","6.2587","0.4908"
"","7.6000","6.2902","0.4913"
"","7.6400","6.3246","0.4947"
"","7.6800","6.3572","0.4963"
"","7.7200","6.3904","0.4993"
"","7.7600","6.4253","0.5029"
"","7.8000","6.4583","0.5039"
"","7.8400","6.4902","0.5053"
"","7.8800","6.5245","0.5077"
"","7.9200","6.5567","0.5073"
"","7.9600","6.5910","0.5094"
"","8.0000","6.6251","0.5113"
"","8.0400","6.6562","0.5074"
"","8.0800","6.6907","0.5109"
"","8.1200","6.7251","0.5117"
"","8.1600","6.7572","0.5059"
"","8.2000","6.7909","0.5022"
"","8.2400","6.8240","0.5019"
"","8.2800","6.8567","0.4976"
"","8.3200","6.8915","0.4973"
"","8.3600","6.9244","0.4930"
"","8.4000","6.9570","0.4940"
"","8.4400","6.9913","0.4977"
"","8.4800","7.0235","0.4985"
"","8.5200","7.0582","0.5002"
"","8.5600","7.0921","0.5016"
"","8.6000","7.1231","0.4983"
"","8.6400","7.1578","0.5024"
"","8.6800","7.1911","0.5016"
"","8.7200","7.2241","0.5004"
"","8.7600","7.2578","0.4991"
"","8.8000","7.2893","0.4904"
"","8.8400","7.3237","0.4911"
"","8.8800","7.3589","0.4983"
"","8.9200","7.3907","0.5003"
"","8.9600","7.4242","0.5029"
"","9.0000","7.4579","0.5052"
"","9.0400","7.4889","0.5037"
"","9.0800","7.5252","0.5082"
"","9.1200","7.5582","0.5104"
"","9.1600","7.5890","0.5109"
"","9.2000","7.6239","0.5144"
"","9.2400","7.6586","0.5212"
"","9.2800","7.6902","0.5203"
"","9.3200","7.7253","0.5175"
"","9.3600","7.7571","0.5149"
"","9.4000","7.7896","0.5188"
"","9.4400","7.8255","0.5249"
"","9.4800","7.8573","0.5261"
"","9.5200","7.8900","0.5288"
"","9.5600","7.9243","0.5365"
"","9.6000","7.9571","0.5357"
"","9.6400","7.9915","0.5377"
"","9.6800","8.0251","0.5419"
"","9.7200","8.0569","0.5418"
"","9.7600","8.0907","0.5473"
"","9.8000","8.1241","0.5505"
"","9.8400","8.1579","0.5539"
"","9.8800","8.1910","0.5586"
"","9.9200","8.2230","0.5617"
"","9.9600","8.2573","0.5648"
"","10.0000","8.2920","0.5693"
"","10.0400","8.3240","0.5724"
"","10.0800","8.3583","0.5747"
"","10.1200","8.3905","0.5724"
"","10.1600","8.4232","0.5725"
"","10.2000","8.4585","0.5760"
"","10.2400","8.4910","0.5777"
"","10.2800","8.5228","0.5775"
"","10.3200","8.5581","0.5805"
"","10.3600","8.5908","0.5734"
"","10.4000","8.6244","0.5556"
"","10.4400","8.6596","0.5493"
"","10.4800","8.6894","0.5452"
"","10.5200","8.7237","0.5479"
"","10.5600","8.7585","0.5552"
"","10.6000","8.7905","0.5578"
"","10.6400","8.8240","0.5631"
"","10.6800","8.8577","0.5702"
"","10.7200","8.8902","0.5714"
"","10.7600","8.9257","0.5780"
"","10.8000","8.9581","0.5770"
"","10.8400","8.9900","0.5738"
"","10.8800","9.0241","0.5802"
"","10.9200","9.0572","0.5846"
"","10.9600","9.0908","0.5917"
"","11.0000","9.1250","0.6000"
"","11.0400","9.1565","0.6018"
[...]
"","11.1200","9.2300","1.2557"
"","11.1600","9.2627","1.2585"
"","11.2000","9.2959","1.2645"
"","11.2400","9.3296","1.2714"
"","11.2800","9.3639","1.2733"
"","11.3200","9.3969","1.2761"
"","11.3600","9.4287","1.2794"
"","11.4000","9.4637","1.2831"
"","11.4400","9.4966","1.2868"
"","11.4800","9.5295","1.2906"
"","11.5200","9.5637","1.2939"
"","11.5600","9.5956","1.2978"
"","11.6000","9.6292","1.3002"
"","11.6400","9.6630","1.3052"
"","11.6800","9.6968","1.3099"
"","11.7200","9.7304","1.3134"
"","11.7600","9.7624","1.3136"
"","11.8000","9.7960","1.3197"
"","11.8400","9.8306","1.3233"
"","11.8800","9.8626","1.3239"
"","11.9200","9.8964","1.3295"
"","11.9600","9.9299","1.3336"
"","12.0000","9.9629","1.3348"
"","12.0400","9.9972","1.3402"
"","12.0800","10.0300","1.3430"
"","12.1200","10.0625","1.3439"
"","12.1600","10.0964","1.3482"
"","12.2000","10.1292","1.3528"
"","12.2400","10.1632","1.3566"
"","12.2800","10.1966","1.3590"
"","12.3200","10.2283","1.3610"
"","12.3600","10.2627","1.3658"
"","12.4000","10.2979","1.3711"
"","12.4400","10.3297","1.3684"
"","12.4800","10.3627","1.3666"
"","12.5200","10.3967","1.3674"
"","12.5600","10.4290","1.3695"
"","12.6000","10.4640","1.3769"
"","12.6400","10.4964","1.3770"
"","12.6800","10.5277","1.3758"
"","12.7200","10.5640","1.3842"
"","12.7600","10.5969","1.3839"
"","12.8000","10.6291","1.3848"
"","12.8400","10.6643","1.3870"
"","12.8800","10.6957","1.3831"
"","12.9200","10.7285","1.3832"
"","12.9600","10.7648","1.3904"
"","13.0000","10.7964","1.3874"
"","13.0400","10.8293","1.3845"
"","13.0800","10.8628","1.3862"
"","13.1200","10.8963","1.3879"
"","13.1600","10.9298","1.3873"
"","13.2000","10.9625","1.3860"
"","13.2400","10.9960","1.3845"
"","13.2800","11.0302","1.3779"
"","13.3200","11.0629","1.3701"
"","13.3600","11.0965","1.3608"
"","13.4000","11.1301","1.3243"
"","13.4400","11.1625","1.2885"
"","13.4800","11.1964","1.2748"
"","13.5200","11.2307","1.2836"
"","13.5600","11.2628","1.2874"
"","13.6000","11.2972","1.2943"
"","13.6400","11.3288","1.2998"
"","13.6800","11.3622","1.3051"
"","13.7200","11.3981","1.3167"
"","13.7600","11.4290","1.3187"
"","13.8000","11.4619","1.3261"
"","13.8400","11.4973","1.3371"
"","13.8800","11.5290","1.3417"
"","13.9200","11.5632","1.3481"
"","13.9600","11.5982","1.3610"
"","14.0000","11.6280","1.3593"
"","14.0400","11.6632","1.3694"
"","14.0800","11.6973","1.3753"
"","14.1200","11.7290","1.3781"
"","14.1600","11.7631","1.3841"
"","14.2000","11.7960","1.3881"
"","14.2400","11.8287","1.3940"
"","14.2800","11.8643","1.4016"
"","14.3200","11.8970","1.4055"
"","14.3600","11.9288","1.4071"
"","14.4000","11.9635","1.4129"
"","14.4400","11.9962","1.4146"
"","14.4800","12.0296","1.4218"
"","14.5200","12.0640","1.4255"
"","14.5600","12.0950","1.4285"
"","14.6000","12.1299","1.4301"
"","14.6400","12.1631","1.4336"
"","14.6800","12.1958","1.4347"
"","14.7200","12.2304","1.4399"
"","14.7600","12.2628","1.4440"
"","14.8000","12.2956","1.4501"
"","14.8400","12.3301","1.4566"
"","14.8800","12.3625","1.4614"
"","14.9200","12.3955","1.4636"
"","14.9600","12.4299","1.4674"
"","15.0000","12.4628","1.4727"
"","15.0400","12.4970","1.4794"
"","15.0800","12.5300","1.4819"
"","15.1200","12.5620","1.4831"
"","15.1600","12.5966","1.4893"
"","15.2000","12.6296","1.4941"
"","15.2400","12.6626","1.5000"
"","15.2800","12.6972","1.5054"
"","15.3200","12.7287","1.5048"
"","15.3600","12.7630","1.5140"
"","15.4000","12.7975","1.5192"
"","15.4400","12.8297","1.5201"
"","15.4800","12.8629","1.5255"
"","15.5200","12.8969","1.5314"
"","15.5600","12.9288","1.5353"
"","15.6000","12.9643","1.5450"
"","15.6400","12.9965","1.5455"
"","15.6800","13.0276","1.5469"
"","15.7200","13.0636","1.5553"
"","15.7600","13.0969","1.5605"
"","15.8000","13.1297","1.5629"
"","15.8400","13.1638","1.5660"
"","15.8800","13.1959","1.5683"
"","15.9200","13.2286","1.5722"
"","15.9600","13.2644","1.5799"
"","16.0000","13.2965","1.5792"
"","16.0400","13.3290","1.5815"
"","16.0800","13.3627","1.5847"
"","16.1200","13.3965","1.5885"
"","16.1600","13.4301","1.5894"
"","16.2000","13.4636","1.5905"
"","16.2400","13.4960","1.5910"
"","16.2800","13.5302","1.5923"
"","16.3200","13.5627","1.5938"
"","16.3600","13.5966","1.5998"
"","16.4000","13.6298","1.5996"
"","16.4400","13.6626","1.5994"
"","16.4800","13.6963","1.6054"
"","16.5200","13.7300","1.6110"
"","16.5600","13.7635","1.6141"
"","16.6000","13.7969","1.6171"
"","16.6400","13.8292","1.6178"
"","16.6800","13.8619","1.6210"
"","16.7200","13.8979","1.6308"
"","16.7600","13.9295","1.6294"
"","16.8000","13.9621","1.6272"
"","16.8400","13.9972","1.6344"
"","16.8800","14.0290","1.6325"
"","16.9200","14.0627","1.6344"
"","16.9600","14.0982","1.6404"
"","17.0000","14.1290","1.6380"
"","17.0400","14.1629","1.6404"
"","17.0800","14.1973","1.6444"
"","17.1200","14.2298","1.6431"
"","17.1600","14.2628","1.6444"
"","17.2000","14.2960","1.6441"
"","17.2400","14.3291","1.6461"
"","17.2800","14.3645","1.6463"
"","17.3200","14.3972","1.6472"
"","17.3600","14.4287","1.6458"
"","17.4000","14.4636","1.6499"
"","17.4400","14.4967","1.6536"
"","17.4800","14.5294","1.6555"
"","17.5200","14.5637","1.6603"
"","17.5600","14.5957","1.6599"
"","17.6000","14.6297","1.6632"
"","17.6400","14.6640","1.6679"
"","17.6800","14.6959","1.6681"
"","17.7200","14.7304","1.6726"
"","17.7600","14.7627","1.6732"
"","17.8000","14.7957","1.6750"
"","17.8400","14.8307","1.6803"
"","17.8800","14.8624","1.6781"
"","17.9200","14.8958","1.6842"
"","17.9600","14.9300","1.6871"
"","18.0000","14.9630","1.6903"
"","18.0400","14.9970","1.6935"
"","18.0800","15.0301","1.6917"
"","18.1200","15.0627","1.6940"
"","18.1600","15.0968","1.6992"
"","18.2000","15.1293","1.6982"
"","18.2400","15.1632","1.7030"
"","18.2800","15.1969","1.7051"
"","18.3200","15.2289","1.7049"
"","18.3600","15.2625","1.7125"
"","18.4000","15.2974","1.7158"
"","18.4400","15.3297","1.7148"
"","18.4800","15.3628","1.7172"
"","18.5200","15.3963","1.7195"
"","18.5600","15.4294","1.7239"
"","18.6000","15.4636","1.7277"
"","18.6400","15.4969","1.7293"
"","18.6800","15.5270","1.7255"
"","18.7200","15.5628","1.7346"
"","18.7600","15.5967","1.7373"
"","18.8000","15.6288","1.7369"
"","18.8400","15.6651","1.7430"
"","18.8800","15.6960","1.7409"
"","18.9200","15.7292","1.7426"
"","18.9600","15.7643","1.7483"
"","19.0000","15.7967","1.7496"
"","19.0400","15.8290","1.7486"
"","19.0800","15.8634","1.7531"
"","19.1200","15.8964","1.7571"
"","19.1600","15.9301","1.7577"
"","19.2000","15.9637","1.7590"
"","19.2400","15.9962","1.7599"
"","19.2800","16.0301","1.7626"
"","19.3200","16.0631","1.7646"
"","19.3600","16.0962","1.7667"
"","19.4000","16.1301","1.7651"
"","19.4400","16.1624","1.7641"
"","19.4800","16.1965","1.7701"
"","19.5200","16.2299","1.7704"
"","19.5600","16.2639","1.7746"
"","19.6000","16.2965","1.7728"
"","19.6400","16.3294","1.7748"
"","19.6800","16.3618","1.7768"
"","19.7200","16.3974","1.7843"
"","19.7600","16.4296","1.7836"
"","19.8000","16.4619","1.7820"
"","19.8400","16.4973","1.7871"
"","19.8800","16.5286","1.7847"
"","19.9200","16.5634","1.7883"
"","19.9600","16.5980","1.7947"
"","20.0000","16.6284","1.7891"
"","20.0400","16.6629","1.7927"
"","20.0800","16.6975","1.7984"
"","20.1200","16.7287","1.7945"
"","20.1600","16.7629","1.7981"
"","20.2000","16.7959","1.7998"
"","20.2400","16.8286","1.8000"
"","20.2800","16.8646","1.8044"
"","20.3200","16.8968","1.8025"
"","20.3600","16.9292","1.8012"
"","20.4000","16.9636","1.8057"
"","20.4400","16.9963","1.8059"
"","20.4800","17.0297","1.8064"
"","20.5200","17.0634","1.8066"
"","20.5600","17.0959","1.8099"
"","20.6000","17.1292","1.8092"
"","20.6400","17.1639","1.8109"
"","20.6800","17.1960","1.8122"
"","20.7200","17.2298","1.8126"
"","20.7600","17.2633","1.8146"
"","20.8000","17.2954","1.8150"
"","20.8400","17.3307","1.8181"
"","20.8800","17.3624","1.8155"
"","20.9200","17.3956","1.8158"
"","20.9600","17.4299","1.8178"
"","21.0000","17.4623","1.8182"
"","21.0400","17.4969","1.8215"
"","21.0800","17.5303","1.8200"
"","21.1200","17.5624","1.8181"
"","21.1600","17.5968","1.8200"
"","21.2000","17.6294","1.8191"
"","21.2400","17.6630","1.8234"
"","21.2800","17.6972","1.8238"
"","21.3200","17.7291","1.8187"
"","21.3600","17.7624","1.8209"
"","21.4000","17.7976","1.8256"
"","21.4400","17.8296","1.8251"
"","21.4800","17.8630","1.8251"
"","21.5200","17.8969","1.8249"
"","21.5600","17.9287","1.8246"
"","21.6000","17.9637","1.8286"
"","21.6400","17.9970","1.8292"
"","21.6800","18.0277","1.8251"
"","21.7200","18.0631","1.8320"
"","21.7600","18.0974","1.8357"
"","21.8000","18.1296","1.8330"
"","21.8400","18.1644","1.8344"
"","21.8800","18.1955","1.8324"
"","21.9200","18.2286","1.8347"
"","21.9600","18.2644","1.8402"
"","22.0000","18.2963","1.8372"
"","22.0400","18.3287","1.8368"
"","22.0800","18.3637","1.8430"
"","22.1200","18.3958","1.8422"
"","22.1600","18.4304","1.8461"
"","22.2000","18.4631","1.8452"
"","22.2400","18.4957","1.8477"
"","22.2800","18.5303","1.8486"
"","22.3200","18.5630","1.8495"
"","22.3600","18.5965","1.8511"
"","22.4000","18.6300","1.8509"
"","22.4400","18.6623","1.8500"
"","22.4800","18.6963","1.8528"
"","22.5200","18.7301","1.8547"
"","22.5600","18.7637","1.8546"
"","22.6000","18.7970","1.8556"
"","22.6400","18.8293","1.8525"
"","22.6800","18.8619","1.8526"
"","22.7200","18.8969","1.8585"
"","22.7600","18.9299","1.8557"
"","22.8000","18.9622","1.8531"
"","22.8400","18.9968","1.8593"
"","22.8800","19.0289","1.8573"
"","22.9200","19.0630","1.8560"
"","22.9600","19.0983","1.8573"
"","23.0000","19.1285","1.8505"
"","23.0400","19.1626","1.8537"
"","23.0800","19.1976","1.8587"
"","23.1200","19.2291","1.8560"
"","23.1600","19.2632","1.8550"
"","23.2000","19.2958","1.8547"
"","23.2400","19.3289","1.8546"
"","23.2800","19.3648","1.8591"
"","23.3200","19.3971","1.8570"
"","23.3600","19.4291","1.8521"
"","23.4000","19.4637","1.8571"
"","23.4400","19.4961","1.8563"
"","23.4800","19.5297","1.8571"
"","23.5200","19.5634","1.8584"
"","23.5600","19.5960","1.8576"
"","23.6000","19.6291","1.8546"
"","23.6400","19.6638","1.8558"
"","23.6800","19.6965","1.8551"
"","23.7200","19.7294","1.8548"
"","23.7600","19.7631","1.8549"
"","23.8000","19.7958","1.8541"
"","23.8400","19.8308","1.8530"
"","23.8800","19.8628","1.8507"
"","23.9200","19.8956","1.8498"
"","23.9600","19.9298","1.8497"
"","24.0000","19.9629","1.8499"
"","24.0400","19.9973","1.8501"
"","24.0800","20.0308","1.8490"
"","24.1200","20.0623","1.8437"
"","24.1600","20.0970","1.8449"
"","24.2000","20.1291","1.8423"
"","24.2400","20.1630","1.8433"
"","24.2800","20.1975","1.8479"
"","24.3200","20.2283","1.8396"
"","24.3600","20.2621","1.8419"
"","24.4000","20.2979","1.8440"
"","24.4400","20.3297","1.8373"
"","24.4800","20.3629","1.8372"
"","24.5200","20.3968","1.8367"
"","24.5600","20.4295","1.8322"
"","24.6000","20.4633","1.8291"
"","24.6400","20.4968","1.8284"
"","24.6800","20.5278","1.8227"
"","24.7200","20.5629","1.8222"
"","24.7600","20.5971","1.8177"
"","24.8000","20.6291","1.8054"
"","24.8400","20.6644","1.7951"
"","24.8800","20.6958","1.7804"
"","24.9200","20.7285","1.7523"
"","24.9600","20.7640","1.7319"
"","25.0000","20.7967","1.7156"
"","25.0400","20.8287","1.6954"
"","25.0800","20.8637","1.6763"
"","25.1200","20.8958","1.6617"
"","25.1600","20.9305","1.6497"
"","25.2000","20.9633","1.6287"
"","25.2400","20.9962","1.5857"
"","25.2800","21.0296","1.5428"
"","25.3200","21.0634","1.5301"
"","25.3600","21.0963","1.5206"
"","25.4000","21.1305","1.5139"
"","25.4400","21.1621","1.5014"
"","25.4800","21.1961","1.4914"
"","25.5200","21.2305","1.4813"
"","25.5600","21.2637","1.4723"
"","25.6000","21.2967","1.4645"
"","25.6400","21.3294","1.4556"
"","25.6800","21.3620","1.4469"
"","25.7200","21.3968","1.4401"
"","25.7600","21.4300","1.4214"
"","25.8000","21.4618","1.3961"
"","25.8400","21.4971","1.3827"
"","25.8800","21.5291","1.3727"
"","25.9200","21.5632","1.3659"
"","25.9600","21.5975","1.3597"
"","26.0000","21.6293","1.3470"
"","26.0400","21.6629","1.3410"
"","26.0800","21.6976","1.3365"
"","26.1200","21.7284","1.3241"
"","26.1600","21.7633","1.3225"
"","26.2000","21.7960","1.3148"
"","26.2400","21.8286","1.3098"
"","26.2800","21.8647","1.3088"
"","26.3200","21.8970","1.3017"
"","26.3600","21.9286","1.2949"
"","26.4000","21.9637","1.2959"
"","26.4400","21.9957","1.2912"
"","26.4800","22.0301","1.2918"
"","26.5200","22.0630","1.2877"
"","26.5600","22.0961","1.2859"
"","26.6000","22.1292","1.2840"
"","26.6400","22.1638","1.2844"
"","26.6800","22.1964","1.2816"
"","26.7200","22.2294","1.2762"
"","26.7600","22.2631","1.2768"
"","26.8000","22.2955","1.2736"
"","26.8400","22.3309","1.2758"
"","26.8800","22.3627","1.2708"
"","26.9200","22.3952","1.2703"
"","26.9600","22.4292","1.2732"
"","27.0000","22.4634","1.2749"
"","27.0400","22.4971","1.2706"
"","27.0800","22.5307","1.2702"
"","27.1200","22.5620","1.2620"
"","27.1600","22.5968","1.2627"
"","27.2000","22.6293","1.2564"
"","27.2400","22.6626","1.2569"
"","27.2800","22.6973","1.2542"
"","27.3200","22.7286","1.2436"
"","27.3600","22.7627","1.2391"
"","27.4000","22.7977","1.2399"
"","27.4400","22.8294","1.2298"
"","27.4800","22.8633","1.2304"
"","27.5200","22.8961","1.2265"
"","27.5600","22.9293","1.2190"
"","27.6000","22.9634","1.2140"
"","27.6400","22.9968","1.2118"
"","27.6800","23.0281","1.2010"
"","27.7200","23.0626","1.1751"
"","27.7600","23.0974","1.1661"
"","27.8000","23.1292","1.1577"
"","27.8400","23.1646","1.1593"
"","27.8800","23.1958","1.1496"
"","27.9200","23.2280","1.1431"
"","27.9600","23.2643","1.1448"
"","28.0000","23.2963","1.1380"
"","28.0400","23.3292","1.1363"
"","28.0800","23.3629","1.1400"
"","28.1200","23.3957","1.1409"
"","28.1600","23.4304","1.1429"
"","28.2000","23.4636","1.1386"
"","28.2400","23.4954","1.1366"
"","28.2800","23.5298","1.1380"
"","28.3200","23.5631","1.1347"
"","28.3600","23.5968","1.1335"
"","28.4000","23.6298","1.1351"
"","28.4400","23.6622","1.1308"
"","28.4800","23.6969","1.1332"
"","28.5200","23.7298","1.1291"
"","28.5600","23.7634","1.1297"
"","28.6000","23.7971","1.1297"
"","28.6400","23.8289","1.1267"
"","28.6800","23.8624","1.1265"
"","28.7200","23.8970","1.1299"
"","28.7600","23.9298","1.1277"
"","28.8000","23.9622","1.1235"
"","28.8400","23.9968","1.1265"
"","28.8800","24.0288","1.1216"
"","28.9200","24.0628","1.1235"
"","28.9600","24.0986","1.1236"
"","29.0000","24.1289","1.1156"
"","29.0400","24.1636","1.1150"
"","29.0800","24.1978","1.1098"
"","29.1200","24.2290","1.1038"
"","29.1600","24.2632","1.1045"
"","29.2000","24.2964","1.1016"
"","29.2400","24.3290","1.0983"
"","29.2800","24.3643","1.1018"
"","29.3200","24.3974","1.0982"
"","29.3600","24.4287","1.0956"
"","29.4000","24.4635","1.0970"
"","29.4400","24.4961","1.0942"
"","29.4800","24.5301","1.0923"
"","29.5200","24.5634","1.0872"
"","29.5600","24.5948","1.0844"
"","29.6000","24.6291","1.0830"
"","29.6400","24.6626","1.0800"
"","29.6800","24.6971","1.0792"
"","29.7200","24.7303","1.0738"
"","29.7600","24.7628","1.0672"
"","29.8000","24.7962","1.0677"
"","29.8400","24.8308","1.0667"
"","29.8800","24.8630","1.0607"
"","29.9200","24.8956","1.0516"
"","29.9600","24.9296","1.0453"
"","30.0000","24.9623","1.0405"
"","30.0400","24.9977","1.0394"
"","30.0800","25.0305","1.0290"
"","30.1200","25.0623","1.0255"
"","30.1600","25.0967","1.0273"
"","30.2000","25.1292","1.0222"
"","30.2400","25.1628","1.0241"
"","30.2800","25.1974","1.0241"
"","30.3200","25.2286","1.0182"
"","30.3600","25.2625","1.0191"
"","30.4000","25.2981","1.0194"
"","30.4400","25.3297","1.0136"
"","30.4800","25.3629","1.0128"
"","30.5200","25.3970","1.0103"
"","30.5600","25.4286","1.0074"
"","30.6000","25.4639","1.0087"
"","30.6400","25.4961","1.0063"
"","30.6800","25.5280","1.0019"
"","30.7200","25.5633","1.0017"
"","30.7600","25.5967","0.9978"
"","30.8000","25.6294","0.9936"
"","30.8400","25.6646","0.9943"
"","30.8800","25.6960","0.9891"
"","30.9200","25.7280","0.9894"
"","30.9600","25.7641","0.9919"
"","31.0000","25.7966","0.9841"
"","31.0400","25.8292","0.9773"
"","31.0800","25.8632","0.9771"
"","31.1200","25.8960","0.9751"
"","31.1600","25.9305","0.9769"
"","31.2000","25.9637","0.9763"
"","31.2400","25.9957","0.9746"
"","31.2800","26.0297","0.9748"
"","31.3200","26.0632","0.9736"
"","31.3600","26.0963","0.9691"
"","31.4000","26.1301","0.9674"
"","31.4400","26.1625","0.9665"
"","31.4800","26.1960","0.9667"
"","31.5200","26.2307","0.9703"
"","31.5600","26.2635","0.9683"
"","31.6000","26.2970","0.9662"
"","31.6400","26.3291","0.9601"
"","31.6800","26.3622","0.9623"
"","31.7200","26.3973","0.9636"
"","31.7600","26.4292","0.9611"
"","31.8000","26.4622","0.9604"
"","31.8400","26.4969","0.9609"
"","31.8800","26.5294","0.9608"
"","31.9200","26.5631","0.9605"
"","31.9600","26.5976","0.9614"
"","32.0000","26.6293","0.9560"
"","32.0400","26.6623","0.9561"
"","32.0800","26.6973","0.9568"
"","32.1200","26.7287","0.9515"
"","32.1600","26.7635","0.9526"
"","32.2000","26.7966","0.9488"
"","32.2400","26.8282","0.9461"
"","32.2800","26.8645","0.9503"
"","32.3200","26.8977","0.9494"
"","32.3600","26.9289","0.9442"
"","32.4000","26.9630","0.9450"
"","32.4400","26.9963","0.9457"
"","32.4800","27.0296","0.9444"
"","32.5200","27.0634","0.9451"
"","32.5600","27.0956","0.9411"
"","32.6000","27.1291","0.9427"
"","32.6400","27.1634","0.9435"
"","32.6800","27.1967","0.9442"
"","32.7200","27.2298","0.9411"
"","32.7600","27.2621","0.9396"
"","32.8000","27.2957","0.9408"
"","32.8400","27.3305","0.9419"
"","32.8800","27.3630","0.9409"
"","32.9200","27.3954","0.9386"
"","32.9600","27.4291","0.9405"
"","33.0000","27.4634","0.9421"
"","33.0400","27.4969","0.9391"
"","33.0800","27.5307","0.9373"
"","33.1200","27.5622","0.9331"
"","33.1600","27.5964","0.9345"
"","33.2000","27.6304","0.9370"
"","33.2400","27.6623","0.9337"
"","33.2800","27.6968","0.9343"
"","33.3200","27.7288","0.9321"
"","33.3600","27.7625","0.9323"
"","33.4000","27.7978","0.9331"
"","33.4400","27.8298","0.9288"
"","33.4800","27.8631","0.9279"
"","33.5200","27.8966","0.9289"
"","33.5600","27.9292","0.9290"
"","33.6000","27.9636","0.9308"
"","33.6400","27.9966","0.9279"
"","33.6800","28.0281","0.9264"
"","33.7200","28.0634","0.9284"
"","33.7600","28.0964","0.9282"
"","33.8000","28.1298","0.9259"
"","33.8400","28.1647","0.9271"
"","33.8800","28.1955","0.9222"
"","33.9200","28.2285","0.9214"
"","33.9600","28.2640","0.9275"
"","34.0000","28.2967","0.9260"
"","34.0400","28.3290","0.9217"
"","34.0800","28.3626","0.9242"
"","34.1200","28.3957","0.9224"
"","34.1600","28.4303","0.9220"
"","34.2000","28.4639","0.9231"
"","34.2400","28.4953","0.9188"
"","34.2800","28.5296","0.9213"
"","34.3200","28.5627","0.9199"
"","34.3600","28.5968","0.9202"
"","34.4000","28.6300","0.9199"
"","34.4400","28.6622","0.9179"
"","34.4800","28.6964","0.9161"
"","34.5200","28.7304","0.9188"
"","34.5600","28.7632","0.9164"
"","34.6000","28.7969","0.9150"
"","34.6400","28.8288","0.9111"
"","34.6800","28.8625","0.9101"
"","34.7200","28.8975","0.9125"
"","34.7600","28.9287","0.9074"
"","34.8000","28.9623","0.9080"
"","34.8400","28.9970","0.9094"
"","34.8800","29.0297","0.9041"
"","34.9200","29.0632","0.9051"
"","34.9600","29.0979","0.9050"
"","35.0000","29.1287","0.8992"
"","35.0400","29.1627","0.9000"
"","35.0800","29.1976","0.9005"
"","35.1200","29.2289","0.8959"
"","35.1600","29.2633","0.8964"
"","35.2000","29.2966","0.8955"
"","35.2400","29.3290","0.8905"
"","35.2800","29.3644","0.8905"
"","35.3200","29.3973","0.8846"
"","35.3600","29.4294","0.8797"
"","35.4000","29.4632","0.8803"
"","35.4400","29.4968","0.8792"
"","35.4800","29.5297","0.8777"
"","35.5200","29.5637","0.8776"
"","35.5600","29.5954","0.8764"
"","35.6000","29.6295","0.8745"
"","35.6400","29.6635","0.8786"
"","35.6800","29.6967","0.8752"
"","35.7200","29.7300","0.8735"
"","35.7600","29.7621","0.8695"
"","35.8000","29.7962","0.8715"
"","35.8400","29.8306","0.8713"
"","35.8800","29.8627","0.8701"
"","35.9200","29.8956","0.8674"
"","35.9600","29.9296","0.8712"
"","36.0000","29.9630","0.8722"
"","36.0400","29.9973","0.8702"
"","36.0440","30.0003","0.8697"